{
  "version": 8,
  "blockIdVersion": 11,
  "anchorX": 0,
  "anchorY": 0,
  "anchorZ": 0,
  "blocks": [
    {
      "x": -12,
      "y": -1,
      "z": 5,
      "name": "Rock_Basalt"
    },
    {
      "x": -12,
      "y": -3,
      "z": 6,
      "name": "Rock_Basalt"
    },
    {
      "x": -12,
      "y": -2,
      "z": 6,
      "name": "Rock_Basalt"
    },
    {
      "x": -12,
      "y": -1,
      "z": 6,
      "name": "Rock_Basalt"
    },
    {
      "x": -12,
      "y": -5,
      "z": 7,
      "name": "Rock_Basalt"
    },
    {
      "x": -12,
      "y": -4,
      "z": 7,
      "name": "Rock_Basalt"
    },
    {
      "x": -12,
      "y": -3,
      "z": 7,
      "name": "Rock_Basalt"
    },
    {
      "x": -12,
      "y": -2,
      "z": 7,
      "name": "Rock_Basalt"
    },
    {
      "x": -12,
      "y": -1,
      "z": 7,
      "name": "Rock_Basalt"
    },
    {
      "x": -12,
      "y": 0,
      "z": 7,
      "name": "Rock_Basalt_Brick"
    },
    {
      "x": -12,
      "y": -3,
      "z": 8,
      "name": "Rock_Basalt"
    },
    {
      "x": -12,
      "y": -2,
      "z": 8,
      "name": "Rock_Basalt"
    },
    {
      "x": -12,
      "y": -1,
      "z": 8,
      "name": "Rock_Basalt"
    },
    {
      "x": -11,
      "y": -3,
      "z": 5,
      "name": "Rock_Basalt"
    },
    {
      "x": -11,
      "y": -2,
      "z": 5,
      "name": "Rock_Basalt"
    },
    {
      "x": -11,
      "y": -1,
      "z": 5,
      "name": "Rock_Basalt"
    },
    {
      "x": -11,
      "y": 0,
      "z": 5,
      "name": "Rock_Basalt_Brick"
    },
    {
      "x": -11,
      "y": 1,
      "z": 5,
      "name": "Rock_Basalt"
    },
    {
      "x": -11,
      "y": 2,
      "z": 5,
      "name": "Soil_Grass"
    },
    {
      "x": -11,
      "y": -6,
      "z": 6,
      "name": "Rock_Basalt"
    },
    {
      "x": -11,
      "y": -5,
      "z": 6,
      "name": "Rock_Basalt"
    },
    {
      "x": -11,
      "y": -4,
      "z": 6,
      "name": "Rock_Basalt"
    },
    {
      "x": -11,
      "y": -3,
      "z": 6,
      "name": "Rock_Basalt"
    },
    {
      "x": -11,
      "y": -2,
      "z": 6,
      "name": "Rock_Basalt"
    },
    {
      "x": -11,
      "y": -1,
      "z": 6,
      "name": "Rock_Basalt"
    },
    {
      "x": -11,
      "y": 0,
      "z": 6,
      "name": "Rock_Basalt_Brick"
    },
    {
      "x": -11,
      "y": 1,
      "z": 6,
      "name": "Rock_Basalt"
    },
    {
      "x": -11,
      "y": 2,
      "z": 6,
      "name": "Rock_Basalt"
    },
    {
      "x": -11,
      "y": 3,
      "z": 6,
      "name": "Soil_Grass"
    },
    {
      "x": -11,
      "y": 4,
      "z": 6,
      "name": "Plant_Crop_Mushroom_Common_Lime",
      "components": {
        "Components": {
          "FarmingBlock": {
            "LastTickGameTime": "0001-01-01T12:00:00Z"
          },
          "PlacedByInteraction": {
            "WhoPlacedUuid": {
              "$binary": "5RPZJ2uQSJ2g+KZxfjqR+g==",
              "$type": "04"
            }
          }
        }
      }
    },
    {
      "x": -11,
      "y": -6,
      "z": 7,
      "name": "Rock_Basalt"
    },
    {
      "x": -11,
      "y": -5,
      "z": 7,
      "name": "Rock_Basalt"
    },
    {
      "x": -11,
      "y": -4,
      "z": 7,
      "name": "Rock_Basalt"
    },
    {
      "x": -11,
      "y": -3,
      "z": 7,
      "name": "Rock_Basalt"
    },
    {
      "x": -11,
      "y": -2,
      "z": 7,
      "name": "Rock_Basalt"
    },
    {
      "x": -11,
      "y": -1,
      "z": 7,
      "name": "Rock_Basalt"
    },
    {
      "x": -11,
      "y": 0,
      "z": 7,
      "name": "Rock_Basalt_Brick"
    },
    {
      "x": -11,
      "y": 1,
      "z": 7,
      "name": "Rock_Basalt"
    },
    {
      "x": -11,
      "y": -6,
      "z": 8,
      "name": "Rock_Basalt"
    },
    {
      "x": -11,
      "y": -5,
      "z": 8,
      "name": "Rock_Basalt"
    },
    {
      "x": -11,
      "y": -4,
      "z": 8,
      "name": "Rock_Basalt"
    },
    {
      "x": -11,
      "y": -3,
      "z": 8,
      "name": "Rock_Basalt"
    },
    {
      "x": -11,
      "y": -2,
      "z": 8,
      "name": "Rock_Basalt"
    },
    {
      "x": -11,
      "y": -1,
      "z": 8,
      "name": "Rock_Basalt"
    },
    {
      "x": -10,
      "y": -5,
      "z": 5,
      "name": "Rock_Basalt"
    },
    {
      "x": -10,
      "y": -4,
      "z": 5,
      "name": "Rock_Basalt"
    },
    {
      "x": -10,
      "y": -3,
      "z": 5,
      "name": "Rock_Basalt"
    },
    {
      "x": -10,
      "y": -2,
      "z": 5,
      "name": "Rock_Basalt"
    },
    {
      "x": -10,
      "y": -1,
      "z": 5,
      "name": "Rock_Basalt"
    },
    {
      "x": -10,
      "y": 0,
      "z": 5,
      "name": "Rock_Basalt_Brick"
    },
    {
      "x": -10,
      "y": 1,
      "z": 5,
      "name": "Rock_Basalt"
    },
    {
      "x": -10,
      "y": 2,
      "z": 5,
      "name": "Soil_Dirt"
    },
    {
      "x": -10,
      "y": 3,
      "z": 5,
      "name": "Soil_Grass"
    },
    {
      "x": -10,
      "y": 4,
      "z": 5,
      "name": "Plant_Grass_Lush_Short"
    },
    {
      "x": -10,
      "y": -6,
      "z": 6,
      "name": "Rock_Basalt"
    },
    {
      "x": -10,
      "y": -5,
      "z": 6,
      "name": "Rock_Basalt"
    },
    {
      "x": -10,
      "y": -4,
      "z": 6,
      "name": "Rock_Basalt"
    },
    {
      "x": -10,
      "y": -3,
      "z": 6,
      "name": "Rock_Basalt"
    },
    {
      "x": -10,
      "y": -2,
      "z": 6,
      "name": "Rock_Basalt"
    },
    {
      "x": -10,
      "y": -1,
      "z": 6,
      "name": "Rock_Basalt"
    },
    {
      "x": -10,
      "y": 0,
      "z": 6,
      "name": "Rock_Basalt_Brick"
    },
    {
      "x": -10,
      "y": 1,
      "z": 6,
      "name": "Rock_Basalt"
    },
    {
      "x": -10,
      "y": 2,
      "z": 6,
      "name": "Rock_Basalt"
    },
    {
      "x": -10,
      "y": 3,
      "z": 6,
      "name": "Soil_Grass"
    },
    {
      "x": -10,
      "y": 4,
      "z": 6,
      "name": "Plant_Grass_Sharp"
    },
    {
      "x": -10,
      "y": -6,
      "z": 7,
      "name": "Rock_Basalt"
    },
    {
      "x": -10,
      "y": -5,
      "z": 7,
      "name": "Rock_Basalt"
    },
    {
      "x": -10,
      "y": -4,
      "z": 7,
      "name": "Rock_Basalt"
    },
    {
      "x": -10,
      "y": -3,
      "z": 7,
      "name": "Rock_Basalt"
    },
    {
      "x": -10,
      "y": -2,
      "z": 7,
      "name": "Rock_Basalt"
    },
    {
      "x": -10,
      "y": -1,
      "z": 7,
      "name": "Rock_Basalt"
    },
    {
      "x": -10,
      "y": 0,
      "z": 7,
      "name": "Rock_Basalt_Brick"
    },
    {
      "x": -10,
      "y": 1,
      "z": 7,
      "name": "Rock_Basalt"
    },
    {
      "x": -10,
      "y": 2,
      "z": 7,
      "name": "Rock_Basalt"
    },
    {
      "x": -10,
      "y": 3,
      "z": 7,
      "name": "Soil_Grass"
    },
    {
      "x": -10,
      "y": 4,
      "z": 7,
      "name": "Plant_Fern_Winter"
    },
    {
      "x": -10,
      "y": -6,
      "z": 8,
      "name": "Rock_Basalt"
    },
    {
      "x": -10,
      "y": -5,
      "z": 8,
      "name": "Rock_Basalt"
    },
    {
      "x": -10,
      "y": -4,
      "z": 8,
      "name": "Rock_Basalt"
    },
    {
      "x": -10,
      "y": -3,
      "z": 8,
      "name": "Rock_Basalt"
    },
    {
      "x": -10,
      "y": -2,
      "z": 8,
      "name": "Rock_Basalt"
    },
    {
      "x": -10,
      "y": -1,
      "z": 8,
      "name": "Rock_Basalt"
    },
    {
      "x": -9,
      "y": 2,
      "z": 4,
      "name": "Plant_Vine_Wall",
      "rotation": 2
    },
    {
      "x": -9,
      "y": 3,
      "z": 4,
      "name": "Plant_Vine",
      "rotation": 2
    },
    {
      "x": -9,
      "y": -6,
      "z": 5,
      "name": "Rock_Basalt"
    },
    {
      "x": -9,
      "y": -3,
      "z": 5,
      "name": "Rock_Basalt"
    },
    {
      "x": -9,
      "y": -2,
      "z": 5,
      "name": "Rock_Basalt"
    },
    {
      "x": -9,
      "y": -1,
      "z": 5,
      "name": "Rock_Basalt"
    },
    {
      "x": -9,
      "y": 0,
      "z": 5,
      "name": "Rock_Basalt_Brick"
    },
    {
      "x": -9,
      "y": 1,
      "z": 5,
      "name": "Rock_Basalt"
    },
    {
      "x": -9,
      "y": 2,
      "z": 5,
      "name": "Soil_Dirt"
    },
    {
      "x": -9,
      "y": 3,
      "z": 5,
      "name": "Soil_Grass"
    },
    {
      "x": -9,
      "y": 4,
      "z": 5,
      "name": "Plant_Crop_Mushroom_Common_Lime",
      "components": {
        "Components": {
          "FarmingBlock": {
            "LastTickGameTime": "0001-01-01T12:00:00Z"
          },
          "PlacedByInteraction": {
            "WhoPlacedUuid": {
              "$binary": "5RPZJ2uQSJ2g+KZxfjqR+g==",
              "$type": "04"
            }
          }
        }
      }
    },
    {
      "x": -9,
      "y": -6,
      "z": 6,
      "name": "Rock_Basalt"
    },
    {
      "x": -9,
      "y": -5,
      "z": 6,
      "name": "Rock_Basalt"
    },
    {
      "x": -9,
      "y": -4,
      "z": 6,
      "name": "Rock_Basalt"
    },
    {
      "x": -9,
      "y": -3,
      "z": 6,
      "name": "Rock_Basalt"
    },
    {
      "x": -9,
      "y": -2,
      "z": 6,
      "name": "Rock_Basalt"
    },
    {
      "x": -9,
      "y": -1,
      "z": 6,
      "name": "Rock_Basalt"
    },
    {
      "x": -9,
      "y": 0,
      "z": 6,
      "name": "Rock_Basalt_Brick"
    },
    {
      "x": -9,
      "y": 1,
      "z": 6,
      "name": "Rock_Basalt"
    },
    {
      "x": -9,
      "y": 2,
      "z": 6,
      "name": "Rock_Basalt"
    },
    {
      "x": -9,
      "y": 3,
      "z": 6,
      "name": "Soil_Grass"
    },
    {
      "x": -9,
      "y": 4,
      "z": 6,
      "name": "Plant_Grass_Sharp"
    },
    {
      "x": -9,
      "y": -6,
      "z": 7,
      "name": "Rock_Basalt"
    },
    {
      "x": -9,
      "y": -5,
      "z": 7,
      "name": "Rock_Basalt"
    },
    {
      "x": -9,
      "y": -4,
      "z": 7,
      "name": "Rock_Basalt"
    },
    {
      "x": -9,
      "y": -3,
      "z": 7,
      "name": "Rock_Basalt"
    },
    {
      "x": -9,
      "y": -2,
      "z": 7,
      "name": "Rock_Basalt"
    },
    {
      "x": -9,
      "y": -1,
      "z": 7,
      "name": "Rock_Basalt"
    },
    {
      "x": -9,
      "y": 0,
      "z": 7,
      "name": "Rock_Basalt_Brick"
    },
    {
      "x": -9,
      "y": 1,
      "z": 7,
      "name": "Rock_Basalt"
    },
    {
      "x": -9,
      "y": 2,
      "z": 7,
      "name": "Rock_Basalt"
    },
    {
      "x": -9,
      "y": 3,
      "z": 7,
      "name": "Rock_Basalt"
    },
    {
      "x": -9,
      "y": 4,
      "z": 7,
      "name": "Rock_Basalt"
    },
    {
      "x": -9,
      "y": -6,
      "z": 8,
      "name": "Rock_Basalt"
    },
    {
      "x": -9,
      "y": -5,
      "z": 8,
      "name": "Rock_Basalt"
    },
    {
      "x": -9,
      "y": -4,
      "z": 8,
      "name": "Rock_Basalt"
    },
    {
      "x": -9,
      "y": -3,
      "z": 8,
      "name": "Rock_Basalt"
    },
    {
      "x": -9,
      "y": -2,
      "z": 8,
      "name": "Rock_Basalt"
    },
    {
      "x": -9,
      "y": -1,
      "z": 8,
      "name": "Rock_Basalt"
    },
    {
      "x": -9,
      "y": 0,
      "z": 8,
      "name": "Rock_Basalt_Brick"
    },
    {
      "x": -9,
      "y": 1,
      "z": 8,
      "name": "Rock_Basalt_Brick_Half",
      "rotation": 4
    },
    {
      "x": -9,
      "y": 2,
      "z": 8,
      "name": "Rock_Basalt_Brick_Half",
      "rotation": 4
    },
    {
      "x": -8,
      "y": -6,
      "z": 4,
      "name": "Rock_Basalt"
    },
    {
      "x": -8,
      "y": 3,
      "z": 4,
      "name": "Plant_Vine",
      "rotation": 2
    },
    {
      "x": -8,
      "y": 4,
      "z": 4,
      "name": "Plant_Vine",
      "rotation": 2
    },
    {
      "x": -8,
      "y": -6,
      "z": 5,
      "name": "Rock_Basalt"
    },
    {
      "x": -8,
      "y": -5,
      "z": 5,
      "name": "Rock_Basalt"
    },
    {
      "x": -8,
      "y": -3,
      "z": 5,
      "name": "Rock_Basalt"
    },
    {
      "x": -8,
      "y": -2,
      "z": 5,
      "name": "Rock_Basalt"
    },
    {
      "x": -8,
      "y": -1,
      "z": 5,
      "name": "Rock_Basalt"
    },
    {
      "x": -8,
      "y": 0,
      "z": 5,
      "name": "Rock_Basalt_Brick"
    },
    {
      "x": -8,
      "y": 1,
      "z": 5,
      "name": "Rock_Basalt"
    },
    {
      "x": -8,
      "y": 2,
      "z": 5,
      "name": "Soil_Dirt"
    },
    {
      "x": -8,
      "y": 3,
      "z": 5,
      "name": "Soil_Dirt"
    },
    {
      "x": -8,
      "y": 4,
      "z": 5,
      "name": "Soil_Grass"
    },
    {
      "x": -8,
      "y": -6,
      "z": 6,
      "name": "Rock_Basalt"
    },
    {
      "x": -8,
      "y": -5,
      "z": 6,
      "name": "Rock_Basalt"
    },
    {
      "x": -8,
      "y": -4,
      "z": 6,
      "name": "Rock_Basalt"
    },
    {
      "x": -8,
      "y": -3,
      "z": 6,
      "name": "Rock_Basalt"
    },
    {
      "x": -8,
      "y": -2,
      "z": 6,
      "name": "Rock_Basalt"
    },
    {
      "x": -8,
      "y": -1,
      "z": 6,
      "name": "Rock_Basalt"
    },
    {
      "x": -8,
      "y": 0,
      "z": 6,
      "name": "Rock_Basalt_Brick"
    },
    {
      "x": -8,
      "y": 1,
      "z": 6,
      "name": "Rock_Basalt"
    },
    {
      "x": -8,
      "y": 2,
      "z": 6,
      "name": "Rock_Basalt"
    },
    {
      "x": -8,
      "y": 3,
      "z": 6,
      "name": "Rock_Basalt"
    },
    {
      "x": -8,
      "y": 4,
      "z": 6,
      "name": "Soil_Grass"
    },
    {
      "x": -8,
      "y": 5,
      "z": 6,
      "name": "Plant_Grass_Lush_Short"
    },
    {
      "x": -8,
      "y": -6,
      "z": 7,
      "name": "Rock_Basalt"
    },
    {
      "x": -8,
      "y": -5,
      "z": 7,
      "name": "Rock_Basalt"
    },
    {
      "x": -8,
      "y": -4,
      "z": 7,
      "name": "Rock_Basalt"
    },
    {
      "x": -8,
      "y": -3,
      "z": 7,
      "name": "Rock_Basalt"
    },
    {
      "x": -8,
      "y": -2,
      "z": 7,
      "name": "Rock_Basalt"
    },
    {
      "x": -8,
      "y": -1,
      "z": 7,
      "name": "Rock_Basalt"
    },
    {
      "x": -8,
      "y": 0,
      "z": 7,
      "name": "Rock_Basalt_Brick"
    },
    {
      "x": -8,
      "y": 1,
      "z": 7,
      "name": "Rock_Basalt"
    },
    {
      "x": -8,
      "y": 2,
      "z": 7,
      "name": "Rock_Basalt"
    },
    {
      "x": -8,
      "y": 3,
      "z": 7,
      "name": "Soil_Dirt"
    },
    {
      "x": -8,
      "y": 4,
      "z": 7,
      "name": "Soil_Grass"
    },
    {
      "x": -8,
      "y": -6,
      "z": 8,
      "name": "Rock_Basalt"
    },
    {
      "x": -8,
      "y": -3,
      "z": 8,
      "name": "Rock_Basalt"
    },
    {
      "x": -8,
      "y": -2,
      "z": 8,
      "name": "Rock_Basalt"
    },
    {
      "x": -8,
      "y": -1,
      "z": 8,
      "name": "Rock_Basalt"
    },
    {
      "x": -8,
      "y": 3,
      "z": 8,
      "name": "Rock_Basalt_Brick"
    },
    {
      "x": -7,
      "y": -2,
      "z": 1,
      "name": "Rock_Basalt"
    },
    {
      "x": -7,
      "y": -6,
      "z": 3,
      "name": "Rock_Basalt"
    },
    {
      "x": -7,
      "y": -6,
      "z": 4,
      "name": "Rock_Basalt"
    },
    {
      "x": -7,
      "y": -5,
      "z": 4,
      "name": "Rock_Basalt"
    },
    {
      "x": -7,
      "y": -3,
      "z": 4,
      "name": "Rock_Basalt"
    },
    {
      "x": -7,
      "y": -2,
      "z": 4,
      "name": "Rock_Basalt"
    },
    {
      "x": -7,
      "y": 3,
      "z": 4,
      "name": "Plant_Vine_Wall",
      "rotation": 2
    },
    {
      "x": -7,
      "y": -6,
      "z": 5,
      "name": "Rock_Basalt"
    },
    {
      "x": -7,
      "y": -5,
      "z": 5,
      "name": "Rock_Basalt"
    },
    {
      "x": -7,
      "y": -4,
      "z": 5,
      "name": "Rock_Basalt"
    },
    {
      "x": -7,
      "y": -3,
      "z": 5,
      "name": "Rock_Basalt"
    },
    {
      "x": -7,
      "y": -2,
      "z": 5,
      "name": "Rock_Basalt"
    },
    {
      "x": -7,
      "y": -1,
      "z": 5,
      "name": "Rock_Basalt"
    },
    {
      "x": -7,
      "y": 0,
      "z": 5,
      "name": "Rock_Basalt_Brick"
    },
    {
      "x": -7,
      "y": 1,
      "z": 5,
      "name": "Rock_Basalt_Cobble"
    },
    {
      "x": -7,
      "y": 3,
      "z": 5,
      "name": "Soil_Dirt"
    },
    {
      "x": -7,
      "y": 4,
      "z": 5,
      "name": "Soil_Grass"
    },
    {
      "x": -7,
      "y": 5,
      "z": 5,
      "name": "Plant_Grass_Lush"
    },
    {
      "x": -7,
      "y": -6,
      "z": 6,
      "name": "Rock_Basalt"
    },
    {
      "x": -7,
      "y": -5,
      "z": 6,
      "name": "Rock_Basalt"
    },
    {
      "x": -7,
      "y": -4,
      "z": 6,
      "name": "Rock_Basalt"
    },
    {
      "x": -7,
      "y": -3,
      "z": 6,
      "name": "Rock_Basalt"
    },
    {
      "x": -7,
      "y": -2,
      "z": 6,
      "name": "Rock_Basalt"
    },
    {
      "x": -7,
      "y": -1,
      "z": 6,
      "name": "Rock_Basalt"
    },
    {
      "x": -7,
      "y": 0,
      "z": 6,
      "name": "Rock_Basalt_Brick"
    },
    {
      "x": -7,
      "y": 1,
      "z": 6,
      "name": "Rock_Basalt"
    },
    {
      "x": -7,
      "y": 2,
      "z": 6,
      "name": "Rock_Basalt"
    },
    {
      "x": -7,
      "y": 3,
      "z": 6,
      "name": "Rock_Basalt"
    },
    {
      "x": -7,
      "y": 4,
      "z": 6,
      "name": "Soil_Grass"
    },
    {
      "x": -7,
      "y": -6,
      "z": 7,
      "name": "Rock_Basalt"
    },
    {
      "x": -7,
      "y": -5,
      "z": 7,
      "name": "Rock_Basalt"
    },
    {
      "x": -7,
      "y": -4,
      "z": 7,
      "name": "Rock_Basalt"
    },
    {
      "x": -7,
      "y": -3,
      "z": 7,
      "name": "Rock_Basalt"
    },
    {
      "x": -7,
      "y": -2,
      "z": 7,
      "name": "Rock_Basalt"
    },
    {
      "x": -7,
      "y": -1,
      "z": 7,
      "name": "Rock_Basalt"
    },
    {
      "x": -7,
      "y": 0,
      "z": 7,
      "name": "Rock_Basalt_Brick"
    },
    {
      "x": -7,
      "y": 1,
      "z": 7,
      "name": "Rock_Basalt"
    },
    {
      "x": -7,
      "y": 2,
      "z": 7,
      "name": "Rock_Basalt"
    },
    {
      "x": -7,
      "y": 3,
      "z": 7,
      "name": "Soil_Dirt"
    },
    {
      "x": -7,
      "y": 4,
      "z": 7,
      "name": "Soil_Dirt"
    },
    {
      "x": -7,
      "y": 5,
      "z": 7,
      "name": "Soil_Grass"
    },
    {
      "x": -7,
      "y": -6,
      "z": 8,
      "name": "Rock_Basalt"
    },
    {
      "x": -7,
      "y": -5,
      "z": 8,
      "name": "Rock_Basalt"
    },
    {
      "x": -7,
      "y": -3,
      "z": 8,
      "name": "Rock_Basalt"
    },
    {
      "x": -7,
      "y": -2,
      "z": 8,
      "name": "Rock_Basalt"
    },
    {
      "x": -6,
      "y": -2,
      "z": 0,
      "name": "Rock_Basalt"
    },
    {
      "x": -6,
      "y": -2,
      "z": 1,
      "name": "Rock_Basalt"
    },
    {
      "x": -6,
      "y": -6,
      "z": 2,
      "name": "Rock_Basalt"
    },
    {
      "x": -6,
      "y": -2,
      "z": 2,
      "name": "Rock_Basalt"
    },
    {
      "x": -6,
      "y": -6,
      "z": 3,
      "name": "Rock_Basalt"
    },
    {
      "x": -6,
      "y": -5,
      "z": 3,
      "name": "Rock_Basalt"
    },
    {
      "x": -6,
      "y": -6,
      "z": 4,
      "name": "Rock_Basalt"
    },
    {
      "x": -6,
      "y": -5,
      "z": 4,
      "name": "Rock_Basalt"
    },
    {
      "x": -6,
      "y": -4,
      "z": 4,
      "name": "Rock_Basalt"
    },
    {
      "x": -6,
      "y": -3,
      "z": 4,
      "name": "Rock_Basalt"
    },
    {
      "x": -6,
      "y": -2,
      "z": 4,
      "name": "Rock_Basalt"
    },
    {
      "x": -6,
      "y": -6,
      "z": 5,
      "name": "Rock_Basalt"
    },
    {
      "x": -6,
      "y": -5,
      "z": 5,
      "name": "Rock_Basalt"
    },
    {
      "x": -6,
      "y": -4,
      "z": 5,
      "name": "Rock_Basalt"
    },
    {
      "x": -6,
      "y": -3,
      "z": 5,
      "name": "Rock_Basalt"
    },
    {
      "x": -6,
      "y": -2,
      "z": 5,
      "name": "Rock_Basalt"
    },
    {
      "x": -6,
      "y": 2,
      "z": 5,
      "name": "Plant_Roots_Cave_Small",
      "rotation": 8
    },
    {
      "x": -6,
      "y": 3,
      "z": 5,
      "name": "Soil_Dirt"
    },
    {
      "x": -6,
      "y": 4,
      "z": 5,
      "name": "Soil_Grass"
    },
    {
      "x": -6,
      "y": -6,
      "z": 6,
      "name": "Rock_Basalt"
    },
    {
      "x": -6,
      "y": -5,
      "z": 6,
      "name": "Rock_Basalt"
    },
    {
      "x": -6,
      "y": -4,
      "z": 6,
      "name": "Rock_Basalt"
    },
    {
      "x": -6,
      "y": -3,
      "z": 6,
      "name": "Rock_Basalt"
    },
    {
      "x": -6,
      "y": -2,
      "z": 6,
      "name": "Rock_Basalt"
    },
    {
      "x": -6,
      "y": 3,
      "z": 6,
      "name": "Soil_Dirt"
    },
    {
      "x": -6,
      "y": 4,
      "z": 6,
      "name": "Rock_Basalt_Cobble"
    },
    {
      "x": -6,
      "y": -6,
      "z": 7,
      "name": "Rock_Basalt"
    },
    {
      "x": -6,
      "y": -5,
      "z": 7,
      "name": "Rock_Basalt"
    },
    {
      "x": -6,
      "y": -4,
      "z": 7,
      "name": "Rock_Basalt"
    },
    {
      "x": -6,
      "y": -3,
      "z": 7,
      "name": "Rock_Basalt"
    },
    {
      "x": -6,
      "y": -2,
      "z": 7,
      "name": "Rock_Basalt"
    },
    {
      "x": -6,
      "y": 1,
      "z": 7,
      "name": "Rock_Basalt"
    },
    {
      "x": -6,
      "y": 2,
      "z": 7,
      "name": "Rock_Basalt"
    },
    {
      "x": -6,
      "y": 3,
      "z": 7,
      "name": "Rock_Basalt"
    },
    {
      "x": -6,
      "y": 4,
      "z": 7,
      "name": "Soil_Dirt"
    },
    {
      "x": -6,
      "y": 5,
      "z": 7,
      "name": "Soil_Grass"
    },
    {
      "x": -6,
      "y": 6,
      "z": 7,
      "name": "Plant_Grass_Lush_Short"
    },
    {
      "x": -6,
      "y": -6,
      "z": 8,
      "name": "Rock_Basalt"
    },
    {
      "x": -6,
      "y": -5,
      "z": 8,
      "name": "Rock_Basalt"
    },
    {
      "x": -6,
      "y": -4,
      "z": 8,
      "name": "Rock_Basalt"
    },
    {
      "x": -6,
      "y": -3,
      "z": 8,
      "name": "Rock_Basalt"
    },
    {
      "x": -6,
      "y": -2,
      "z": 8,
      "name": "Rock_Basalt"
    },
    {
      "x": -6,
      "y": 5,
      "z": 8,
      "name": "Rock_Basalt_Brick"
    },
    {
      "x": -5,
      "y": -2,
      "z": -1,
      "name": "Rock_Basalt"
    },
    {
      "x": -5,
      "y": -2,
      "z": 0,
      "name": "Rock_Basalt"
    },
    {
      "x": -5,
      "y": -3,
      "z": 1,
      "name": "Rock_Basalt"
    },
    {
      "x": -5,
      "y": -2,
      "z": 1,
      "name": "Rock_Basalt"
    },
    {
      "x": -5,
      "y": -6,
      "z": 2,
      "name": "Rock_Basalt"
    },
    {
      "x": -5,
      "y": -3,
      "z": 2,
      "name": "Rock_Basalt"
    },
    {
      "x": -5,
      "y": -2,
      "z": 2,
      "name": "Rock_Basalt"
    },
    {
      "x": -5,
      "y": -6,
      "z": 3,
      "name": "Rock_Basalt"
    },
    {
      "x": -5,
      "y": -3,
      "z": 3,
      "name": "Rock_Basalt"
    },
    {
      "x": -5,
      "y": -2,
      "z": 3,
      "name": "Rock_Basalt"
    },
    {
      "x": -5,
      "y": -6,
      "z": 4,
      "name": "Rock_Basalt"
    },
    {
      "x": -5,
      "y": -5,
      "z": 4,
      "name": "Rock_Basalt"
    },
    {
      "x": -5,
      "y": -4,
      "z": 4,
      "name": "Rock_Basalt"
    },
    {
      "x": -5,
      "y": -3,
      "z": 4,
      "name": "Rock_Basalt"
    },
    {
      "x": -5,
      "y": -2,
      "z": 4,
      "name": "Rock_Basalt"
    },
    {
      "x": -5,
      "y": -6,
      "z": 5,
      "name": "Rock_Basalt"
    },
    {
      "x": -5,
      "y": -5,
      "z": 5,
      "name": "Rock_Basalt"
    },
    {
      "x": -5,
      "y": -4,
      "z": 5,
      "name": "Rock_Basalt"
    },
    {
      "x": -5,
      "y": -3,
      "z": 5,
      "name": "Rock_Basalt"
    },
    {
      "x": -5,
      "y": -2,
      "z": 5,
      "name": "Rock_Basalt"
    },
    {
      "x": -5,
      "y": 3,
      "z": 5,
      "name": "Soil_Dirt"
    },
    {
      "x": -5,
      "y": 4,
      "z": 5,
      "name": "Rock_Basalt_Cobble"
    },
    {
      "x": -5,
      "y": -6,
      "z": 6,
      "name": "Rock_Basalt"
    },
    {
      "x": -5,
      "y": -5,
      "z": 6,
      "name": "Rock_Basalt"
    },
    {
      "x": -5,
      "y": -4,
      "z": 6,
      "name": "Rock_Basalt"
    },
    {
      "x": -5,
      "y": -3,
      "z": 6,
      "name": "Rock_Basalt"
    },
    {
      "x": -5,
      "y": -2,
      "z": 6,
      "name": "Rock_Basalt"
    },
    {
      "x": -5,
      "y": 4,
      "z": 6,
      "name": "Rock_Basalt_Cobble"
    },
    {
      "x": -5,
      "y": -6,
      "z": 7,
      "name": "Rock_Basalt"
    },
    {
      "x": -5,
      "y": -5,
      "z": 7,
      "name": "Rock_Basalt"
    },
    {
      "x": -5,
      "y": -4,
      "z": 7,
      "name": "Rock_Basalt"
    },
    {
      "x": -5,
      "y": -3,
      "z": 7,
      "name": "Rock_Basalt"
    },
    {
      "x": -5,
      "y": -2,
      "z": 7,
      "name": "Rock_Basalt"
    },
    {
      "x": -5,
      "y": 4,
      "z": 7,
      "name": "Rock_Basalt_Cobble"
    },
    {
      "x": -5,
      "y": 5,
      "z": 7,
      "name": "Soil_Grass"
    },
    {
      "x": -5,
      "y": -3,
      "z": 8,
      "name": "Rock_Basalt"
    },
    {
      "x": -5,
      "y": -2,
      "z": 8,
      "name": "Rock_Basalt"
    },
    {
      "x": -5,
      "y": 5,
      "z": 8,
      "name": "Rock_Basalt_Brick"
    },
    {
      "x": -4,
      "y": -2,
      "z": -8,
      "name": "Rock_Basalt"
    },
    {
      "x": -4,
      "y": -1,
      "z": -6,
      "name": "Rock_Basalt"
    },
    {
      "x": -4,
      "y": -2,
      "z": -5,
      "name": "Rock_Basalt"
    },
    {
      "x": -4,
      "y": -1,
      "z": -5,
      "name": "Rock_Basalt"
    },
    {
      "x": -4,
      "y": -2,
      "z": -3,
      "name": "Rock_Basalt"
    },
    {
      "x": -4,
      "y": -2,
      "z": -2,
      "name": "Rock_Basalt"
    },
    {
      "x": -4,
      "y": -3,
      "z": -1,
      "name": "Rock_Basalt"
    },
    {
      "x": -4,
      "y": -2,
      "z": -1,
      "name": "Rock_Basalt"
    },
    {
      "x": -4,
      "y": -2,
      "z": 0,
      "name": "Rock_Basalt"
    },
    {
      "x": -4,
      "y": -3,
      "z": 1,
      "name": "Rock_Basalt"
    },
    {
      "x": -4,
      "y": -2,
      "z": 1,
      "name": "Rock_Basalt"
    },
    {
      "x": -4,
      "y": -6,
      "z": 2,
      "name": "Rock_Basalt"
    },
    {
      "x": -4,
      "y": -3,
      "z": 2,
      "name": "Rock_Basalt"
    },
    {
      "x": -4,
      "y": -2,
      "z": 2,
      "name": "Rock_Basalt"
    },
    {
      "x": -4,
      "y": -6,
      "z": 3,
      "name": "Rock_Basalt"
    },
    {
      "x": -4,
      "y": -5,
      "z": 3,
      "name": "Rock_Basalt"
    },
    {
      "x": -4,
      "y": -4,
      "z": 3,
      "name": "Rock_Basalt"
    },
    {
      "x": -4,
      "y": -3,
      "z": 3,
      "name": "Rock_Basalt"
    },
    {
      "x": -4,
      "y": -2,
      "z": 3,
      "name": "Rock_Basalt"
    },
    {
      "x": -4,
      "y": -6,
      "z": 4,
      "name": "Rock_Basalt"
    },
    {
      "x": -4,
      "y": -5,
      "z": 4,
      "name": "Rock_Basalt"
    },
    {
      "x": -4,
      "y": -4,
      "z": 4,
      "name": "Rock_Basalt"
    },
    {
      "x": -4,
      "y": -3,
      "z": 4,
      "name": "Rock_Basalt"
    },
    {
      "x": -4,
      "y": -2,
      "z": 4,
      "name": "Rock_Basalt"
    },
    {
      "x": -4,
      "y": -6,
      "z": 5,
      "name": "Rock_Basalt"
    },
    {
      "x": -4,
      "y": -5,
      "z": 5,
      "name": "Rock_Basalt"
    },
    {
      "x": -4,
      "y": -4,
      "z": 5,
      "name": "Rock_Basalt"
    },
    {
      "x": -4,
      "y": -3,
      "z": 5,
      "name": "Rock_Basalt"
    },
    {
      "x": -4,
      "y": -2,
      "z": 5,
      "name": "Rock_Basalt"
    },
    {
      "x": -4,
      "y": 4,
      "z": 5,
      "name": "Rock_Basalt_Cobble"
    },
    {
      "x": -4,
      "y": -6,
      "z": 6,
      "name": "Rock_Basalt"
    },
    {
      "x": -4,
      "y": -5,
      "z": 6,
      "name": "Rock_Basalt"
    },
    {
      "x": -4,
      "y": -4,
      "z": 6,
      "name": "Rock_Basalt"
    },
    {
      "x": -4,
      "y": -3,
      "z": 6,
      "name": "Rock_Basalt"
    },
    {
      "x": -4,
      "y": -2,
      "z": 6,
      "name": "Rock_Basalt"
    },
    {
      "x": -4,
      "y": 4,
      "z": 6,
      "name": "Rock_Basalt"
    },
    {
      "x": -4,
      "y": 5,
      "z": 6,
      "name": "Rock_Basalt_Cobble"
    },
    {
      "x": -4,
      "y": -3,
      "z": 7,
      "name": "Rock_Basalt"
    },
    {
      "x": -4,
      "y": -2,
      "z": 7,
      "name": "Rock_Basalt"
    },
    {
      "x": -4,
      "y": 4,
      "z": 7,
      "name": "Rock_Basalt_Cobble"
    },
    {
      "x": -4,
      "y": 5,
      "z": 7,
      "name": "Soil_Grass"
    },
    {
      "x": -4,
      "y": 6,
      "z": 7,
      "name": "Plant_Grass_Sharp"
    },
    {
      "x": -4,
      "y": 5,
      "z": 8,
      "name": "Rock_Basalt_Brick_Half",
      "rotation": 8
    },
    {
      "x": -3,
      "y": -2,
      "z": -9,
      "name": "Rock_Basalt"
    },
    {
      "x": -3,
      "y": -2,
      "z": -8,
      "name": "Rock_Basalt"
    },
    {
      "x": -3,
      "y": -1,
      "z": -8,
      "name": "Rock_Basalt"
    },
    {
      "x": -3,
      "y": 0,
      "z": -8,
      "name": "Rock_Basalt_Brick_Stairs",
      "rotation": 3
    },
    {
      "x": -3,
      "y": -2,
      "z": -7,
      "name": "Rock_Basalt"
    },
    {
      "x": -3,
      "y": -1,
      "z": -7,
      "name": "Rock_Basalt"
    },
    {
      "x": -3,
      "y": 0,
      "z": -7,
      "name": "Rock_Basalt_Brick_Stairs",
      "rotation": 3
    },
    {
      "x": -3,
      "y": -2,
      "z": -6,
      "name": "Rock_Basalt"
    },
    {
      "x": -3,
      "y": -1,
      "z": -6,
      "name": "Rock_Basalt"
    },
    {
      "x": -3,
      "y": 0,
      "z": -6,
      "name": "Rock_Basalt_Brick_Half",
      "rotation": 7
    },
    {
      "x": -3,
      "y": -2,
      "z": -5,
      "name": "Rock_Basalt"
    },
    {
      "x": -3,
      "y": -1,
      "z": -5,
      "name": "Rock_Basalt"
    },
    {
      "x": -3,
      "y": -2,
      "z": -4,
      "name": "Rock_Basalt"
    },
    {
      "x": -3,
      "y": -3,
      "z": -3,
      "name": "Rock_Basalt"
    },
    {
      "x": -3,
      "y": -2,
      "z": -3,
      "name": "Rock_Basalt"
    },
    {
      "x": -3,
      "y": -3,
      "z": -2,
      "name": "Rock_Basalt"
    },
    {
      "x": -3,
      "y": -2,
      "z": -2,
      "name": "Rock_Basalt"
    },
    {
      "x": -3,
      "y": -3,
      "z": -1,
      "name": "Rock_Basalt"
    },
    {
      "x": -3,
      "y": -2,
      "z": -1,
      "name": "Rock_Basalt"
    },
    {
      "x": -3,
      "y": -3,
      "z": 0,
      "name": "Rock_Basalt"
    },
    {
      "x": -3,
      "y": -2,
      "z": 0,
      "name": "Rock_Basalt"
    },
    {
      "x": -3,
      "y": -6,
      "z": 1,
      "name": "Rock_Basalt"
    },
    {
      "x": -3,
      "y": -4,
      "z": 1,
      "name": "Rock_Basalt"
    },
    {
      "x": -3,
      "y": -3,
      "z": 1,
      "name": "Rock_Basalt"
    },
    {
      "x": -3,
      "y": -2,
      "z": 1,
      "name": "Rock_Basalt"
    },
    {
      "x": -3,
      "y": -6,
      "z": 2,
      "name": "Rock_Basalt"
    },
    {
      "x": -3,
      "y": -5,
      "z": 2,
      "name": "Rock_Basalt"
    },
    {
      "x": -3,
      "y": -4,
      "z": 2,
      "name": "Rock_Basalt"
    },
    {
      "x": -3,
      "y": -3,
      "z": 2,
      "name": "Rock_Basalt"
    },
    {
      "x": -3,
      "y": -2,
      "z": 2,
      "name": "Rock_Basalt"
    },
    {
      "x": -3,
      "y": -6,
      "z": 3,
      "name": "Rock_Basalt"
    },
    {
      "x": -3,
      "y": -5,
      "z": 3,
      "name": "Rock_Basalt"
    },
    {
      "x": -3,
      "y": -4,
      "z": 3,
      "name": "Rock_Basalt"
    },
    {
      "x": -3,
      "y": -3,
      "z": 3,
      "name": "Rock_Basalt"
    },
    {
      "x": -3,
      "y": -2,
      "z": 3,
      "name": "Rock_Basalt"
    },
    {
      "x": -3,
      "y": -6,
      "z": 4,
      "name": "Rock_Basalt"
    },
    {
      "x": -3,
      "y": -5,
      "z": 4,
      "name": "Rock_Basalt"
    },
    {
      "x": -3,
      "y": -4,
      "z": 4,
      "name": "Rock_Basalt"
    },
    {
      "x": -3,
      "y": -3,
      "z": 4,
      "name": "Rock_Basalt"
    },
    {
      "x": -3,
      "y": -2,
      "z": 4,
      "name": "Rock_Basalt"
    },
    {
      "x": -3,
      "y": -6,
      "z": 5,
      "name": "Rock_Basalt"
    },
    {
      "x": -3,
      "y": -5,
      "z": 5,
      "name": "Rock_Basalt"
    },
    {
      "x": -3,
      "y": -4,
      "z": 5,
      "name": "Rock_Basalt"
    },
    {
      "x": -3,
      "y": -3,
      "z": 5,
      "name": "Rock_Basalt"
    },
    {
      "x": -3,
      "y": -2,
      "z": 5,
      "name": "Rock_Basalt"
    },
    {
      "x": -3,
      "y": -1,
      "z": 5,
      "name": "Rock_Basalt_Cobble"
    },
    {
      "x": -3,
      "y": 0,
      "z": 5,
      "name": "Rock_Basalt_Cobble"
    },
    {
      "x": -3,
      "y": 4,
      "z": 5,
      "name": "Rock_Basalt"
    },
    {
      "x": -3,
      "y": 5,
      "z": 5,
      "name": "Soil_Grass"
    },
    {
      "x": -3,
      "y": -6,
      "z": 6,
      "name": "Rock_Basalt"
    },
    {
      "x": -3,
      "y": -5,
      "z": 6,
      "name": "Rock_Basalt"
    },
    {
      "x": -3,
      "y": -4,
      "z": 6,
      "name": "Rock_Basalt"
    },
    {
      "x": -3,
      "y": -3,
      "z": 6,
      "name": "Rock_Basalt"
    },
    {
      "x": -3,
      "y": -2,
      "z": 6,
      "name": "Rock_Basalt"
    },
    {
      "x": -3,
      "y": -1,
      "z": 6,
      "name": "Rock_Basalt_Cobble"
    },
    {
      "x": -3,
      "y": 0,
      "z": 6,
      "name": "Rock_Basalt_Cobble"
    },
    {
      "x": -3,
      "y": 1,
      "z": 6,
      "name": "Rock_Basalt_Cobble"
    },
    {
      "x": -3,
      "y": 4,
      "z": 6,
      "name": "Rock_Basalt"
    },
    {
      "x": -3,
      "y": 5,
      "z": 6,
      "name": "Soil_Grass"
    },
    {
      "x": -3,
      "y": -4,
      "z": 7,
      "name": "Rock_Basalt"
    },
    {
      "x": -3,
      "y": -3,
      "z": 7,
      "name": "Rock_Basalt"
    },
    {
      "x": -3,
      "y": -2,
      "z": 7,
      "name": "Rock_Basalt"
    },
    {
      "x": -3,
      "y": -1,
      "z": 7,
      "name": "Rock_Basalt"
    },
    {
      "x": -3,
      "y": 3,
      "z": 7,
      "name": "Rock_Basalt_Cobble"
    },
    {
      "x": -3,
      "y": 4,
      "z": 7,
      "name": "Rock_Basalt_Cobble"
    },
    {
      "x": -3,
      "y": 5,
      "z": 7,
      "name": "Soil_Grass"
    },
    {
      "x": -3,
      "y": 6,
      "z": 7,
      "name": "Plant_Grass_Sharp_Tall"
    },
    {
      "x": -3,
      "y": 7,
      "z": 7,
      "name": "Plant_Grass_Sharp_Tall",
      "filler": 1024
    },
    {
      "x": -3,
      "y": 5,
      "z": 8,
      "name": "Rock_Basalt_Brick_Half",
      "rotation": 8
    },
    {
      "x": -2,
      "y": -2,
      "z": -9,
      "name": "Rock_Basalt"
    },
    {
      "x": -2,
      "y": -2,
      "z": -8,
      "name": "Rock_Basalt"
    },
    {
      "x": -2,
      "y": -1,
      "z": -8,
      "name": "Rock_Basalt"
    },
    {
      "x": -2,
      "y": 0,
      "z": -8,
      "name": "Rock_Basalt_Brick"
    },
    {
      "x": -2,
      "y": 1,
      "z": -8,
      "name": "Rock_Basalt_Brick_Stairs",
      "rotation": 3
    },
    {
      "x": -2,
      "y": -2,
      "z": -7,
      "name": "Rock_Basalt"
    },
    {
      "x": -2,
      "y": -1,
      "z": -7,
      "name": "Rock_Basalt"
    },
    {
      "x": -2,
      "y": 0,
      "z": -7,
      "name": "Rock_Basalt_Brick"
    },
    {
      "x": -2,
      "y": 1,
      "z": -7,
      "name": "Rock_Basalt_Brick_Half",
      "rotation": 7
    },
    {
      "x": -2,
      "y": -2,
      "z": -6,
      "name": "Rock_Basalt"
    },
    {
      "x": -2,
      "y": -1,
      "z": -6,
      "name": "Rock_Basalt"
    },
    {
      "x": -2,
      "y": 0,
      "z": -6,
      "name": "Rock_Basalt_Brick"
    },
    {
      "x": -2,
      "y": 1,
      "z": -6,
      "name": "Rock_Basalt_Brick_Half",
      "rotation": 7
    },
    {
      "x": -2,
      "y": -3,
      "z": -5,
      "name": "Rock_Basalt"
    },
    {
      "x": -2,
      "y": -2,
      "z": -5,
      "name": "Rock_Basalt"
    },
    {
      "x": -2,
      "y": -1,
      "z": -5,
      "name": "Rock_Basalt"
    },
    {
      "x": -2,
      "y": 0,
      "z": -5,
      "name": "Soil_Grass"
    },
    {
      "x": -2,
      "y": 1,
      "z": -5,
      "name": "Plant_Bush"
    },
    {
      "x": -2,
      "y": -3,
      "z": -4,
      "name": "Rock_Basalt"
    },
    {
      "x": -2,
      "y": -2,
      "z": -4,
      "name": "Rock_Basalt"
    },
    {
      "x": -2,
      "y": -1,
      "z": -4,
      "name": "Rock_Basalt"
    },
    {
      "x": -2,
      "y": 0,
      "z": -4,
      "name": "Soil_Grass"
    },
    {
      "x": -2,
      "y": -3,
      "z": -3,
      "name": "Rock_Basalt"
    },
    {
      "x": -2,
      "y": -2,
      "z": -3,
      "name": "Rock_Basalt"
    },
    {
      "x": -2,
      "y": -1,
      "z": -3,
      "name": "Rock_Basalt"
    },
    {
      "x": -2,
      "y": -4,
      "z": -2,
      "name": "Rock_Basalt"
    },
    {
      "x": -2,
      "y": -3,
      "z": -2,
      "name": "Rock_Basalt"
    },
    {
      "x": -2,
      "y": -2,
      "z": -2,
      "name": "Rock_Basalt"
    },
    {
      "x": -2,
      "y": -1,
      "z": -2,
      "name": "Rock_Basalt"
    },
    {
      "x": -2,
      "y": 0,
      "z": -2,
      "name": "Rock_Basalt_Cobble"
    },
    {
      "x": -2,
      "y": -4,
      "z": -1,
      "name": "Rock_Basalt"
    },
    {
      "x": -2,
      "y": -3,
      "z": -1,
      "name": "Rock_Basalt"
    },
    {
      "x": -2,
      "y": -2,
      "z": -1,
      "name": "Rock_Basalt"
    },
    {
      "x": -2,
      "y": -1,
      "z": -1,
      "name": "Rock_Basalt"
    },
    {
      "x": -2,
      "y": 0,
      "z": -1,
      "name": "Rock_Basalt_Cobble"
    },
    {
      "x": -2,
      "y": -4,
      "z": 0,
      "name": "Rock_Basalt"
    },
    {
      "x": -2,
      "y": -3,
      "z": 0,
      "name": "Rock_Basalt"
    },
    {
      "x": -2,
      "y": -2,
      "z": 0,
      "name": "Rock_Basalt"
    },
    {
      "x": -2,
      "y": -1,
      "z": 0,
      "name": "Rock_Basalt"
    },
    {
      "x": -2,
      "y": 0,
      "z": 0,
      "name": "Rock_Basalt_Cobble"
    },
    {
      "x": -2,
      "y": -6,
      "z": 1,
      "name": "Rock_Basalt"
    },
    {
      "x": -2,
      "y": -5,
      "z": 1,
      "name": "Rock_Basalt"
    },
    {
      "x": -2,
      "y": -4,
      "z": 1,
      "name": "Rock_Basalt"
    },
    {
      "x": -2,
      "y": -3,
      "z": 1,
      "name": "Rock_Basalt"
    },
    {
      "x": -2,
      "y": -2,
      "z": 1,
      "name": "Rock_Basalt"
    },
    {
      "x": -2,
      "y": -1,
      "z": 1,
      "name": "Rock_Basalt"
    },
    {
      "x": -2,
      "y": -6,
      "z": 2,
      "name": "Rock_Basalt"
    },
    {
      "x": -2,
      "y": -5,
      "z": 2,
      "name": "Rock_Basalt"
    },
    {
      "x": -2,
      "y": -4,
      "z": 2,
      "name": "Rock_Basalt"
    },
    {
      "x": -2,
      "y": -3,
      "z": 2,
      "name": "Rock_Basalt"
    },
    {
      "x": -2,
      "y": -2,
      "z": 2,
      "name": "Rock_Basalt"
    },
    {
      "x": -2,
      "y": -1,
      "z": 2,
      "name": "Rock_Basalt"
    },
    {
      "x": -2,
      "y": -6,
      "z": 3,
      "name": "Rock_Basalt"
    },
    {
      "x": -2,
      "y": -5,
      "z": 3,
      "name": "Rock_Basalt"
    },
    {
      "x": -2,
      "y": -4,
      "z": 3,
      "name": "Rock_Basalt"
    },
    {
      "x": -2,
      "y": -3,
      "z": 3,
      "name": "Rock_Basalt"
    },
    {
      "x": -2,
      "y": -2,
      "z": 3,
      "name": "Rock_Basalt"
    },
    {
      "x": -2,
      "y": -1,
      "z": 3,
      "name": "Rock_Basalt"
    },
    {
      "x": -2,
      "y": 0,
      "z": 3,
      "name": "Soil_Grass"
    },
    {
      "x": -2,
      "y": -6,
      "z": 4,
      "name": "Rock_Basalt"
    },
    {
      "x": -2,
      "y": -5,
      "z": 4,
      "name": "Rock_Basalt"
    },
    {
      "x": -2,
      "y": -4,
      "z": 4,
      "name": "Rock_Basalt"
    },
    {
      "x": -2,
      "y": -3,
      "z": 4,
      "name": "Rock_Basalt"
    },
    {
      "x": -2,
      "y": -2,
      "z": 4,
      "name": "Rock_Basalt"
    },
    {
      "x": -2,
      "y": -1,
      "z": 4,
      "name": "Rock_Basalt"
    },
    {
      "x": -2,
      "y": 0,
      "z": 4,
      "name": "Soil_Grass"
    },
    {
      "x": -2,
      "y": 4,
      "z": 4,
      "name": "Rock_Basalt_Brick_Half",
      "rotation": 6
    },
    {
      "x": -2,
      "y": -6,
      "z": 5,
      "name": "Rock_Basalt"
    },
    {
      "x": -2,
      "y": -5,
      "z": 5,
      "name": "Rock_Basalt"
    },
    {
      "x": -2,
      "y": -4,
      "z": 5,
      "name": "Rock_Basalt"
    },
    {
      "x": -2,
      "y": -3,
      "z": 5,
      "name": "Rock_Basalt"
    },
    {
      "x": -2,
      "y": -2,
      "z": 5,
      "name": "Rock_Basalt"
    },
    {
      "x": -2,
      "y": -1,
      "z": 5,
      "name": "Rock_Basalt"
    },
    {
      "x": -2,
      "y": 0,
      "z": 5,
      "name": "Rock_Basalt_Cobble"
    },
    {
      "x": -2,
      "y": 4,
      "z": 5,
      "name": "Rock_Basalt"
    },
    {
      "x": -2,
      "y": 5,
      "z": 5,
      "name": "Rock_Basalt"
    },
    {
      "x": -2,
      "y": -4,
      "z": 6,
      "name": "Rock_Basalt"
    },
    {
      "x": -2,
      "y": -3,
      "z": 6,
      "name": "Rock_Basalt"
    },
    {
      "x": -2,
      "y": -2,
      "z": 6,
      "name": "Rock_Basalt"
    },
    {
      "x": -2,
      "y": -1,
      "z": 6,
      "name": "Rock_Basalt"
    },
    {
      "x": -2,
      "y": 0,
      "z": 6,
      "name": "Rock_Basalt_Brick"
    },
    {
      "x": -2,
      "y": 1,
      "z": 6,
      "name": "Rock_Basalt"
    },
    {
      "x": -2,
      "y": 2,
      "z": 6,
      "name": "Rock_Basalt"
    },
    {
      "x": -2,
      "y": 3,
      "z": 6,
      "name": "Rock_Basalt"
    },
    {
      "x": -2,
      "y": 4,
      "z": 6,
      "name": "Rock_Basalt"
    },
    {
      "x": -2,
      "y": 5,
      "z": 6,
      "name": "Soil_Grass"
    },
    {
      "x": -2,
      "y": -3,
      "z": 7,
      "name": "Rock_Basalt"
    },
    {
      "x": -2,
      "y": -2,
      "z": 7,
      "name": "Rock_Basalt"
    },
    {
      "x": -2,
      "y": -1,
      "z": 7,
      "name": "Rock_Basalt"
    },
    {
      "x": -2,
      "y": 0,
      "z": 7,
      "name": "Rock_Basalt_Brick"
    },
    {
      "x": -2,
      "y": 1,
      "z": 7,
      "name": "Rock_Basalt"
    },
    {
      "x": -2,
      "y": 2,
      "z": 7,
      "name": "Rock_Basalt"
    },
    {
      "x": -2,
      "y": 3,
      "z": 7,
      "name": "Rock_Basalt"
    },
    {
      "x": -2,
      "y": 4,
      "z": 7,
      "name": "Rock_Basalt_Cobble"
    },
    {
      "x": -2,
      "y": 5,
      "z": 7,
      "name": "Soil_Grass"
    },
    {
      "x": -2,
      "y": 6,
      "z": 7,
      "name": "Plant_Grass_Sharp"
    },
    {
      "x": -2,
      "y": -1,
      "z": 8,
      "name": "Rock_Basalt"
    },
    {
      "x": -2,
      "y": 0,
      "z": 8,
      "name": "Rock_Basalt_Brick"
    },
    {
      "x": -2,
      "y": 1,
      "z": 8,
      "name": "Rock_Basalt_Brick_Half",
      "rotation": 4
    },
    {
      "x": -2,
      "y": 2,
      "z": 8,
      "name": "Rock_Basalt_Brick_Half",
      "rotation": 4
    },
    {
      "x": -2,
      "y": 3,
      "z": 8,
      "name": "Rock_Basalt_Brick_Half",
      "rotation": 4
    },
    {
      "x": -2,
      "y": 4,
      "z": 8,
      "name": "Rock_Basalt_Brick_Half",
      "rotation": 4
    },
    {
      "x": -2,
      "y": 5,
      "z": 8,
      "name": "Rock_Basalt_Brick"
    },
    {
      "x": -1,
      "y": -2,
      "z": -9,
      "name": "Rock_Basalt"
    },
    {
      "x": -1,
      "y": -2,
      "z": -8,
      "name": "Rock_Basalt"
    },
    {
      "x": -1,
      "y": -1,
      "z": -8,
      "name": "Rock_Basalt"
    },
    {
      "x": -1,
      "y": 0,
      "z": -8,
      "name": "Rock_Basalt"
    },
    {
      "x": -1,
      "y": 1,
      "z": -8,
      "name": "Rock_Basalt_Brick"
    },
    {
      "x": -1,
      "y": 2,
      "z": -8,
      "name": "Rock_Basalt_Brick_Stairs",
      "rotation": 3
    },
    {
      "x": -1,
      "y": -2,
      "z": -7,
      "name": "Rock_Basalt"
    },
    {
      "x": -1,
      "y": -1,
      "z": -7,
      "name": "Rock_Basalt"
    },
    {
      "x": -1,
      "y": 0,
      "z": -7,
      "name": "Rock_Basalt"
    },
    {
      "x": -1,
      "y": 1,
      "z": -7,
      "name": "Rock_Basalt_Brick"
    },
    {
      "x": -1,
      "y": 2,
      "z": -7,
      "name": "Rock_Basalt_Brick_Stairs",
      "rotation": 3
    },
    {
      "x": -1,
      "y": -2,
      "z": -6,
      "name": "Rock_Basalt"
    },
    {
      "x": -1,
      "y": -1,
      "z": -6,
      "name": "Rock_Basalt"
    },
    {
      "x": -1,
      "y": 0,
      "z": -6,
      "name": "Rock_Basalt"
    },
    {
      "x": -1,
      "y": 1,
      "z": -6,
      "name": "Rock_Basalt_Brick"
    },
    {
      "x": -1,
      "y": -2,
      "z": -5,
      "name": "Rock_Basalt"
    },
    {
      "x": -1,
      "y": -1,
      "z": -5,
      "name": "Rock_Basalt"
    },
    {
      "x": -1,
      "y": 0,
      "z": -5,
      "name": "Soil_Grass"
    },
    {
      "x": -1,
      "y": -3,
      "z": -4,
      "name": "Rock_Basalt"
    },
    {
      "x": -1,
      "y": -2,
      "z": -4,
      "name": "Rock_Basalt"
    },
    {
      "x": -1,
      "y": -1,
      "z": -4,
      "name": "Rock_Basalt"
    },
    {
      "x": -1,
      "y": 0,
      "z": -4,
      "name": "Rock_Basalt_Cobble"
    },
    {
      "x": -1,
      "y": 1,
      "z": -4,
      "name": "Rock_Basalt_Brick_Half"
    },
    {
      "x": -1,
      "y": -4,
      "z": -3,
      "name": "Rock_Basalt"
    },
    {
      "x": -1,
      "y": -3,
      "z": -3,
      "name": "Rock_Basalt"
    },
    {
      "x": -1,
      "y": -2,
      "z": -3,
      "name": "Rock_Basalt"
    },
    {
      "x": -1,
      "y": -1,
      "z": -3,
      "name": "Rock_Basalt"
    },
    {
      "x": -1,
      "y": 0,
      "z": -3,
      "name": "Rock_Basalt_Cobble"
    },
    {
      "x": -1,
      "y": -4,
      "z": -2,
      "name": "Rock_Basalt"
    },
    {
      "x": -1,
      "y": -3,
      "z": -2,
      "name": "Rock_Basalt"
    },
    {
      "x": -1,
      "y": -2,
      "z": -2,
      "name": "Rock_Basalt"
    },
    {
      "x": -1,
      "y": -1,
      "z": -2,
      "name": "Rock_Basalt"
    },
    {
      "x": -1,
      "y": 0,
      "z": -2,
      "name": "Rock_Basalt_Cobble"
    },
    {
      "x": -1,
      "y": -4,
      "z": -1,
      "name": "Rock_Basalt"
    },
    {
      "x": -1,
      "y": -3,
      "z": -1,
      "name": "Rock_Basalt"
    },
    {
      "x": -1,
      "y": -2,
      "z": -1,
      "name": "Rock_Basalt"
    },
    {
      "x": -1,
      "y": -1,
      "z": -1,
      "name": "Rock_Basalt"
    },
    {
      "x": -1,
      "y": 0,
      "z": -1,
      "name": "Rock_Basalt_Cobble"
    },
    {
      "x": -1,
      "y": -5,
      "z": 0,
      "name": "Rock_Basalt"
    },
    {
      "x": -1,
      "y": -4,
      "z": 0,
      "name": "Rock_Basalt"
    },
    {
      "x": -1,
      "y": -3,
      "z": 0,
      "name": "Rock_Basalt"
    },
    {
      "x": -1,
      "y": -2,
      "z": 0,
      "name": "Rock_Basalt"
    },
    {
      "x": -1,
      "y": -1,
      "z": 0,
      "name": "Rock_Basalt"
    },
    {
      "x": -1,
      "y": 0,
      "z": 0,
      "name": "Rock_Basalt_Cobble"
    },
    {
      "x": -1,
      "y": -6,
      "z": 1,
      "name": "Rock_Basalt"
    },
    {
      "x": -1,
      "y": -5,
      "z": 1,
      "name": "Rock_Basalt"
    },
    {
      "x": -1,
      "y": -4,
      "z": 1,
      "name": "Rock_Basalt"
    },
    {
      "x": -1,
      "y": -3,
      "z": 1,
      "name": "Rock_Basalt"
    },
    {
      "x": -1,
      "y": -2,
      "z": 1,
      "name": "Rock_Basalt"
    },
    {
      "x": -1,
      "y": -1,
      "z": 1,
      "name": "Rock_Basalt"
    },
    {
      "x": -1,
      "y": 0,
      "z": 1,
      "name": "Rock_Basalt_Cobble"
    },
    {
      "x": -1,
      "y": -6,
      "z": 2,
      "name": "Rock_Basalt"
    },
    {
      "x": -1,
      "y": -5,
      "z": 2,
      "name": "Rock_Basalt"
    },
    {
      "x": -1,
      "y": -4,
      "z": 2,
      "name": "Rock_Basalt"
    },
    {
      "x": -1,
      "y": -3,
      "z": 2,
      "name": "Rock_Basalt"
    },
    {
      "x": -1,
      "y": -2,
      "z": 2,
      "name": "Rock_Basalt"
    },
    {
      "x": -1,
      "y": -1,
      "z": 2,
      "name": "Rock_Basalt"
    },
    {
      "x": -1,
      "y": 0,
      "z": 2,
      "name": "Rock_Basalt_Cobble"
    },
    {
      "x": -1,
      "y": -6,
      "z": 3,
      "name": "Rock_Basalt"
    },
    {
      "x": -1,
      "y": -5,
      "z": 3,
      "name": "Rock_Basalt"
    },
    {
      "x": -1,
      "y": -4,
      "z": 3,
      "name": "Rock_Basalt"
    },
    {
      "x": -1,
      "y": -3,
      "z": 3,
      "name": "Rock_Basalt"
    },
    {
      "x": -1,
      "y": -2,
      "z": 3,
      "name": "Rock_Basalt"
    },
    {
      "x": -1,
      "y": -1,
      "z": 3,
      "name": "Rock_Basalt"
    },
    {
      "x": -1,
      "y": 0,
      "z": 3,
      "name": "Soil_Grass"
    },
    {
      "x": -1,
      "y": 1,
      "z": 3,
      "name": "Plant_Grass_Sharp_Tall"
    },
    {
      "x": -1,
      "y": 2,
      "z": 3,
      "name": "Plant_Grass_Sharp_Tall",
      "filler": 1024
    },
    {
      "x": -1,
      "y": -6,
      "z": 4,
      "name": "Rock_Basalt"
    },
    {
      "x": -1,
      "y": -5,
      "z": 4,
      "name": "Rock_Basalt"
    },
    {
      "x": -1,
      "y": -4,
      "z": 4,
      "name": "Rock_Basalt"
    },
    {
      "x": -1,
      "y": -3,
      "z": 4,
      "name": "Rock_Basalt"
    },
    {
      "x": -1,
      "y": -2,
      "z": 4,
      "name": "Rock_Basalt"
    },
    {
      "x": -1,
      "y": -1,
      "z": 4,
      "name": "Rock_Basalt"
    },
    {
      "x": -1,
      "y": 0,
      "z": 4,
      "name": "Soil_Grass"
    },
    {
      "x": -1,
      "y": 1,
      "z": 4,
      "name": "Plant_Bush"
    },
    {
      "x": -1,
      "y": -6,
      "z": 5,
      "name": "Rock_Basalt"
    },
    {
      "x": -1,
      "y": -5,
      "z": 5,
      "name": "Rock_Basalt"
    },
    {
      "x": -1,
      "y": -4,
      "z": 5,
      "name": "Rock_Basalt"
    },
    {
      "x": -1,
      "y": -3,
      "z": 5,
      "name": "Rock_Basalt"
    },
    {
      "x": -1,
      "y": -2,
      "z": 5,
      "name": "Rock_Basalt"
    },
    {
      "x": -1,
      "y": -1,
      "z": 5,
      "name": "Rock_Basalt"
    },
    {
      "x": -1,
      "y": 0,
      "z": 5,
      "name": "Rock_Basalt_Brick"
    },
    {
      "x": -1,
      "y": 1,
      "z": 5,
      "name": "Rock_Basalt"
    },
    {
      "x": -1,
      "y": 2,
      "z": 5,
      "name": "Rock_Basalt"
    },
    {
      "x": -1,
      "y": 3,
      "z": 5,
      "name": "Rock_Basalt_Cobble"
    },
    {
      "x": -1,
      "y": 5,
      "z": 5,
      "name": "Soil_Dirt"
    },
    {
      "x": -1,
      "y": 6,
      "z": 5,
      "name": "Soil_Grass"
    },
    {
      "x": -1,
      "y": 7,
      "z": 5,
      "name": "Plant_Crop_Mushroom_Common_Lime",
      "components": {
        "Components": {
          "FarmingBlock": {
            "LastTickGameTime": "0001-01-01T12:00:00Z"
          },
          "PlacedByInteraction": {
            "WhoPlacedUuid": {
              "$binary": "5RPZJ2uQSJ2g+KZxfjqR+g==",
              "$type": "04"
            }
          }
        }
      }
    },
    {
      "x": -1,
      "y": -3,
      "z": 6,
      "name": "Rock_Basalt"
    },
    {
      "x": -1,
      "y": -2,
      "z": 6,
      "name": "Rock_Basalt"
    },
    {
      "x": -1,
      "y": -1,
      "z": 6,
      "name": "Rock_Basalt"
    },
    {
      "x": -1,
      "y": 0,
      "z": 6,
      "name": "Rock_Basalt_Brick"
    },
    {
      "x": -1,
      "y": 1,
      "z": 6,
      "name": "Rock_Basalt"
    },
    {
      "x": -1,
      "y": 2,
      "z": 6,
      "name": "Rock_Basalt"
    },
    {
      "x": -1,
      "y": 3,
      "z": 6,
      "name": "Rock_Basalt"
    },
    {
      "x": -1,
      "y": 4,
      "z": 6,
      "name": "Rock_Basalt_Cobble"
    },
    {
      "x": -1,
      "y": 5,
      "z": 6,
      "name": "Rock_Basalt"
    },
    {
      "x": -1,
      "y": 6,
      "z": 6,
      "name": "Soil_Grass"
    },
    {
      "x": -1,
      "y": 7,
      "z": 6,
      "name": "Plant_Grass_Lush_Short"
    },
    {
      "x": -1,
      "y": -2,
      "z": 7,
      "name": "Rock_Basalt"
    },
    {
      "x": -1,
      "y": -1,
      "z": 7,
      "name": "Rock_Basalt"
    },
    {
      "x": -1,
      "y": 0,
      "z": 7,
      "name": "Rock_Basalt_Brick"
    },
    {
      "x": -1,
      "y": 1,
      "z": 7,
      "name": "Rock_Basalt_Cobble"
    },
    {
      "x": -1,
      "y": 2,
      "z": 7,
      "name": "Rock_Basalt_Cobble"
    },
    {
      "x": -1,
      "y": 3,
      "z": 7,
      "name": "Rock_Basalt_Cobble"
    },
    {
      "x": -1,
      "y": 4,
      "z": 7,
      "name": "Rock_Basalt_Cobble"
    },
    {
      "x": -1,
      "y": 5,
      "z": 7,
      "name": "Soil_Grass"
    },
    {
      "x": -1,
      "y": 6,
      "z": 7,
      "name": "Plant_Grass_Sharp_Tall"
    },
    {
      "x": -1,
      "y": 7,
      "z": 7,
      "name": "Plant_Grass_Sharp_Tall",
      "filler": 1024
    },
    {
      "x": -1,
      "y": -1,
      "z": 8,
      "name": "Rock_Basalt"
    },
    {
      "x": -1,
      "y": 6,
      "z": 8,
      "name": "Rock_Basalt_Brick_Half"
    },
    {
      "x": 0,
      "y": -2,
      "z": -9,
      "name": "Rock_Basalt"
    },
    {
      "x": 0,
      "y": -2,
      "z": -8,
      "name": "Rock_Basalt"
    },
    {
      "x": 0,
      "y": -1,
      "z": -8,
      "name": "Rock_Basalt"
    },
    {
      "x": 0,
      "y": 1,
      "z": -8,
      "name": "Rock_Basalt"
    },
    {
      "x": 0,
      "y": 2,
      "z": -8,
      "name": "Rock_Basalt_Brick"
    },
    {
      "x": 0,
      "y": 3,
      "z": -8,
      "name": "Rock_Basalt_Brick_Stairs",
      "rotation": 3
    },
    {
      "x": 0,
      "y": -1,
      "z": -7,
      "name": "Rock_Basalt"
    },
    {
      "x": 0,
      "y": 0,
      "z": -7,
      "name": "Rock_Basalt"
    },
    {
      "x": 0,
      "y": 1,
      "z": -7,
      "name": "Rock_Basalt"
    },
    {
      "x": 0,
      "y": 2,
      "z": -7,
      "name": "Rock_Basalt_Brick"
    },
    {
      "x": 0,
      "y": 3,
      "z": -7,
      "name": "Rock_Basalt_Brick_Stairs",
      "rotation": 3
    },
    {
      "x": 0,
      "y": -1,
      "z": -6,
      "name": "Rock_Basalt"
    },
    {
      "x": 0,
      "y": 0,
      "z": -6,
      "name": "Rock_Basalt"
    },
    {
      "x": 0,
      "y": -3,
      "z": -5,
      "name": "Rock_Basalt"
    },
    {
      "x": 0,
      "y": -2,
      "z": -5,
      "name": "Rock_Basalt"
    },
    {
      "x": 0,
      "y": -1,
      "z": -5,
      "name": "Rock_Basalt"
    },
    {
      "x": 0,
      "y": 0,
      "z": -5,
      "name": "Rock_Basalt_Cobble"
    },
    {
      "x": 0,
      "y": -3,
      "z": -4,
      "name": "Rock_Basalt"
    },
    {
      "x": 0,
      "y": -2,
      "z": -4,
      "name": "Rock_Basalt"
    },
    {
      "x": 0,
      "y": -1,
      "z": -4,
      "name": "Rock_Basalt"
    },
    {
      "x": 0,
      "y": 0,
      "z": -4,
      "name": "Rock_Basalt_Cobble"
    },
    {
      "x": 0,
      "y": -4,
      "z": -3,
      "name": "Rock_Basalt"
    },
    {
      "x": 0,
      "y": -3,
      "z": -3,
      "name": "Rock_Basalt"
    },
    {
      "x": 0,
      "y": -2,
      "z": -3,
      "name": "Rock_Basalt"
    },
    {
      "x": 0,
      "y": -1,
      "z": -3,
      "name": "Rock_Basalt"
    },
    {
      "x": 0,
      "y": 0,
      "z": -3,
      "name": "Rock_Basalt_Cobble"
    },
    {
      "x": 0,
      "y": -4,
      "z": -2,
      "name": "Rock_Basalt"
    },
    {
      "x": 0,
      "y": -3,
      "z": -2,
      "name": "Rock_Basalt"
    },
    {
      "x": 0,
      "y": -2,
      "z": -2,
      "name": "Rock_Basalt"
    },
    {
      "x": 0,
      "y": -1,
      "z": -2,
      "name": "Rock_Basalt"
    },
    {
      "x": 0,
      "y": 0,
      "z": -2,
      "name": "Rock_Basalt_Cobble"
    },
    {
      "x": 0,
      "y": -4,
      "z": -1,
      "name": "Rock_Basalt"
    },
    {
      "x": 0,
      "y": -3,
      "z": -1,
      "name": "Rock_Basalt"
    },
    {
      "x": 0,
      "y": -2,
      "z": -1,
      "name": "Rock_Basalt"
    },
    {
      "x": 0,
      "y": -1,
      "z": -1,
      "name": "Rock_Basalt"
    },
    {
      "x": 0,
      "y": 0,
      "z": -1,
      "name": "Rock_Basalt_Cobble"
    },
    {
      "x": 0,
      "y": -4,
      "z": 0,
      "name": "Rock_Basalt"
    },
    {
      "x": 0,
      "y": -3,
      "z": 0,
      "name": "Rock_Basalt"
    },
    {
      "x": 0,
      "y": -2,
      "z": 0,
      "name": "Rock_Basalt"
    },
    {
      "x": 0,
      "y": -1,
      "z": 0,
      "name": "Rock_Basalt"
    },
    {
      "x": 0,
      "y": 0,
      "z": 0,
      "name": "Rock_Basalt_Cobble"
    },
    {
      "x": 0,
      "y": -6,
      "z": 1,
      "name": "Rock_Basalt"
    },
    {
      "x": 0,
      "y": -5,
      "z": 1,
      "name": "Rock_Basalt"
    },
    {
      "x": 0,
      "y": -4,
      "z": 1,
      "name": "Rock_Basalt"
    },
    {
      "x": 0,
      "y": -3,
      "z": 1,
      "name": "Rock_Basalt"
    },
    {
      "x": 0,
      "y": -2,
      "z": 1,
      "name": "Rock_Basalt"
    },
    {
      "x": 0,
      "y": -1,
      "z": 1,
      "name": "Rock_Basalt"
    },
    {
      "x": 0,
      "y": 0,
      "z": 1,
      "name": "Rock_Basalt_Cobble"
    },
    {
      "x": 0,
      "y": -6,
      "z": 2,
      "name": "Rock_Basalt"
    },
    {
      "x": 0,
      "y": -5,
      "z": 2,
      "name": "Rock_Basalt"
    },
    {
      "x": 0,
      "y": -4,
      "z": 2,
      "name": "Rock_Basalt"
    },
    {
      "x": 0,
      "y": -3,
      "z": 2,
      "name": "Rock_Basalt"
    },
    {
      "x": 0,
      "y": -2,
      "z": 2,
      "name": "Rock_Basalt"
    },
    {
      "x": 0,
      "y": -1,
      "z": 2,
      "name": "Rock_Basalt"
    },
    {
      "x": 0,
      "y": 0,
      "z": 2,
      "name": "Rock_Basalt_Cobble"
    },
    {
      "x": 0,
      "y": -6,
      "z": 3,
      "name": "Rock_Basalt"
    },
    {
      "x": 0,
      "y": -5,
      "z": 3,
      "name": "Rock_Basalt"
    },
    {
      "x": 0,
      "y": -4,
      "z": 3,
      "name": "Rock_Basalt"
    },
    {
      "x": 0,
      "y": -3,
      "z": 3,
      "name": "Rock_Basalt"
    },
    {
      "x": 0,
      "y": -2,
      "z": 3,
      "name": "Rock_Basalt"
    },
    {
      "x": 0,
      "y": -1,
      "z": 3,
      "name": "Rock_Basalt"
    },
    {
      "x": 0,
      "y": 0,
      "z": 3,
      "name": "Rock_Basalt_Cobble"
    },
    {
      "x": 0,
      "y": -6,
      "z": 4,
      "name": "Rock_Basalt"
    },
    {
      "x": 0,
      "y": -5,
      "z": 4,
      "name": "Rock_Basalt"
    },
    {
      "x": 0,
      "y": -4,
      "z": 4,
      "name": "Rock_Basalt"
    },
    {
      "x": 0,
      "y": -3,
      "z": 4,
      "name": "Rock_Basalt"
    },
    {
      "x": 0,
      "y": -2,
      "z": 4,
      "name": "Rock_Basalt"
    },
    {
      "x": 0,
      "y": -1,
      "z": 4,
      "name": "Rock_Basalt"
    },
    {
      "x": 0,
      "y": 0,
      "z": 4,
      "name": "Soil_Grass"
    },
    {
      "x": 0,
      "y": 1,
      "z": 4,
      "name": "Plant_Grass_Lush"
    },
    {
      "x": 0,
      "y": 4,
      "z": 4,
      "name": "Plant_Vine_Wall",
      "rotation": 2
    },
    {
      "x": 0,
      "y": 5,
      "z": 4,
      "name": "Plant_Vine",
      "rotation": 2
    },
    {
      "x": 0,
      "y": 6,
      "z": 4,
      "name": "Plant_Vine",
      "rotation": 2
    },
    {
      "x": 0,
      "y": -6,
      "z": 5,
      "name": "Rock_Basalt"
    },
    {
      "x": 0,
      "y": -5,
      "z": 5,
      "name": "Rock_Basalt"
    },
    {
      "x": 0,
      "y": -4,
      "z": 5,
      "name": "Rock_Basalt"
    },
    {
      "x": 0,
      "y": -3,
      "z": 5,
      "name": "Rock_Basalt"
    },
    {
      "x": 0,
      "y": -2,
      "z": 5,
      "name": "Rock_Basalt"
    },
    {
      "x": 0,
      "y": -1,
      "z": 5,
      "name": "Rock_Basalt"
    },
    {
      "x": 0,
      "y": 0,
      "z": 5,
      "name": "Rock_Basalt_Brick"
    },
    {
      "x": 0,
      "y": 1,
      "z": 5,
      "name": "Rock_Basalt"
    },
    {
      "x": 0,
      "y": 2,
      "z": 5,
      "name": "Rock_Basalt"
    },
    {
      "x": 0,
      "y": 3,
      "z": 5,
      "name": "Rock_Basalt"
    },
    {
      "x": 0,
      "y": 4,
      "z": 5,
      "name": "Rock_Basalt_Cobble"
    },
    {
      "x": 0,
      "y": 5,
      "z": 5,
      "name": "Soil_Dirt"
    },
    {
      "x": 0,
      "y": 6,
      "z": 5,
      "name": "Soil_Grass"
    },
    {
      "x": 0,
      "y": 7,
      "z": 5,
      "name": "Plant_Grass_Lush"
    },
    {
      "x": 0,
      "y": -4,
      "z": 6,
      "name": "Rock_Basalt"
    },
    {
      "x": 0,
      "y": -3,
      "z": 6,
      "name": "Rock_Basalt"
    },
    {
      "x": 0,
      "y": -2,
      "z": 6,
      "name": "Rock_Basalt"
    },
    {
      "x": 0,
      "y": -1,
      "z": 6,
      "name": "Rock_Basalt"
    },
    {
      "x": 0,
      "y": 0,
      "z": 6,
      "name": "Rock_Basalt_Brick"
    },
    {
      "x": 0,
      "y": 1,
      "z": 6,
      "name": "Rock_Basalt"
    },
    {
      "x": 0,
      "y": 3,
      "z": 6,
      "name": "Rock_Basalt"
    },
    {
      "x": 0,
      "y": 4,
      "z": 6,
      "name": "Rock_Basalt"
    },
    {
      "x": 0,
      "y": 5,
      "z": 6,
      "name": "Rock_Basalt"
    },
    {
      "x": 0,
      "y": 6,
      "z": 6,
      "name": "Soil_Grass"
    },
    {
      "x": 0,
      "y": -3,
      "z": 7,
      "name": "Rock_Basalt"
    },
    {
      "x": 0,
      "y": -2,
      "z": 7,
      "name": "Rock_Basalt"
    },
    {
      "x": 0,
      "y": -1,
      "z": 7,
      "name": "Rock_Basalt"
    },
    {
      "x": 0,
      "y": 4,
      "z": 7,
      "name": "Rock_Basalt"
    },
    {
      "x": 0,
      "y": 5,
      "z": 7,
      "name": "Rock_Basalt"
    },
    {
      "x": 0,
      "y": 6,
      "z": 7,
      "name": "Soil_Grass"
    },
    {
      "x": 0,
      "y": 7,
      "z": 7,
      "name": "Plant_Moss_Rug_Green"
    },
    {
      "x": 0,
      "y": -1,
      "z": 8,
      "name": "Rock_Basalt"
    },
    {
      "x": 0,
      "y": 6,
      "z": 8,
      "name": "Rock_Basalt_Brick"
    },
    {
      "x": 0,
      "y": 7,
      "z": 8,
      "name": "Plant_Moss_Rug_Green"
    },
    {
      "x": 1,
      "y": -1,
      "z": -9,
      "name": "Rock_Basalt"
    },
    {
      "x": 1,
      "y": -1,
      "z": -8,
      "name": "Rock_Basalt"
    },
    {
      "x": 1,
      "y": 3,
      "z": -8,
      "name": "Rock_Basalt_Brick"
    },
    {
      "x": 1,
      "y": 4,
      "z": -8,
      "name": "Rock_Basalt_Brick_Stairs",
      "rotation": 3
    },
    {
      "x": 1,
      "y": -1,
      "z": -7,
      "name": "Rock_Basalt"
    },
    {
      "x": 1,
      "y": 0,
      "z": -7,
      "name": "Rock_Basalt"
    },
    {
      "x": 1,
      "y": 1,
      "z": -7,
      "name": "Rock_Basalt"
    },
    {
      "x": 1,
      "y": 2,
      "z": -7,
      "name": "Rock_Basalt"
    },
    {
      "x": 1,
      "y": 3,
      "z": -7,
      "name": "Rock_Basalt_Brick"
    },
    {
      "x": 1,
      "y": 4,
      "z": -7,
      "name": "Rock_Basalt_Brick_Stairs",
      "rotation": 3
    },
    {
      "x": 1,
      "y": -1,
      "z": -6,
      "name": "Rock_Basalt"
    },
    {
      "x": 1,
      "y": 0,
      "z": -6,
      "name": "Rock_Basalt"
    },
    {
      "x": 1,
      "y": -2,
      "z": -5,
      "name": "Rock_Basalt"
    },
    {
      "x": 1,
      "y": -1,
      "z": -5,
      "name": "Rock_Basalt"
    },
    {
      "x": 1,
      "y": 0,
      "z": -5,
      "name": "Rock_Basalt_Cobble"
    },
    {
      "x": 1,
      "y": 1,
      "z": -5,
      "name": "Rock_Sandstone_Red_Brick_Pillar_Middle",
      "rotation": 4
    },
    {
      "x": 1,
      "y": -3,
      "z": -4,
      "name": "Rock_Basalt"
    },
    {
      "x": 1,
      "y": -2,
      "z": -4,
      "name": "Rock_Basalt"
    },
    {
      "x": 1,
      "y": -1,
      "z": -4,
      "name": "Rock_Basalt"
    },
    {
      "x": 1,
      "y": 0,
      "z": -4,
      "name": "Rock_Basalt_Cobble"
    },
    {
      "x": 1,
      "y": 1,
      "z": -4,
      "name": "Rock_Sandstone_Red_Brick_Pillar_Middle",
      "rotation": 4
    },
    {
      "x": 1,
      "y": -4,
      "z": -3,
      "name": "Rock_Basalt"
    },
    {
      "x": 1,
      "y": -3,
      "z": -3,
      "name": "Rock_Basalt"
    },
    {
      "x": 1,
      "y": -2,
      "z": -3,
      "name": "Rock_Basalt"
    },
    {
      "x": 1,
      "y": -1,
      "z": -3,
      "name": "Rock_Basalt"
    },
    {
      "x": 1,
      "y": 0,
      "z": -3,
      "name": "Rock_Basalt_Cobble"
    },
    {
      "x": 1,
      "y": 1,
      "z": -3,
      "name": "Rock_Sandstone_Red_Brick_Pillar_Base"
    },
    {
      "x": 1,
      "y": 2,
      "z": -3,
      "name": "Rock_Sandstone_Red_Brick_Pillar_Middle"
    },
    {
      "x": 1,
      "y": -4,
      "z": -2,
      "name": "Rock_Basalt"
    },
    {
      "x": 1,
      "y": -3,
      "z": -2,
      "name": "Rock_Basalt"
    },
    {
      "x": 1,
      "y": -2,
      "z": -2,
      "name": "Rock_Basalt"
    },
    {
      "x": 1,
      "y": -1,
      "z": -2,
      "name": "Rock_Basalt"
    },
    {
      "x": 1,
      "y": 0,
      "z": -2,
      "name": "Rock_Basalt_Cobble"
    },
    {
      "x": 1,
      "y": -5,
      "z": -1,
      "name": "Rock_Basalt"
    },
    {
      "x": 1,
      "y": -4,
      "z": -1,
      "name": "Rock_Basalt"
    },
    {
      "x": 1,
      "y": -3,
      "z": -1,
      "name": "Rock_Basalt"
    },
    {
      "x": 1,
      "y": -2,
      "z": -1,
      "name": "Rock_Basalt"
    },
    {
      "x": 1,
      "y": -1,
      "z": -1,
      "name": "Rock_Basalt"
    },
    {
      "x": 1,
      "y": 0,
      "z": -1,
      "name": "Rock_Basalt_Cobble"
    },
    {
      "x": 1,
      "y": -4,
      "z": 0,
      "name": "Rock_Basalt"
    },
    {
      "x": 1,
      "y": -3,
      "z": 0,
      "name": "Rock_Basalt"
    },
    {
      "x": 1,
      "y": -2,
      "z": 0,
      "name": "Rock_Basalt"
    },
    {
      "x": 1,
      "y": -1,
      "z": 0,
      "name": "Rock_Basalt"
    },
    {
      "x": 1,
      "y": 0,
      "z": 0,
      "name": "Rock_Basalt_Cobble"
    },
    {
      "x": 1,
      "y": 6,
      "z": 0,
      "name": "Rock_Basalt_Brick_Half",
      "rotation": 6
    },
    {
      "x": 1,
      "y": -6,
      "z": 1,
      "name": "Rock_Basalt"
    },
    {
      "x": 1,
      "y": -5,
      "z": 1,
      "name": "Rock_Basalt"
    },
    {
      "x": 1,
      "y": -4,
      "z": 1,
      "name": "Rock_Basalt"
    },
    {
      "x": 1,
      "y": -3,
      "z": 1,
      "name": "Rock_Basalt"
    },
    {
      "x": 1,
      "y": -2,
      "z": 1,
      "name": "Rock_Basalt"
    },
    {
      "x": 1,
      "y": -1,
      "z": 1,
      "name": "Rock_Basalt"
    },
    {
      "x": 1,
      "y": 0,
      "z": 1,
      "name": "Rock_Basalt_Cobble"
    },
    {
      "x": 1,
      "y": 5,
      "z": 1,
      "name": "*Rock_Basalt_Brick_Half_State_Definitions_Block",
      "rotation": 6
    },
    {
      "x": 1,
      "y": 6,
      "z": 1,
      "name": "Rock_Basalt_Brick"
    },
    {
      "x": 1,
      "y": -6,
      "z": 2,
      "name": "Rock_Basalt"
    },
    {
      "x": 1,
      "y": -5,
      "z": 2,
      "name": "Rock_Basalt"
    },
    {
      "x": 1,
      "y": -4,
      "z": 2,
      "name": "Rock_Basalt"
    },
    {
      "x": 1,
      "y": -3,
      "z": 2,
      "name": "Rock_Basalt"
    },
    {
      "x": 1,
      "y": -2,
      "z": 2,
      "name": "Rock_Basalt"
    },
    {
      "x": 1,
      "y": -1,
      "z": 2,
      "name": "Rock_Basalt"
    },
    {
      "x": 1,
      "y": 0,
      "z": 2,
      "name": "Rock_Basalt_Cobble"
    },
    {
      "x": 1,
      "y": 1,
      "z": 2,
      "name": "Rock_Sandstone_Red_Brick_Pillar_Base"
    },
    {
      "x": 1,
      "y": 2,
      "z": 2,
      "name": "Rock_Sandstone_Red_Brick_Pillar_Middle"
    },
    {
      "x": 1,
      "y": 3,
      "z": 2,
      "name": "Rock_Sandstone_Red_Brick_Pillar_Middle"
    },
    {
      "x": 1,
      "y": 4,
      "z": 2,
      "name": "Rock_Sandstone_Red_Brick_Pillar_Middle"
    },
    {
      "x": 1,
      "y": 5,
      "z": 2,
      "name": "Rock_Sandstone_Red_Brick_Pillar_Base",
      "rotation": 8
    },
    {
      "x": 1,
      "y": 6,
      "z": 2,
      "name": "Rock_Basalt_Brick"
    },
    {
      "x": 1,
      "y": -6,
      "z": 3,
      "name": "Rock_Basalt"
    },
    {
      "x": 1,
      "y": -5,
      "z": 3,
      "name": "Rock_Basalt"
    },
    {
      "x": 1,
      "y": -4,
      "z": 3,
      "name": "Rock_Basalt"
    },
    {
      "x": 1,
      "y": -3,
      "z": 3,
      "name": "Rock_Basalt"
    },
    {
      "x": 1,
      "y": -2,
      "z": 3,
      "name": "Rock_Basalt"
    },
    {
      "x": 1,
      "y": -1,
      "z": 3,
      "name": "Rock_Basalt"
    },
    {
      "x": 1,
      "y": 0,
      "z": 3,
      "name": "Rock_Basalt_Cobble"
    },
    {
      "x": 1,
      "y": 6,
      "z": 3,
      "name": "Rock_Basalt_Brick"
    },
    {
      "x": 1,
      "y": -6,
      "z": 4,
      "name": "Rock_Basalt"
    },
    {
      "x": 1,
      "y": -5,
      "z": 4,
      "name": "Rock_Basalt"
    },
    {
      "x": 1,
      "y": -4,
      "z": 4,
      "name": "Rock_Basalt"
    },
    {
      "x": 1,
      "y": -3,
      "z": 4,
      "name": "Rock_Basalt"
    },
    {
      "x": 1,
      "y": -2,
      "z": 4,
      "name": "Rock_Basalt"
    },
    {
      "x": 1,
      "y": -1,
      "z": 4,
      "name": "Rock_Basalt"
    },
    {
      "x": 1,
      "y": 0,
      "z": 4,
      "name": "Rock_Basalt_Brick_Half",
      "rotation": 7
    },
    {
      "x": 1,
      "y": 1,
      "z": 4,
      "name": "*Rock_Basalt_Brick_Half_State_Definitions_Block"
    },
    {
      "x": 1,
      "y": 2,
      "z": 4,
      "name": "Rock_Basalt_Brick_Half",
      "rotation": 7
    },
    {
      "x": 1,
      "y": 6,
      "z": 4,
      "name": "Plant_Vine_Wall",
      "rotation": 2
    },
    {
      "x": 1,
      "y": -6,
      "z": 5,
      "name": "Rock_Basalt"
    },
    {
      "x": 1,
      "y": -5,
      "z": 5,
      "name": "Rock_Basalt"
    },
    {
      "x": 1,
      "y": -4,
      "z": 5,
      "name": "Rock_Basalt"
    },
    {
      "x": 1,
      "y": -3,
      "z": 5,
      "name": "Rock_Basalt"
    },
    {
      "x": 1,
      "y": -2,
      "z": 5,
      "name": "Rock_Basalt"
    },
    {
      "x": 1,
      "y": -1,
      "z": 5,
      "name": "Rock_Basalt"
    },
    {
      "x": 1,
      "y": 0,
      "z": 5,
      "name": "Rock_Basalt_Brick"
    },
    {
      "x": 1,
      "y": 1,
      "z": 5,
      "name": "Rock_Basalt"
    },
    {
      "x": 1,
      "y": 2,
      "z": 5,
      "name": "Rock_Basalt"
    },
    {
      "x": 1,
      "y": 3,
      "z": 5,
      "name": "Rock_Basalt"
    },
    {
      "x": 1,
      "y": 4,
      "z": 5,
      "name": "Rock_Basalt"
    },
    {
      "x": 1,
      "y": 5,
      "z": 5,
      "name": "Rock_Basalt"
    },
    {
      "x": 1,
      "y": 6,
      "z": 5,
      "name": "Soil_Grass"
    },
    {
      "x": 1,
      "y": 7,
      "z": 5,
      "name": "Plant_Moss_Rug_Green"
    },
    {
      "x": 1,
      "y": -3,
      "z": 6,
      "name": "Rock_Basalt"
    },
    {
      "x": 1,
      "y": -2,
      "z": 6,
      "name": "Rock_Basalt"
    },
    {
      "x": 1,
      "y": -1,
      "z": 6,
      "name": "Rock_Basalt"
    },
    {
      "x": 1,
      "y": 0,
      "z": 6,
      "name": "Rock_Basalt_Brick"
    },
    {
      "x": 1,
      "y": 1,
      "z": 6,
      "name": "Rock_Basalt"
    },
    {
      "x": 1,
      "y": 3,
      "z": 6,
      "name": "Rock_Basalt"
    },
    {
      "x": 1,
      "y": 4,
      "z": 6,
      "name": "Rock_Basalt"
    },
    {
      "x": 1,
      "y": 5,
      "z": 6,
      "name": "Rock_Basalt"
    },
    {
      "x": 1,
      "y": 6,
      "z": 6,
      "name": "Soil_Grass"
    },
    {
      "x": 1,
      "y": -2,
      "z": 7,
      "name": "Rock_Basalt"
    },
    {
      "x": 1,
      "y": -1,
      "z": 7,
      "name": "Rock_Basalt"
    },
    {
      "x": 1,
      "y": 0,
      "z": 7,
      "name": "Rock_Basalt_Brick"
    },
    {
      "x": 1,
      "y": 3,
      "z": 7,
      "name": "Rock_Basalt"
    },
    {
      "x": 1,
      "y": 4,
      "z": 7,
      "name": "Rock_Basalt"
    },
    {
      "x": 1,
      "y": 5,
      "z": 7,
      "name": "Rock_Basalt"
    },
    {
      "x": 1,
      "y": 6,
      "z": 7,
      "name": "Soil_Grass"
    },
    {
      "x": 1,
      "y": 7,
      "z": 7,
      "name": "Plant_Grass_Sharp"
    },
    {
      "x": 1,
      "y": 6,
      "z": 8,
      "name": "Rock_Basalt_Brick"
    },
    {
      "x": 2,
      "y": -1,
      "z": -9,
      "name": "Rock_Basalt"
    },
    {
      "x": 2,
      "y": -1,
      "z": -8,
      "name": "Rock_Basalt"
    },
    {
      "x": 2,
      "y": 3,
      "z": -8,
      "name": "Rock_Basalt"
    },
    {
      "x": 2,
      "y": 4,
      "z": -8,
      "name": "Rock_Basalt_Brick"
    },
    {
      "x": 2,
      "y": 5,
      "z": -8,
      "name": "Rock_Basalt_Brick_Half"
    },
    {
      "x": 2,
      "y": -1,
      "z": -7,
      "name": "Rock_Basalt"
    },
    {
      "x": 2,
      "y": 3,
      "z": -7,
      "name": "Rock_Basalt"
    },
    {
      "x": 2,
      "y": 4,
      "z": -7,
      "name": "Rock_Basalt_Brick_Stairs",
      "rotation": 11
    },
    {
      "x": 2,
      "y": 5,
      "z": -7,
      "name": "Rock_Basalt_Brick_Stairs",
      "rotation": 3
    },
    {
      "x": 2,
      "y": -1,
      "z": -6,
      "name": "Rock_Basalt"
    },
    {
      "x": 2,
      "y": 0,
      "z": -6,
      "name": "Rock_Basalt_Cobble"
    },
    {
      "x": 2,
      "y": 1,
      "z": -6,
      "name": "Plant_Crop_Mushroom_Common_Lime",
      "components": {
        "Components": {
          "FarmingBlock": {
            "LastTickGameTime": "0001-01-01T12:00:00Z"
          },
          "PlacedByInteraction": {
            "WhoPlacedUuid": {
              "$binary": "5RPZJ2uQSJ2g+KZxfjqR+g==",
              "$type": "04"
            }
          }
        }
      }
    },
    {
      "x": 2,
      "y": -1,
      "z": -5,
      "name": "Rock_Basalt"
    },
    {
      "x": 2,
      "y": 0,
      "z": -5,
      "name": "Rock_Basalt_Cobble"
    },
    {
      "x": 2,
      "y": 1,
      "z": -5,
      "name": "Rock_Basalt_Brick"
    },
    {
      "x": 2,
      "y": 2,
      "z": -5,
      "name": "Rock_Basalt_Brick"
    },
    {
      "x": 2,
      "y": 3,
      "z": -5,
      "name": "Rock_Basalt_Brick"
    },
    {
      "x": 2,
      "y": 4,
      "z": -5,
      "name": "Rock_Basalt_Brick_Half"
    },
    {
      "x": 2,
      "y": 5,
      "z": -5,
      "name": "*Rock_Basalt_Brick_Half_State_Definitions_Block",
      "rotation": 7
    },
    {
      "x": 2,
      "y": -3,
      "z": -4,
      "name": "Rock_Basalt"
    },
    {
      "x": 2,
      "y": -2,
      "z": -4,
      "name": "Rock_Basalt"
    },
    {
      "x": 2,
      "y": -1,
      "z": -4,
      "name": "Rock_Basalt"
    },
    {
      "x": 2,
      "y": 0,
      "z": -4,
      "name": "Rock_Basalt_Cobble"
    },
    {
      "x": 2,
      "y": 1,
      "z": -4,
      "name": "Rock_Basalt_Brick"
    },
    {
      "x": 2,
      "y": 2,
      "z": -4,
      "name": "Rock_Basalt_Brick_Half",
      "rotation": 4
    },
    {
      "x": 2,
      "y": 3,
      "z": -4,
      "name": "*Rock_Basalt_Brick_Half_State_Definitions_Block"
    },
    {
      "x": 2,
      "y": -4,
      "z": -3,
      "name": "Rock_Basalt"
    },
    {
      "x": 2,
      "y": -3,
      "z": -3,
      "name": "Rock_Basalt"
    },
    {
      "x": 2,
      "y": -2,
      "z": -3,
      "name": "Rock_Basalt"
    },
    {
      "x": 2,
      "y": -1,
      "z": -3,
      "name": "Rock_Basalt"
    },
    {
      "x": 2,
      "y": 0,
      "z": -3,
      "name": "Rock_Basalt_Cobble"
    },
    {
      "x": 2,
      "y": -5,
      "z": -2,
      "name": "Rock_Basalt"
    },
    {
      "x": 2,
      "y": -4,
      "z": -2,
      "name": "Rock_Basalt"
    },
    {
      "x": 2,
      "y": -3,
      "z": -2,
      "name": "Rock_Basalt"
    },
    {
      "x": 2,
      "y": -2,
      "z": -2,
      "name": "Rock_Basalt"
    },
    {
      "x": 2,
      "y": -1,
      "z": -2,
      "name": "Rock_Basalt"
    },
    {
      "x": 2,
      "y": 0,
      "z": -2,
      "name": "Rock_Basalt_Cobble"
    },
    {
      "x": 2,
      "y": -5,
      "z": -1,
      "name": "Rock_Basalt"
    },
    {
      "x": 2,
      "y": -4,
      "z": -1,
      "name": "Rock_Basalt"
    },
    {
      "x": 2,
      "y": -3,
      "z": -1,
      "name": "Rock_Basalt"
    },
    {
      "x": 2,
      "y": -2,
      "z": -1,
      "name": "Rock_Basalt"
    },
    {
      "x": 2,
      "y": -1,
      "z": -1,
      "name": "Rock_Basalt"
    },
    {
      "x": 2,
      "y": 0,
      "z": -1,
      "name": "Rock_Basalt_Cobble"
    },
    {
      "x": 2,
      "y": 1,
      "z": -1,
      "name": "Rock_Basalt_Brick_Half"
    },
    {
      "x": 2,
      "y": -6,
      "z": 0,
      "name": "Rock_Basalt"
    },
    {
      "x": 2,
      "y": -5,
      "z": 0,
      "name": "Rock_Basalt"
    },
    {
      "x": 2,
      "y": -4,
      "z": 0,
      "name": "Rock_Basalt"
    },
    {
      "x": 2,
      "y": -3,
      "z": 0,
      "name": "Rock_Basalt"
    },
    {
      "x": 2,
      "y": -2,
      "z": 0,
      "name": "Rock_Basalt"
    },
    {
      "x": 2,
      "y": -1,
      "z": 0,
      "name": "Rock_Basalt"
    },
    {
      "x": 2,
      "y": 0,
      "z": 0,
      "name": "Rock_Basalt_Cobble"
    },
    {
      "x": 2,
      "y": 1,
      "z": 0,
      "name": "Rock_Basalt_Brick_Half"
    },
    {
      "x": 2,
      "y": -6,
      "z": 1,
      "name": "Rock_Basalt"
    },
    {
      "x": 2,
      "y": -5,
      "z": 1,
      "name": "Rock_Basalt"
    },
    {
      "x": 2,
      "y": -4,
      "z": 1,
      "name": "Rock_Basalt"
    },
    {
      "x": 2,
      "y": -3,
      "z": 1,
      "name": "Rock_Basalt"
    },
    {
      "x": 2,
      "y": -2,
      "z": 1,
      "name": "Rock_Basalt"
    },
    {
      "x": 2,
      "y": -1,
      "z": 1,
      "name": "Rock_Basalt"
    },
    {
      "x": 2,
      "y": 0,
      "z": 1,
      "name": "Rock_Basalt_Cobble"
    },
    {
      "x": 2,
      "y": 6,
      "z": 1,
      "name": "Rock_Basalt_Brick"
    },
    {
      "x": 2,
      "y": -6,
      "z": 2,
      "name": "Rock_Basalt"
    },
    {
      "x": 2,
      "y": -5,
      "z": 2,
      "name": "Rock_Basalt"
    },
    {
      "x": 2,
      "y": -4,
      "z": 2,
      "name": "Rock_Basalt"
    },
    {
      "x": 2,
      "y": -3,
      "z": 2,
      "name": "Rock_Basalt"
    },
    {
      "x": 2,
      "y": -2,
      "z": 2,
      "name": "Rock_Basalt"
    },
    {
      "x": 2,
      "y": -1,
      "z": 2,
      "name": "Rock_Basalt"
    },
    {
      "x": 2,
      "y": 0,
      "z": 2,
      "name": "Rock_Basalt_Cobble"
    },
    {
      "x": 2,
      "y": 6,
      "z": 2,
      "name": "Rock_Basalt_Brick"
    },
    {
      "x": 2,
      "y": -6,
      "z": 3,
      "name": "Rock_Basalt"
    },
    {
      "x": 2,
      "y": -5,
      "z": 3,
      "name": "Rock_Basalt"
    },
    {
      "x": 2,
      "y": -4,
      "z": 3,
      "name": "Rock_Basalt"
    },
    {
      "x": 2,
      "y": -3,
      "z": 3,
      "name": "Rock_Basalt"
    },
    {
      "x": 2,
      "y": -2,
      "z": 3,
      "name": "Rock_Basalt"
    },
    {
      "x": 2,
      "y": -1,
      "z": 3,
      "name": "Rock_Basalt"
    },
    {
      "x": 2,
      "y": 0,
      "z": 3,
      "name": "Rock_Basalt_Cobble"
    },
    {
      "x": 2,
      "y": 1,
      "z": 3,
      "name": "*Rock_Basalt_Brick_Half_State_Definitions_Block"
    },
    {
      "x": 2,
      "y": 6,
      "z": 3,
      "name": "Rock_Basalt_Brick"
    },
    {
      "x": 2,
      "y": 7,
      "z": 3,
      "name": "Rock_Basalt_Brick"
    },
    {
      "x": 2,
      "y": -6,
      "z": 4,
      "name": "Rock_Basalt"
    },
    {
      "x": 2,
      "y": -5,
      "z": 4,
      "name": "Rock_Basalt"
    },
    {
      "x": 2,
      "y": -4,
      "z": 4,
      "name": "Rock_Basalt"
    },
    {
      "x": 2,
      "y": -3,
      "z": 4,
      "name": "Rock_Basalt"
    },
    {
      "x": 2,
      "y": -2,
      "z": 4,
      "name": "Rock_Basalt"
    },
    {
      "x": 2,
      "y": -1,
      "z": 4,
      "name": "Rock_Basalt"
    },
    {
      "x": 2,
      "y": 0,
      "z": 4,
      "name": "Rock_Basalt_Cobble"
    },
    {
      "x": 2,
      "y": 1,
      "z": 4,
      "name": "*Rock_Basalt_Brick_Half_State_Definitions_Block"
    },
    {
      "x": 2,
      "y": 2,
      "z": 4,
      "name": "*Rock_Basalt_Brick_Half_State_Definitions_Block"
    },
    {
      "x": 2,
      "y": 3,
      "z": 4,
      "name": "*Rock_Basalt_Brick_Half_State_Definitions_Block"
    },
    {
      "x": 2,
      "y": -6,
      "z": 5,
      "name": "Rock_Basalt"
    },
    {
      "x": 2,
      "y": -3,
      "z": 5,
      "name": "Rock_Basalt"
    },
    {
      "x": 2,
      "y": -2,
      "z": 5,
      "name": "Rock_Basalt"
    },
    {
      "x": 2,
      "y": -1,
      "z": 5,
      "name": "Rock_Basalt"
    },
    {
      "x": 2,
      "y": 0,
      "z": 5,
      "name": "Rock_Basalt_Brick"
    },
    {
      "x": 2,
      "y": 1,
      "z": 5,
      "name": "Rock_Basalt"
    },
    {
      "x": 2,
      "y": 2,
      "z": 5,
      "name": "Rock_Basalt"
    },
    {
      "x": 2,
      "y": 3,
      "z": 5,
      "name": "Rock_Basalt"
    },
    {
      "x": 2,
      "y": 4,
      "z": 5,
      "name": "Rock_Basalt"
    },
    {
      "x": 2,
      "y": 5,
      "z": 5,
      "name": "Rock_Basalt"
    },
    {
      "x": 2,
      "y": 6,
      "z": 5,
      "name": "Soil_Grass"
    },
    {
      "x": 2,
      "y": -2,
      "z": 6,
      "name": "Rock_Basalt"
    },
    {
      "x": 2,
      "y": -1,
      "z": 6,
      "name": "Rock_Basalt"
    },
    {
      "x": 2,
      "y": 0,
      "z": 6,
      "name": "Rock_Basalt_Brick"
    },
    {
      "x": 2,
      "y": 1,
      "z": 6,
      "name": "Rock_Basalt"
    },
    {
      "x": 2,
      "y": 2,
      "z": 6,
      "name": "Rock_Basalt"
    },
    {
      "x": 2,
      "y": 3,
      "z": 6,
      "name": "Rock_Basalt"
    },
    {
      "x": 2,
      "y": 4,
      "z": 6,
      "name": "Rock_Basalt"
    },
    {
      "x": 2,
      "y": 5,
      "z": 6,
      "name": "Rock_Basalt"
    },
    {
      "x": 2,
      "y": 6,
      "z": 6,
      "name": "Soil_Grass"
    },
    {
      "x": 2,
      "y": -1,
      "z": 7,
      "name": "Rock_Basalt"
    },
    {
      "x": 2,
      "y": 0,
      "z": 7,
      "name": "Rock_Basalt_Brick"
    },
    {
      "x": 2,
      "y": 1,
      "z": 7,
      "name": "Rock_Basalt"
    },
    {
      "x": 2,
      "y": 2,
      "z": 7,
      "name": "Rock_Basalt"
    },
    {
      "x": 2,
      "y": 3,
      "z": 7,
      "name": "Rock_Basalt"
    },
    {
      "x": 2,
      "y": 4,
      "z": 7,
      "name": "Rock_Basalt"
    },
    {
      "x": 2,
      "y": 5,
      "z": 7,
      "name": "Rock_Basalt"
    },
    {
      "x": 2,
      "y": 6,
      "z": 7,
      "name": "Soil_Grass"
    },
    {
      "x": 2,
      "y": 7,
      "z": 7,
      "name": "Plant_Grass_Lush"
    },
    {
      "x": 2,
      "y": 6,
      "z": 8,
      "name": "Rock_Basalt_Brick"
    },
    {
      "x": 3,
      "y": -1,
      "z": -9,
      "name": "Rock_Basalt"
    },
    {
      "x": 3,
      "y": 0,
      "z": -9,
      "name": "Rock_Basalt_Brick"
    },
    {
      "x": 3,
      "y": 1,
      "z": -9,
      "name": "Rock_Basalt_Brick_Half",
      "rotation": 6
    },
    {
      "x": 3,
      "y": 2,
      "z": -9,
      "name": "Rock_Basalt_Brick_Half",
      "rotation": 6
    },
    {
      "x": 3,
      "y": 3,
      "z": -9,
      "name": "Rock_Basalt_Brick_Half",
      "rotation": 6
    },
    {
      "x": 3,
      "y": -1,
      "z": -8,
      "name": "Rock_Basalt"
    },
    {
      "x": 3,
      "y": 0,
      "z": -8,
      "name": "Rock_Basalt_Cobble"
    },
    {
      "x": 3,
      "y": 1,
      "z": -8,
      "name": "Rock_Basalt_Cobble"
    },
    {
      "x": 3,
      "y": 2,
      "z": -8,
      "name": "Rock_Basalt_Cobble"
    },
    {
      "x": 3,
      "y": 3,
      "z": -8,
      "name": "Rock_Basalt"
    },
    {
      "x": 3,
      "y": 4,
      "z": -8,
      "name": "Rock_Basalt"
    },
    {
      "x": 3,
      "y": 5,
      "z": -8,
      "name": "Soil_Grass"
    },
    {
      "x": 3,
      "y": 6,
      "z": -8,
      "name": "Plant_Grass_Lush"
    },
    {
      "x": 3,
      "y": -1,
      "z": -7,
      "name": "Rock_Basalt"
    },
    {
      "x": 3,
      "y": 0,
      "z": -7,
      "name": "Rock_Basalt"
    },
    {
      "x": 3,
      "y": 1,
      "z": -7,
      "name": "Rock_Basalt_Cobble"
    },
    {
      "x": 3,
      "y": 4,
      "z": -7,
      "name": "Rock_Basalt"
    },
    {
      "x": 3,
      "y": 5,
      "z": -7,
      "name": "Rock_Basalt"
    },
    {
      "x": 3,
      "y": -1,
      "z": -6,
      "name": "Rock_Basalt"
    },
    {
      "x": 3,
      "y": 0,
      "z": -6,
      "name": "Rock_Basalt_Brick"
    },
    {
      "x": 3,
      "y": 1,
      "z": -6,
      "name": "Rock_Basalt"
    },
    {
      "x": 3,
      "y": 3,
      "z": -6,
      "name": "Rock_Basalt"
    },
    {
      "x": 3,
      "y": 4,
      "z": -6,
      "name": "Rock_Basalt"
    },
    {
      "x": 3,
      "y": 5,
      "z": -6,
      "name": "Rock_Basalt"
    },
    {
      "x": 3,
      "y": -1,
      "z": -5,
      "name": "Rock_Basalt"
    },
    {
      "x": 3,
      "y": 0,
      "z": -5,
      "name": "Rock_Basalt_Cobble"
    },
    {
      "x": 3,
      "y": 1,
      "z": -5,
      "name": "Rock_Basalt_Brick_Half",
      "rotation": 4
    },
    {
      "x": 3,
      "y": 2,
      "z": -5,
      "name": "Rock_Basalt_Brick_Half",
      "rotation": 4
    },
    {
      "x": 3,
      "y": 3,
      "z": -5,
      "name": "Rock_Basalt_Brick_Half",
      "rotation": 4
    },
    {
      "x": 3,
      "y": 4,
      "z": -5,
      "name": "Rock_Basalt_Brick_Half",
      "rotation": 4
    },
    {
      "x": 3,
      "y": 5,
      "z": -5,
      "name": "Rock_Basalt_Brick"
    },
    {
      "x": 3,
      "y": -3,
      "z": -4,
      "name": "Rock_Basalt"
    },
    {
      "x": 3,
      "y": -2,
      "z": -4,
      "name": "Rock_Basalt"
    },
    {
      "x": 3,
      "y": -1,
      "z": -4,
      "name": "Rock_Basalt"
    },
    {
      "x": 3,
      "y": 0,
      "z": -4,
      "name": "Rock_Basalt_Cobble"
    },
    {
      "x": 3,
      "y": -4,
      "z": -3,
      "name": "Rock_Basalt"
    },
    {
      "x": 3,
      "y": -3,
      "z": -3,
      "name": "Rock_Basalt"
    },
    {
      "x": 3,
      "y": -2,
      "z": -3,
      "name": "Rock_Basalt"
    },
    {
      "x": 3,
      "y": -1,
      "z": -3,
      "name": "Rock_Basalt"
    },
    {
      "x": 3,
      "y": 0,
      "z": -3,
      "name": "Rock_Basalt_Cobble"
    },
    {
      "x": 3,
      "y": -4,
      "z": -2,
      "name": "Rock_Basalt"
    },
    {
      "x": 3,
      "y": -3,
      "z": -2,
      "name": "Rock_Basalt"
    },
    {
      "x": 3,
      "y": -2,
      "z": -2,
      "name": "Rock_Basalt"
    },
    {
      "x": 3,
      "y": -1,
      "z": -2,
      "name": "Rock_Basalt"
    },
    {
      "x": 3,
      "y": 0,
      "z": -2,
      "name": "Rock_Basalt_Cobble"
    },
    {
      "x": 3,
      "y": 1,
      "z": -2,
      "name": "Rock_Basalt_Brick_Half"
    },
    {
      "x": 3,
      "y": -5,
      "z": -1,
      "name": "Rock_Basalt"
    },
    {
      "x": 3,
      "y": -4,
      "z": -1,
      "name": "Rock_Basalt"
    },
    {
      "x": 3,
      "y": -3,
      "z": -1,
      "name": "Rock_Basalt"
    },
    {
      "x": 3,
      "y": -2,
      "z": -1,
      "name": "Rock_Basalt"
    },
    {
      "x": 3,
      "y": -1,
      "z": -1,
      "name": "Rock_Basalt"
    },
    {
      "x": 3,
      "y": 0,
      "z": -1,
      "name": "Rock_Basalt_Cobble"
    },
    {
      "x": 3,
      "y": 1,
      "z": -1,
      "name": "Rock_Basalt_Brick_Half"
    },
    {
      "x": 3,
      "y": -6,
      "z": 0,
      "name": "Rock_Basalt"
    },
    {
      "x": 3,
      "y": -5,
      "z": 0,
      "name": "Rock_Basalt"
    },
    {
      "x": 3,
      "y": -4,
      "z": 0,
      "name": "Rock_Basalt"
    },
    {
      "x": 3,
      "y": -3,
      "z": 0,
      "name": "Rock_Basalt"
    },
    {
      "x": 3,
      "y": -2,
      "z": 0,
      "name": "Rock_Basalt"
    },
    {
      "x": 3,
      "y": -1,
      "z": 0,
      "name": "Rock_Basalt"
    },
    {
      "x": 3,
      "y": 0,
      "z": 0,
      "name": "Rock_Basalt_Cobble"
    },
    {
      "x": 3,
      "y": -6,
      "z": 1,
      "name": "Rock_Basalt"
    },
    {
      "x": 3,
      "y": -5,
      "z": 1,
      "name": "Rock_Basalt"
    },
    {
      "x": 3,
      "y": -4,
      "z": 1,
      "name": "Rock_Basalt"
    },
    {
      "x": 3,
      "y": -3,
      "z": 1,
      "name": "Rock_Basalt"
    },
    {
      "x": 3,
      "y": -2,
      "z": 1,
      "name": "Rock_Basalt"
    },
    {
      "x": 3,
      "y": -1,
      "z": 1,
      "name": "Rock_Basalt"
    },
    {
      "x": 3,
      "y": 0,
      "z": 1,
      "name": "Rock_Basalt_Cobble"
    },
    {
      "x": 3,
      "y": -6,
      "z": 2,
      "name": "Rock_Basalt"
    },
    {
      "x": 3,
      "y": -5,
      "z": 2,
      "name": "Rock_Basalt"
    },
    {
      "x": 3,
      "y": -4,
      "z": 2,
      "name": "Rock_Basalt"
    },
    {
      "x": 3,
      "y": -3,
      "z": 2,
      "name": "Rock_Basalt"
    },
    {
      "x": 3,
      "y": -2,
      "z": 2,
      "name": "Rock_Basalt"
    },
    {
      "x": 3,
      "y": -1,
      "z": 2,
      "name": "Rock_Basalt"
    },
    {
      "x": 3,
      "y": 0,
      "z": 2,
      "name": "Rock_Basalt_Cobble"
    },
    {
      "x": 3,
      "y": 6,
      "z": 2,
      "name": "Rock_Basalt_Brick"
    },
    {
      "x": 3,
      "y": -6,
      "z": 3,
      "name": "Rock_Basalt"
    },
    {
      "x": 3,
      "y": -5,
      "z": 3,
      "name": "Rock_Basalt"
    },
    {
      "x": 3,
      "y": -4,
      "z": 3,
      "name": "Rock_Basalt"
    },
    {
      "x": 3,
      "y": -3,
      "z": 3,
      "name": "Rock_Basalt"
    },
    {
      "x": 3,
      "y": -2,
      "z": 3,
      "name": "Rock_Basalt"
    },
    {
      "x": 3,
      "y": -1,
      "z": 3,
      "name": "Rock_Basalt"
    },
    {
      "x": 3,
      "y": 0,
      "z": 3,
      "name": "Rock_Basalt_Cobble"
    },
    {
      "x": 3,
      "y": 6,
      "z": 3,
      "name": "Rock_Basalt_Brick"
    },
    {
      "x": 3,
      "y": 7,
      "z": 3,
      "name": "Rock_Basalt_Brick"
    },
    {
      "x": 3,
      "y": -6,
      "z": 4,
      "name": "Rock_Basalt"
    },
    {
      "x": 3,
      "y": -5,
      "z": 4,
      "name": "Rock_Basalt"
    },
    {
      "x": 3,
      "y": -4,
      "z": 4,
      "name": "Rock_Basalt"
    },
    {
      "x": 3,
      "y": -3,
      "z": 4,
      "name": "Rock_Basalt"
    },
    {
      "x": 3,
      "y": -2,
      "z": 4,
      "name": "Rock_Basalt"
    },
    {
      "x": 3,
      "y": -1,
      "z": 4,
      "name": "Rock_Basalt"
    },
    {
      "x": 3,
      "y": 0,
      "z": 4,
      "name": "Rock_Basalt_Cobble"
    },
    {
      "x": 3,
      "y": 6,
      "z": 4,
      "name": "Rock_Basalt_Brick_Half",
      "rotation": 8
    },
    {
      "x": 3,
      "y": 7,
      "z": 4,
      "name": "Plant_Moss_Rug_Green"
    },
    {
      "x": 3,
      "y": -4,
      "z": 5,
      "name": "Rock_Basalt"
    },
    {
      "x": 3,
      "y": -3,
      "z": 5,
      "name": "Rock_Basalt"
    },
    {
      "x": 3,
      "y": -2,
      "z": 5,
      "name": "Rock_Basalt"
    },
    {
      "x": 3,
      "y": -1,
      "z": 5,
      "name": "Rock_Basalt_Cobble"
    },
    {
      "x": 3,
      "y": 0,
      "z": 5,
      "name": "Rock_Basalt_Cobble"
    },
    {
      "x": 3,
      "y": 1,
      "z": 5,
      "name": "Rock_Basalt_Cobble"
    },
    {
      "x": 3,
      "y": 5,
      "z": 5,
      "name": "Rock_Basalt"
    },
    {
      "x": 3,
      "y": 6,
      "z": 5,
      "name": "Soil_Grass"
    },
    {
      "x": 3,
      "y": 7,
      "z": 5,
      "name": "Plant_Moss_Rug_Green"
    },
    {
      "x": 3,
      "y": -2,
      "z": 6,
      "name": "Rock_Basalt"
    },
    {
      "x": 3,
      "y": -1,
      "z": 6,
      "name": "Rock_Basalt"
    },
    {
      "x": 3,
      "y": 0,
      "z": 6,
      "name": "Rock_Basalt_Brick"
    },
    {
      "x": 3,
      "y": 1,
      "z": 6,
      "name": "Rock_Basalt"
    },
    {
      "x": 3,
      "y": 2,
      "z": 6,
      "name": "Rock_Basalt_Cobble"
    },
    {
      "x": 3,
      "y": 3,
      "z": 6,
      "name": "Rock_Basalt_Cobble"
    },
    {
      "x": 3,
      "y": 4,
      "z": 6,
      "name": "Rock_Basalt_Cobble"
    },
    {
      "x": 3,
      "y": 5,
      "z": 6,
      "name": "Rock_Basalt"
    },
    {
      "x": 3,
      "y": 6,
      "z": 6,
      "name": "Soil_Grass"
    },
    {
      "x": 3,
      "y": 7,
      "z": 6,
      "name": "Plant_Grass_Lush_Short"
    },
    {
      "x": 3,
      "y": -1,
      "z": 7,
      "name": "Rock_Basalt"
    },
    {
      "x": 3,
      "y": 0,
      "z": 7,
      "name": "Rock_Basalt_Brick"
    },
    {
      "x": 3,
      "y": 1,
      "z": 7,
      "name": "Rock_Basalt"
    },
    {
      "x": 3,
      "y": 2,
      "z": 7,
      "name": "Rock_Basalt"
    },
    {
      "x": 3,
      "y": 3,
      "z": 7,
      "name": "Rock_Basalt"
    },
    {
      "x": 3,
      "y": 4,
      "z": 7,
      "name": "Rock_Basalt"
    },
    {
      "x": 3,
      "y": 5,
      "z": 7,
      "name": "Rock_Basalt_Cobble"
    },
    {
      "x": 3,
      "y": 6,
      "z": 7,
      "name": "Soil_Grass"
    },
    {
      "x": 4,
      "y": -1,
      "z": -8,
      "name": "Rock_Basalt_Cobble"
    },
    {
      "x": 4,
      "y": 0,
      "z": -8,
      "name": "Rock_Basalt_Cobble"
    },
    {
      "x": 4,
      "y": 1,
      "z": -8,
      "name": "Rock_Basalt_Cobble"
    },
    {
      "x": 4,
      "y": 2,
      "z": -8,
      "name": "Rock_Basalt"
    },
    {
      "x": 4,
      "y": 3,
      "z": -8,
      "name": "Rock_Basalt"
    },
    {
      "x": 4,
      "y": 4,
      "z": -8,
      "name": "Rock_Basalt"
    },
    {
      "x": 4,
      "y": 5,
      "z": -8,
      "name": "Soil_Grass"
    },
    {
      "x": 4,
      "y": -1,
      "z": -7,
      "name": "Rock_Basalt"
    },
    {
      "x": 4,
      "y": 0,
      "z": -7,
      "name": "Rock_Basalt"
    },
    {
      "x": 4,
      "y": 1,
      "z": -7,
      "name": "Rock_Basalt"
    },
    {
      "x": 4,
      "y": 2,
      "z": -7,
      "name": "Rock_Basalt"
    },
    {
      "x": 4,
      "y": 3,
      "z": -7,
      "name": "Rock_Basalt"
    },
    {
      "x": 4,
      "y": 4,
      "z": -7,
      "name": "Rock_Basalt"
    },
    {
      "x": 4,
      "y": 5,
      "z": -7,
      "name": "Soil_Grass"
    },
    {
      "x": 4,
      "y": 6,
      "z": -7,
      "name": "Plant_Grass_Lush_Short"
    },
    {
      "x": 4,
      "y": -2,
      "z": -6,
      "name": "Rock_Basalt"
    },
    {
      "x": 4,
      "y": -1,
      "z": -6,
      "name": "Rock_Basalt"
    },
    {
      "x": 4,
      "y": 0,
      "z": -6,
      "name": "Rock_Basalt_Brick"
    },
    {
      "x": 4,
      "y": 1,
      "z": -6,
      "name": "Rock_Basalt"
    },
    {
      "x": 4,
      "y": 2,
      "z": -6,
      "name": "Rock_Basalt"
    },
    {
      "x": 4,
      "y": 3,
      "z": -6,
      "name": "Rock_Basalt"
    },
    {
      "x": 4,
      "y": 4,
      "z": -6,
      "name": "Rock_Basalt"
    },
    {
      "x": 4,
      "y": 5,
      "z": -6,
      "name": "Soil_Grass"
    },
    {
      "x": 4,
      "y": -3,
      "z": -5,
      "name": "Rock_Basalt"
    },
    {
      "x": 4,
      "y": -2,
      "z": -5,
      "name": "Rock_Basalt"
    },
    {
      "x": 4,
      "y": -1,
      "z": -5,
      "name": "Rock_Basalt"
    },
    {
      "x": 4,
      "y": 0,
      "z": -5,
      "name": "Rock_Basalt_Cobble"
    },
    {
      "x": 4,
      "y": 1,
      "z": -5,
      "name": "Furniture_Ancient_Barrel"
    },
    {
      "x": 4,
      "y": 2,
      "z": -5,
      "name": "Furniture_Crude_Candle"
    },
    {
      "x": 4,
      "y": 5,
      "z": -5,
      "name": "Rock_Basalt_Brick_Stairs",
      "rotation": 10
    },
    {
      "x": 4,
      "y": 6,
      "z": -5,
      "name": "Plant_Moss_Rug_Green"
    },
    {
      "x": 4,
      "y": -4,
      "z": -4,
      "name": "Rock_Basalt"
    },
    {
      "x": 4,
      "y": -3,
      "z": -4,
      "name": "Rock_Basalt"
    },
    {
      "x": 4,
      "y": -2,
      "z": -4,
      "name": "Rock_Basalt"
    },
    {
      "x": 4,
      "y": -1,
      "z": -4,
      "name": "Rock_Basalt"
    },
    {
      "x": 4,
      "y": 0,
      "z": -4,
      "name": "Rock_Basalt_Cobble"
    },
    {
      "x": 4,
      "y": -5,
      "z": -3,
      "name": "Rock_Basalt"
    },
    {
      "x": 4,
      "y": -4,
      "z": -3,
      "name": "Rock_Basalt"
    },
    {
      "x": 4,
      "y": -3,
      "z": -3,
      "name": "Rock_Basalt"
    },
    {
      "x": 4,
      "y": -2,
      "z": -3,
      "name": "Rock_Basalt"
    },
    {
      "x": 4,
      "y": -1,
      "z": -3,
      "name": "Rock_Basalt"
    },
    {
      "x": 4,
      "y": 0,
      "z": -3,
      "name": "Rock_Basalt_Cobble"
    },
    {
      "x": 4,
      "y": -4,
      "z": -2,
      "name": "Rock_Basalt"
    },
    {
      "x": 4,
      "y": -3,
      "z": -2,
      "name": "Rock_Basalt"
    },
    {
      "x": 4,
      "y": -2,
      "z": -2,
      "name": "Rock_Basalt"
    },
    {
      "x": 4,
      "y": -1,
      "z": -2,
