{
  "version": 8,
  "blockIdVersion": 11,
  "anchorX": 0,
  "anchorY": -1,
  "anchorZ": 19,
  "blocks": [
    {
      "x": -20,
      "y": -14,
      "z": -10,
      "name": "Rock_Basalt"
    },
    {
      "x": -20,
      "y": -13,
      "z": -10,
      "name": "Rock_Basalt"
    },
    {
      "x": -20,
      "y": -14,
      "z": -9,
      "name": "Rock_Basalt"
    },
    {
      "x": -20,
      "y": -13,
      "z": -9,
      "name": "Rock_Basalt"
    },
    {
      "x": -20,
      "y": -10,
      "z": -9,
      "name": "Rock_Basalt"
    },
    {
      "x": -20,
      "y": -9,
      "z": -9,
      "name": "Rock_Basalt"
    },
    {
      "x": -20,
      "y": -8,
      "z": -9,
      "name": "Rock_Basalt"
    },
    {
      "x": -20,
      "y": -7,
      "z": -9,
      "name": "Rock_Basalt"
    },
    {
      "x": -20,
      "y": -6,
      "z": -9,
      "name": "Rock_Basalt"
    },
    {
      "x": -20,
      "y": -14,
      "z": -8,
      "name": "Rock_Basalt"
    },
    {
      "x": -20,
      "y": -13,
      "z": -8,
      "name": "Rock_Basalt"
    },
    {
      "x": -20,
      "y": -12,
      "z": -8,
      "name": "Rock_Basalt"
    },
    {
      "x": -20,
      "y": -11,
      "z": -8,
      "name": "Rock_Basalt"
    },
    {
      "x": -20,
      "y": -10,
      "z": -8,
      "name": "Rock_Basalt"
    },
    {
      "x": -20,
      "y": -9,
      "z": -8,
      "name": "Rock_Basalt"
    },
    {
      "x": -20,
      "y": -8,
      "z": -8,
      "name": "Rock_Basalt"
    },
    {
      "x": -20,
      "y": -7,
      "z": -8,
      "name": "Rock_Basalt"
    },
    {
      "x": -20,
      "y": -6,
      "z": -8,
      "name": "Rock_Basalt"
    },
    {
      "x": -20,
      "y": -5,
      "z": -8,
      "name": "Rock_Basalt"
    },
    {
      "x": -20,
      "y": -14,
      "z": -7,
      "name": "Rock_Basalt"
    },
    {
      "x": -20,
      "y": -13,
      "z": -7,
      "name": "Rock_Basalt"
    },
    {
      "x": -20,
      "y": -12,
      "z": -7,
      "name": "Rock_Basalt"
    },
    {
      "x": -20,
      "y": -11,
      "z": -7,
      "name": "Rock_Basalt"
    },
    {
      "x": -20,
      "y": -10,
      "z": -7,
      "name": "Rock_Basalt"
    },
    {
      "x": -20,
      "y": -9,
      "z": -7,
      "name": "Rock_Basalt"
    },
    {
      "x": -20,
      "y": -8,
      "z": -7,
      "name": "Rock_Basalt"
    },
    {
      "x": -20,
      "y": -7,
      "z": -7,
      "name": "Rock_Basalt"
    },
    {
      "x": -20,
      "y": -6,
      "z": -7,
      "name": "Rock_Basalt"
    },
    {
      "x": -20,
      "y": -5,
      "z": -7,
      "name": "Rock_Basalt"
    },
    {
      "x": -20,
      "y": -4,
      "z": -7,
      "name": "Rock_Basalt"
    },
    {
      "x": -20,
      "y": -14,
      "z": -6,
      "name": "Rock_Basalt"
    },
    {
      "x": -20,
      "y": -13,
      "z": -6,
      "name": "Rock_Basalt"
    },
    {
      "x": -20,
      "y": -12,
      "z": -6,
      "name": "Rock_Basalt"
    },
    {
      "x": -20,
      "y": -11,
      "z": -6,
      "name": "Rock_Basalt"
    },
    {
      "x": -20,
      "y": -10,
      "z": -6,
      "name": "Rock_Basalt"
    },
    {
      "x": -20,
      "y": -9,
      "z": -6,
      "name": "Rock_Basalt"
    },
    {
      "x": -20,
      "y": -8,
      "z": -6,
      "name": "Rock_Basalt"
    },
    {
      "x": -20,
      "y": -7,
      "z": -6,
      "name": "Rock_Basalt"
    },
    {
      "x": -20,
      "y": -6,
      "z": -6,
      "name": "Rock_Basalt"
    },
    {
      "x": -20,
      "y": -5,
      "z": -6,
      "name": "Rock_Basalt"
    },
    {
      "x": -20,
      "y": -4,
      "z": -6,
      "name": "Rock_Basalt"
    },
    {
      "x": -20,
      "y": -3,
      "z": -6,
      "name": "Rock_Basalt"
    },
    {
      "x": -20,
      "y": -14,
      "z": -5,
      "name": "Rock_Basalt"
    },
    {
      "x": -20,
      "y": -13,
      "z": -5,
      "name": "Rock_Basalt"
    },
    {
      "x": -20,
      "y": -12,
      "z": -5,
      "name": "Rock_Basalt"
    },
    {
      "x": -20,
      "y": -11,
      "z": -5,
      "name": "Rock_Basalt"
    },
    {
      "x": -20,
      "y": -10,
      "z": -5,
      "name": "Rock_Basalt"
    },
    {
      "x": -20,
      "y": -9,
      "z": -5,
      "name": "Rock_Basalt"
    },
    {
      "x": -20,
      "y": -8,
      "z": -5,
      "name": "Rock_Basalt"
    },
    {
      "x": -20,
      "y": -7,
      "z": -5,
      "name": "Rock_Basalt"
    },
    {
      "x": -20,
      "y": -6,
      "z": -5,
      "name": "Rock_Basalt"
    },
    {
      "x": -20,
      "y": -5,
      "z": -5,
      "name": "Rock_Basalt"
    },
    {
      "x": -20,
      "y": -4,
      "z": -5,
      "name": "Rock_Basalt"
    },
    {
      "x": -20,
      "y": -3,
      "z": -5,
      "name": "Rock_Basalt"
    },
    {
      "x": -20,
      "y": -14,
      "z": -4,
      "name": "Rock_Basalt"
    },
    {
      "x": -20,
      "y": -13,
      "z": -4,
      "name": "Rock_Basalt"
    },
    {
      "x": -20,
      "y": -12,
      "z": -4,
      "name": "Rock_Basalt"
    },
    {
      "x": -20,
      "y": -11,
      "z": -4,
      "name": "Rock_Basalt"
    },
    {
      "x": -20,
      "y": -10,
      "z": -4,
      "name": "Rock_Basalt"
    },
    {
      "x": -20,
      "y": -9,
      "z": -4,
      "name": "Rock_Basalt"
    },
    {
      "x": -20,
      "y": -8,
      "z": -4,
      "name": "Rock_Basalt"
    },
    {
      "x": -20,
      "y": -7,
      "z": -4,
      "name": "Rock_Basalt"
    },
    {
      "x": -20,
      "y": -6,
      "z": -4,
      "name": "Rock_Basalt"
    },
    {
      "x": -20,
      "y": -5,
      "z": -4,
      "name": "Rock_Basalt"
    },
    {
      "x": -20,
      "y": -4,
      "z": -4,
      "name": "Rock_Basalt"
    },
    {
      "x": -20,
      "y": -3,
      "z": -4,
      "name": "Rock_Basalt"
    },
    {
      "x": -20,
      "y": -14,
      "z": -3,
      "name": "Rock_Basalt"
    },
    {
      "x": -20,
      "y": -13,
      "z": -3,
      "name": "Rock_Basalt"
    },
    {
      "x": -20,
      "y": -12,
      "z": -3,
      "name": "Rock_Basalt"
    },
    {
      "x": -20,
      "y": -11,
      "z": -3,
      "name": "Rock_Basalt"
    },
    {
      "x": -20,
      "y": -10,
      "z": -3,
      "name": "Rock_Basalt"
    },
    {
      "x": -20,
      "y": -9,
      "z": -3,
      "name": "Rock_Basalt"
    },
    {
      "x": -20,
      "y": -8,
      "z": -3,
      "name": "Rock_Basalt"
    },
    {
      "x": -20,
      "y": -7,
      "z": -3,
      "name": "Rock_Basalt"
    },
    {
      "x": -20,
      "y": -6,
      "z": -3,
      "name": "Rock_Basalt"
    },
    {
      "x": -20,
      "y": -5,
      "z": -3,
      "name": "Rock_Basalt"
    },
    {
      "x": -20,
      "y": -4,
      "z": -3,
      "name": "Rock_Basalt"
    },
    {
      "x": -20,
      "y": -3,
      "z": -3,
      "name": "Rock_Basalt"
    },
    {
      "x": -20,
      "y": -14,
      "z": -2,
      "name": "Rock_Basalt"
    },
    {
      "x": -20,
      "y": -13,
      "z": -2,
      "name": "Rock_Basalt"
    },
    {
      "x": -20,
      "y": -12,
      "z": -2,
      "name": "Rock_Basalt"
    },
    {
      "x": -20,
      "y": -11,
      "z": -2,
      "name": "Rock_Basalt"
    },
    {
      "x": -20,
      "y": -10,
      "z": -2,
      "name": "Rock_Basalt"
    },
    {
      "x": -20,
      "y": -9,
      "z": -2,
      "name": "Rock_Basalt"
    },
    {
      "x": -20,
      "y": -8,
      "z": -2,
      "name": "Rock_Basalt"
    },
    {
      "x": -20,
      "y": -7,
      "z": -2,
      "name": "Rock_Basalt"
    },
    {
      "x": -20,
      "y": -6,
      "z": -2,
      "name": "Rock_Basalt"
    },
    {
      "x": -20,
      "y": -5,
      "z": -2,
      "name": "Rock_Basalt"
    },
    {
      "x": -20,
      "y": -4,
      "z": -2,
      "name": "Rock_Basalt"
    },
    {
      "x": -20,
      "y": -3,
      "z": -2,
      "name": "Rock_Basalt"
    },
    {
      "x": -20,
      "y": -14,
      "z": -1,
      "name": "Rock_Basalt"
    },
    {
      "x": -20,
      "y": -13,
      "z": -1,
      "name": "Rock_Basalt"
    },
    {
      "x": -20,
      "y": -12,
      "z": -1,
      "name": "Rock_Basalt"
    },
    {
      "x": -20,
      "y": -11,
      "z": -1,
      "name": "Rock_Basalt"
    },
    {
      "x": -20,
      "y": -10,
      "z": -1,
      "name": "Rock_Basalt"
    },
    {
      "x": -20,
      "y": -9,
      "z": -1,
      "name": "Rock_Basalt"
    },
    {
      "x": -20,
      "y": -8,
      "z": -1,
      "name": "Rock_Basalt"
    },
    {
      "x": -20,
      "y": -7,
      "z": -1,
      "name": "Rock_Basalt"
    },
    {
      "x": -20,
      "y": -6,
      "z": -1,
      "name": "Rock_Basalt"
    },
    {
      "x": -20,
      "y": -5,
      "z": -1,
      "name": "Rock_Basalt"
    },
    {
      "x": -20,
      "y": -4,
      "z": -1,
      "name": "Rock_Basalt"
    },
    {
      "x": -20,
      "y": -3,
      "z": -1,
      "name": "Plant_Moss_Block_Green"
    },
    {
      "x": -20,
      "y": -14,
      "z": 0,
      "name": "Rock_Basalt"
    },
    {
      "x": -20,
      "y": -13,
      "z": 0,
      "name": "Rock_Basalt"
    },
    {
      "x": -20,
      "y": -12,
      "z": 0,
      "name": "Rock_Basalt"
    },
    {
      "x": -20,
      "y": -11,
      "z": 0,
      "name": "Rock_Basalt"
    },
    {
      "x": -20,
      "y": -10,
      "z": 0,
      "name": "Rock_Basalt"
    },
    {
      "x": -20,
      "y": -9,
      "z": 0,
      "name": "Rock_Basalt"
    },
    {
      "x": -20,
      "y": -8,
      "z": 0,
      "name": "Rock_Basalt"
    },
    {
      "x": -20,
      "y": -7,
      "z": 0,
      "name": "Rock_Basalt"
    },
    {
      "x": -20,
      "y": -6,
      "z": 0,
      "name": "Rock_Basalt"
    },
    {
      "x": -20,
      "y": -5,
      "z": 0,
      "name": "Rock_Basalt"
    },
    {
      "x": -20,
      "y": -4,
      "z": 0,
      "name": "Rock_Basalt"
    },
    {
      "x": -20,
      "y": -3,
      "z": 0,
      "name": "Plant_Moss_Block_Green"
    },
    {
      "x": -20,
      "y": -14,
      "z": 1,
      "name": "Rock_Basalt"
    },
    {
      "x": -20,
      "y": -13,
      "z": 1,
      "name": "Rock_Basalt"
    },
    {
      "x": -20,
      "y": -12,
      "z": 1,
      "name": "Rock_Basalt"
    },
    {
      "x": -20,
      "y": -11,
      "z": 1,
      "name": "Rock_Basalt"
    },
    {
      "x": -20,
      "y": -10,
      "z": 1,
      "name": "Rock_Basalt"
    },
    {
      "x": -20,
      "y": -9,
      "z": 1,
      "name": "Rock_Basalt"
    },
    {
      "x": -20,
      "y": -8,
      "z": 1,
      "name": "Rock_Basalt"
    },
    {
      "x": -20,
      "y": -7,
      "z": 1,
      "name": "Rock_Basalt"
    },
    {
      "x": -20,
      "y": -6,
      "z": 1,
      "name": "Rock_Basalt"
    },
    {
      "x": -20,
      "y": -5,
      "z": 1,
      "name": "Rock_Basalt"
    },
    {
      "x": -20,
      "y": -4,
      "z": 1,
      "name": "Rock_Basalt"
    },
    {
      "x": -20,
      "y": -3,
      "z": 1,
      "name": "Plant_Moss_Block_Green"
    },
    {
      "x": -20,
      "y": -14,
      "z": 2,
      "name": "Rock_Basalt"
    },
    {
      "x": -20,
      "y": -13,
      "z": 2,
      "name": "Rock_Basalt"
    },
    {
      "x": -20,
      "y": -12,
      "z": 2,
      "name": "Rock_Basalt"
    },
    {
      "x": -20,
      "y": -11,
      "z": 2,
      "name": "Rock_Basalt"
    },
    {
      "x": -20,
      "y": -10,
      "z": 2,
      "name": "Rock_Basalt"
    },
    {
      "x": -20,
      "y": -9,
      "z": 2,
      "name": "Rock_Basalt"
    },
    {
      "x": -20,
      "y": -8,
      "z": 2,
      "name": "Rock_Basalt"
    },
    {
      "x": -20,
      "y": -7,
      "z": 2,
      "name": "Rock_Basalt"
    },
    {
      "x": -20,
      "y": -6,
      "z": 2,
      "name": "Rock_Basalt"
    },
    {
      "x": -20,
      "y": -5,
      "z": 2,
      "name": "Rock_Basalt"
    },
    {
      "x": -20,
      "y": -4,
      "z": 2,
      "name": "Rock_Basalt"
    },
    {
      "x": -20,
      "y": -3,
      "z": 2,
      "name": "Plant_Moss_Block_Green"
    },
    {
      "x": -20,
      "y": -14,
      "z": 3,
      "name": "Rock_Basalt"
    },
    {
      "x": -20,
      "y": -13,
      "z": 3,
      "name": "Rock_Basalt"
    },
    {
      "x": -20,
      "y": -12,
      "z": 3,
      "name": "Rock_Basalt"
    },
    {
      "x": -20,
      "y": -11,
      "z": 3,
      "name": "Rock_Basalt"
    },
    {
      "x": -20,
      "y": -10,
      "z": 3,
      "name": "Rock_Basalt"
    },
    {
      "x": -20,
      "y": -9,
      "z": 3,
      "name": "Rock_Basalt"
    },
    {
      "x": -20,
      "y": -8,
      "z": 3,
      "name": "Rock_Basalt"
    },
    {
      "x": -20,
      "y": -7,
      "z": 3,
      "name": "Rock_Basalt"
    },
    {
      "x": -20,
      "y": -6,
      "z": 3,
      "name": "Rock_Basalt"
    },
    {
      "x": -20,
      "y": -5,
      "z": 3,
      "name": "Rock_Basalt"
    },
    {
      "x": -20,
      "y": -4,
      "z": 3,
      "name": "Rock_Basalt"
    },
    {
      "x": -20,
      "y": -3,
      "z": 3,
      "name": "Plant_Moss_Block_Green"
    },
    {
      "x": -20,
      "y": -14,
      "z": 4,
      "name": "Rock_Basalt"
    },
    {
      "x": -20,
      "y": -13,
      "z": 4,
      "name": "Rock_Basalt"
    },
    {
      "x": -20,
      "y": -12,
      "z": 4,
      "name": "Rock_Basalt"
    },
    {
      "x": -20,
      "y": -11,
      "z": 4,
      "name": "Rock_Basalt"
    },
    {
      "x": -20,
      "y": -10,
      "z": 4,
      "name": "Rock_Basalt"
    },
    {
      "x": -20,
      "y": -9,
      "z": 4,
      "name": "Rock_Basalt"
    },
    {
      "x": -20,
      "y": -8,
      "z": 4,
      "name": "Rock_Basalt"
    },
    {
      "x": -20,
      "y": -7,
      "z": 4,
      "name": "Rock_Basalt"
    },
    {
      "x": -20,
      "y": -6,
      "z": 4,
      "name": "Rock_Basalt"
    },
    {
      "x": -20,
      "y": -5,
      "z": 4,
      "name": "Rock_Basalt"
    },
    {
      "x": -20,
      "y": -4,
      "z": 4,
      "name": "Rock_Basalt"
    },
    {
      "x": -20,
      "y": -3,
      "z": 4,
      "name": "Plant_Moss_Block_Green"
    },
    {
      "x": -20,
      "y": -14,
      "z": 5,
      "name": "Rock_Basalt"
    },
    {
      "x": -20,
      "y": -13,
      "z": 5,
      "name": "Rock_Basalt"
    },
    {
      "x": -20,
      "y": -12,
      "z": 5,
      "name": "Rock_Basalt"
    },
    {
      "x": -20,
      "y": -11,
      "z": 5,
      "name": "Rock_Basalt"
    },
    {
      "x": -20,
      "y": -10,
      "z": 5,
      "name": "Rock_Basalt"
    },
    {
      "x": -20,
      "y": -9,
      "z": 5,
      "name": "Rock_Basalt"
    },
    {
      "x": -20,
      "y": -8,
      "z": 5,
      "name": "Rock_Basalt"
    },
    {
      "x": -20,
      "y": -7,
      "z": 5,
      "name": "Rock_Basalt"
    },
    {
      "x": -20,
      "y": -6,
      "z": 5,
      "name": "Rock_Basalt"
    },
    {
      "x": -20,
      "y": -5,
      "z": 5,
      "name": "Rock_Basalt"
    },
    {
      "x": -20,
      "y": -4,
      "z": 5,
      "name": "Rock_Basalt"
    },
    {
      "x": -20,
      "y": -3,
      "z": 5,
      "name": "Plant_Moss_Block_Green"
    },
    {
      "x": -20,
      "y": -14,
      "z": 6,
      "name": "Rock_Basalt"
    },
    {
      "x": -20,
      "y": -13,
      "z": 6,
      "name": "Rock_Basalt"
    },
    {
      "x": -20,
      "y": -12,
      "z": 6,
      "name": "Rock_Basalt"
    },
    {
      "x": -20,
      "y": -11,
      "z": 6,
      "name": "Rock_Basalt"
    },
    {
      "x": -20,
      "y": -10,
      "z": 6,
      "name": "Rock_Basalt"
    },
    {
      "x": -20,
      "y": -9,
      "z": 6,
      "name": "Rock_Basalt"
    },
    {
      "x": -20,
      "y": -8,
      "z": 6,
      "name": "Rock_Basalt"
    },
    {
      "x": -20,
      "y": -7,
      "z": 6,
      "name": "Rock_Basalt"
    },
    {
      "x": -20,
      "y": -6,
      "z": 6,
      "name": "Rock_Basalt"
    },
    {
      "x": -20,
      "y": -5,
      "z": 6,
      "name": "Rock_Basalt"
    },
    {
      "x": -20,
      "y": -4,
      "z": 6,
      "name": "Rock_Basalt"
    },
    {
      "x": -20,
      "y": -3,
      "z": 6,
      "name": "Rock_Basalt"
    },
    {
      "x": -20,
      "y": -14,
      "z": 7,
      "name": "Rock_Basalt"
    },
    {
      "x": -20,
      "y": -13,
      "z": 7,
      "name": "Rock_Basalt"
    },
    {
      "x": -20,
      "y": -12,
      "z": 7,
      "name": "Rock_Basalt"
    },
    {
      "x": -20,
      "y": -11,
      "z": 7,
      "name": "Rock_Basalt"
    },
    {
      "x": -20,
      "y": -10,
      "z": 7,
      "name": "Rock_Basalt"
    },
    {
      "x": -20,
      "y": -9,
      "z": 7,
      "name": "Rock_Basalt"
    },
    {
      "x": -20,
      "y": -8,
      "z": 7,
      "name": "Rock_Basalt"
    },
    {
      "x": -20,
      "y": -7,
      "z": 7,
      "name": "Rock_Basalt"
    },
    {
      "x": -20,
      "y": -6,
      "z": 7,
      "name": "Rock_Basalt"
    },
    {
      "x": -20,
      "y": -5,
      "z": 7,
      "name": "Rock_Basalt"
    },
    {
      "x": -20,
      "y": -4,
      "z": 7,
      "name": "Rock_Basalt"
    },
    {
      "x": -20,
      "y": -3,
      "z": 7,
      "name": "Rock_Basalt"
    },
    {
      "x": -20,
      "y": -14,
      "z": 8,
      "name": "Rock_Basalt"
    },
    {
      "x": -20,
      "y": -13,
      "z": 8,
      "name": "Rock_Basalt"
    },
    {
      "x": -20,
      "y": -12,
      "z": 8,
      "name": "Rock_Basalt"
    },
    {
      "x": -20,
      "y": -11,
      "z": 8,
      "name": "Rock_Basalt"
    },
    {
      "x": -20,
      "y": -10,
      "z": 8,
      "name": "Rock_Basalt"
    },
    {
      "x": -20,
      "y": -9,
      "z": 8,
      "name": "Rock_Basalt"
    },
    {
      "x": -20,
      "y": -8,
      "z": 8,
      "name": "Rock_Basalt"
    },
    {
      "x": -20,
      "y": -7,
      "z": 8,
      "name": "Rock_Basalt"
    },
    {
      "x": -20,
      "y": -6,
      "z": 8,
      "name": "Rock_Basalt"
    },
    {
      "x": -20,
      "y": -5,
      "z": 8,
      "name": "Rock_Basalt"
    },
    {
      "x": -20,
      "y": -4,
      "z": 8,
      "name": "Rock_Basalt"
    },
    {
      "x": -20,
      "y": -3,
      "z": 8,
      "name": "Rock_Basalt"
    },
    {
      "x": -20,
      "y": -14,
      "z": 9,
      "name": "Rock_Basalt"
    },
    {
      "x": -20,
      "y": -13,
      "z": 9,
      "name": "Rock_Basalt"
    },
    {
      "x": -20,
      "y": -12,
      "z": 9,
      "name": "Rock_Basalt"
    },
    {
      "x": -20,
      "y": -11,
      "z": 9,
      "name": "Rock_Basalt"
    },
    {
      "x": -20,
      "y": -10,
      "z": 9,
      "name": "Rock_Basalt"
    },
    {
      "x": -20,
      "y": -9,
      "z": 9,
      "name": "Rock_Basalt"
    },
    {
      "x": -20,
      "y": -8,
      "z": 9,
      "name": "Rock_Basalt"
    },
    {
      "x": -20,
      "y": -7,
      "z": 9,
      "name": "Rock_Basalt"
    },
    {
      "x": -20,
      "y": -6,
      "z": 9,
      "name": "Rock_Basalt"
    },
    {
      "x": -20,
      "y": -5,
      "z": 9,
      "name": "Rock_Basalt"
    },
    {
      "x": -20,
      "y": -4,
      "z": 9,
      "name": "Rock_Basalt"
    },
    {
      "x": -20,
      "y": -3,
      "z": 9,
      "name": "Rock_Basalt"
    },
    {
      "x": -20,
      "y": -14,
      "z": 10,
      "name": "Rock_Basalt"
    },
    {
      "x": -20,
      "y": -13,
      "z": 10,
      "name": "Rock_Basalt"
    },
    {
      "x": -20,
      "y": -12,
      "z": 10,
      "name": "Rock_Basalt"
    },
    {
      "x": -20,
      "y": -11,
      "z": 10,
      "name": "Rock_Basalt"
    },
    {
      "x": -20,
      "y": -10,
      "z": 10,
      "name": "Rock_Basalt"
    },
    {
      "x": -20,
      "y": -9,
      "z": 10,
      "name": "Rock_Basalt"
    },
    {
      "x": -20,
      "y": -8,
      "z": 10,
      "name": "Rock_Basalt"
    },
    {
      "x": -20,
      "y": -7,
      "z": 10,
      "name": "Rock_Basalt"
    },
    {
      "x": -20,
      "y": -6,
      "z": 10,
      "name": "Rock_Basalt"
    },
    {
      "x": -20,
      "y": -5,
      "z": 10,
      "name": "Rock_Basalt"
    },
    {
      "x": -20,
      "y": -4,
      "z": 10,
      "name": "Rock_Basalt"
    },
    {
      "x": -20,
      "y": -3,
      "z": 10,
      "name": "Rock_Basalt"
    },
    {
      "x": -20,
      "y": -14,
      "z": 11,
      "name": "Rock_Basalt"
    },
    {
      "x": -20,
      "y": -13,
      "z": 11,
      "name": "Rock_Basalt"
    },
    {
      "x": -20,
      "y": -12,
      "z": 11,
      "name": "Rock_Basalt"
    },
    {
      "x": -20,
      "y": -11,
      "z": 11,
      "name": "Rock_Basalt"
    },
    {
      "x": -20,
      "y": -10,
      "z": 11,
      "name": "Rock_Basalt"
    },
    {
      "x": -20,
      "y": -9,
      "z": 11,
      "name": "Rock_Basalt"
    },
    {
      "x": -20,
      "y": -8,
      "z": 11,
      "name": "Rock_Basalt"
    },
    {
      "x": -20,
      "y": -7,
      "z": 11,
      "name": "Rock_Basalt"
    },
    {
      "x": -20,
      "y": -6,
      "z": 11,
      "name": "Rock_Basalt"
    },
    {
      "x": -20,
      "y": -5,
      "z": 11,
      "name": "Rock_Basalt"
    },
    {
      "x": -20,
      "y": -4,
      "z": 11,
      "name": "Rock_Basalt"
    },
    {
      "x": -20,
      "y": -3,
      "z": 11,
      "name": "Plant_Moss_Block_Green"
    },
    {
      "x": -20,
      "y": -14,
      "z": 12,
      "name": "Rock_Basalt"
    },
    {
      "x": -20,
      "y": -13,
      "z": 12,
      "name": "Rock_Basalt"
    },
    {
      "x": -20,
      "y": -12,
      "z": 12,
      "name": "Rock_Basalt"
    },
    {
      "x": -20,
      "y": -11,
      "z": 12,
      "name": "Rock_Basalt"
    },
    {
      "x": -20,
      "y": -10,
      "z": 12,
      "name": "Rock_Basalt"
    },
    {
      "x": -20,
      "y": -9,
      "z": 12,
      "name": "Rock_Basalt"
    },
    {
      "x": -20,
      "y": -8,
      "z": 12,
      "name": "Rock_Basalt"
    },
    {
      "x": -20,
      "y": -7,
      "z": 12,
      "name": "Rock_Basalt"
    },
    {
      "x": -20,
      "y": -6,
      "z": 12,
      "name": "Rock_Basalt"
    },
    {
      "x": -20,
      "y": -5,
      "z": 12,
      "name": "Rock_Basalt"
    },
    {
      "x": -20,
      "y": -4,
      "z": 12,
      "name": "Rock_Basalt"
    },
    {
      "x": -20,
      "y": -3,
      "z": 12,
      "name": "Plant_Moss_Block_Green"
    },
    {
      "x": -20,
      "y": -14,
      "z": 13,
      "name": "Rock_Basalt"
    },
    {
      "x": -20,
      "y": -13,
      "z": 13,
      "name": "Rock_Basalt"
    },
    {
      "x": -20,
      "y": -12,
      "z": 13,
      "name": "Rock_Basalt"
    },
    {
      "x": -20,
      "y": -11,
      "z": 13,
      "name": "Rock_Basalt"
    },
    {
      "x": -20,
      "y": -10,
      "z": 13,
      "name": "Rock_Basalt"
    },
    {
      "x": -20,
      "y": -9,
      "z": 13,
      "name": "Rock_Basalt"
    },
    {
      "x": -20,
      "y": -8,
      "z": 13,
      "name": "Rock_Basalt"
    },
    {
      "x": -20,
      "y": -7,
      "z": 13,
      "name": "Rock_Basalt"
    },
    {
      "x": -20,
      "y": -6,
      "z": 13,
      "name": "Rock_Basalt"
    },
    {
      "x": -20,
      "y": -5,
      "z": 13,
      "name": "Rock_Basalt"
    },
    {
      "x": -20,
      "y": -4,
      "z": 13,
      "name": "Rock_Basalt"
    },
    {
      "x": -20,
      "y": -3,
      "z": 13,
      "name": "Plant_Moss_Block_Green"
    },
    {
      "x": -20,
      "y": -14,
      "z": 14,
      "name": "Rock_Basalt"
    },
    {
      "x": -20,
      "y": -13,
      "z": 14,
      "name": "Rock_Basalt"
    },
    {
      "x": -20,
      "y": -12,
      "z": 14,
      "name": "Rock_Basalt"
    },
    {
      "x": -20,
      "y": -11,
      "z": 14,
      "name": "Rock_Basalt"
    },
    {
      "x": -20,
      "y": -10,
      "z": 14,
      "name": "Rock_Basalt"
    },
    {
      "x": -20,
      "y": -9,
      "z": 14,
      "name": "Rock_Basalt"
    },
    {
      "x": -20,
      "y": -8,
      "z": 14,
      "name": "Rock_Basalt"
    },
    {
      "x": -20,
      "y": -7,
      "z": 14,
      "name": "Rock_Basalt"
    },
    {
      "x": -20,
      "y": -6,
      "z": 14,
      "name": "Rock_Basalt"
    },
    {
      "x": -20,
      "y": -5,
      "z": 14,
      "name": "Rock_Basalt"
    },
    {
      "x": -20,
      "y": -4,
      "z": 14,
      "name": "Rock_Basalt"
    },
    {
      "x": -20,
      "y": -3,
      "z": 14,
      "name": "Plant_Moss_Block_Green"
    },
    {
      "x": -20,
      "y": -14,
      "z": 15,
      "name": "Rock_Basalt"
    },
    {
      "x": -20,
      "y": -13,
      "z": 15,
      "name": "Rock_Basalt"
    },
    {
      "x": -20,
      "y": -12,
      "z": 15,
      "name": "Rock_Basalt"
    },
    {
      "x": -20,
      "y": -11,
      "z": 15,
      "name": "Rock_Basalt"
    },
    {
      "x": -20,
      "y": -10,
      "z": 15,
      "name": "Rock_Basalt"
    },
    {
      "x": -20,
      "y": -9,
      "z": 15,
      "name": "Rock_Basalt"
    },
    {
      "x": -20,
      "y": -8,
      "z": 15,
      "name": "Rock_Basalt"
    },
    {
      "x": -20,
      "y": -7,
      "z": 15,
      "name": "Rock_Basalt"
    },
    {
      "x": -20,
      "y": -6,
      "z": 15,
      "name": "Rock_Basalt_Brick"
    },
    {
      "x": -20,
      "y": -5,
      "z": 15,
      "name": "Rock_Basalt_Brick"
    },
    {
      "x": -20,
      "y": -4,
      "z": 15,
      "name": "Rock_Basalt"
    },
    {
      "x": -20,
      "y": -3,
      "z": 15,
      "name": "Plant_Moss_Block_Green"
    },
    {
      "x": -20,
      "y": -14,
      "z": 16,
      "name": "Rock_Basalt"
    },
    {
      "x": -20,
      "y": -13,
      "z": 16,
      "name": "Rock_Basalt"
    },
    {
      "x": -20,
      "y": -12,
      "z": 16,
      "name": "Rock_Basalt"
    },
    {
      "x": -20,
      "y": -11,
      "z": 16,
      "name": "Rock_Basalt"
    },
    {
      "x": -20,
      "y": -10,
      "z": 16,
      "name": "Rock_Basalt"
    },
    {
      "x": -20,
      "y": -9,
      "z": 16,
      "name": "Rock_Basalt"
    },
    {
      "x": -20,
      "y": -8,
      "z": 16,
      "name": "Rock_Basalt"
    },
    {
      "x": -20,
      "y": -7,
      "z": 16,
      "name": "Rock_Basalt"
    },
    {
      "x": -20,
      "y": -6,
      "z": 16,
      "name": "Rock_Basalt_Brick"
    },
    {
      "x": -20,
      "y": -5,
      "z": 16,
      "name": "Rock_Basalt_Brick"
    },
    {
      "x": -20,
      "y": -4,
      "z": 16,
      "name": "Rock_Basalt"
    },
    {
      "x": -20,
      "y": -3,
      "z": 16,
      "name": "Plant_Moss_Block_Green"
    },
    {
      "x": -20,
      "y": -14,
      "z": 17,
      "name": "Rock_Basalt"
    },
    {
      "x": -20,
      "y": -13,
      "z": 17,
      "name": "Rock_Basalt"
    },
    {
      "x": -20,
      "y": -12,
      "z": 17,
      "name": "Rock_Basalt"
    },
    {
      "x": -20,
      "y": -11,
      "z": 17,
      "name": "Rock_Basalt"
    },
    {
      "x": -20,
      "y": -10,
      "z": 17,
      "name": "Rock_Basalt"
    },
    {
      "x": -20,
      "y": -9,
      "z": 17,
      "name": "Rock_Basalt"
    },
    {
      "x": -20,
      "y": -8,
      "z": 17,
      "name": "Rock_Basalt"
    },
    {
      "x": -20,
      "y": -7,
      "z": 17,
      "name": "Rock_Basalt"
    },
    {
      "x": -20,
      "y": -6,
      "z": 17,
      "name": "Rock_Basalt"
    },
    {
      "x": -20,
      "y": -5,
      "z": 17,
      "name": "Rock_Basalt_Brick"
    },
    {
      "x": -20,
      "y": -4,
      "z": 17,
      "name": "Rock_Basalt"
    },
    {
      "x": -20,
      "y": -3,
      "z": 17,
      "name": "Plant_Moss_Block_Green"
    },
    {
      "x": -20,
      "y": -14,
      "z": 18,
      "name": "Rock_Basalt"
    },
    {
      "x": -20,
      "y": -13,
      "z": 18,
      "name": "Rock_Basalt"
    },
    {
      "x": -20,
      "y": -12,
      "z": 18,
      "name": "Rock_Basalt"
    },
    {
      "x": -20,
      "y": -11,
      "z": 18,
      "name": "Rock_Basalt"
    },
    {
      "x": -20,
      "y": -10,
      "z": 18,
      "name": "Rock_Basalt"
    },
    {
      "x": -20,
      "y": -9,
      "z": 18,
      "name": "Rock_Basalt"
    },
    {
      "x": -20,
      "y": -8,
      "z": 18,
      "name": "Rock_Basalt"
    },
    {
      "x": -20,
      "y": -7,
      "z": 18,
      "name": "Rock_Basalt"
    },
    {
      "x": -20,
      "y": -6,
      "z": 18,
      "name": "Rock_Basalt_Brick"
    },
    {
      "x": -20,
      "y": -5,
      "z": 18,
      "name": "Rock_Basalt_Brick"
    },
    {
      "x": -20,
      "y": -4,
      "z": 18,
      "name": "Rock_Basalt_Brick"
    },
    {
      "x": -20,
      "y": -3,
      "z": 18,
      "name": "Plant_Moss_Block_Green"
    },
    {
      "x": -20,
      "y": -14,
      "z": 19,
      "name": "Rock_Basalt"
    },
    {
      "x": -20,
      "y": -13,
      "z": 19,
      "name": "Rock_Basalt"
    },
    {
      "x": -20,
      "y": -12,
      "z": 19,
      "name": "Rock_Basalt"
    },
    {
      "x": -20,
      "y": -11,
      "z": 19,
      "name": "Rock_Basalt"
    },
    {
      "x": -20,
      "y": -10,
      "z": 19,
      "name": "Rock_Basalt"
    },
    {
      "x": -20,
      "y": -9,
      "z": 19,
      "name": "Rock_Basalt"
    },
    {
      "x": -20,
      "y": -8,
      "z": 19,
      "name": "Rock_Basalt"
    },
    {
      "x": -20,
      "y": -7,
      "z": 19,
      "name": "Rock_Basalt"
    },
    {
      "x": -20,
      "y": -6,
      "z": 19,
      "name": "Rock_Basalt"
    },
    {
      "x": -20,
      "y": -5,
      "z": 19,
      "name": "Rock_Basalt_Brick"
    },
    {
      "x": -20,
      "y": -4,
      "z": 19,
      "name": "Rock_Basalt_Brick"
    },
    {
      "x": -20,
      "y": -3,
      "z": 19,
      "name": "Plant_Moss_Block_Green"
    },
    {
      "x": -20,
      "y": -14,
      "z": 20,
      "name": "Rock_Basalt"
    },
    {
      "x": -20,
      "y": -13,
      "z": 20,
      "name": "Rock_Basalt"
    },
    {
      "x": -20,
      "y": -12,
      "z": 20,
      "name": "Rock_Basalt"
    },
    {
      "x": -20,
      "y": -11,
      "z": 20,
      "name": "Rock_Basalt"
    },
    {
      "x": -20,
      "y": -10,
      "z": 20,
      "name": "Rock_Basalt"
    },
    {
      "x": -20,
      "y": -9,
      "z": 20,
      "name": "Rock_Basalt"
    },
    {
      "x": -20,
      "y": -8,
      "z": 20,
      "name": "Rock_Basalt"
    },
    {
      "x": -20,
      "y": -7,
      "z": 20,
      "name": "Rock_Basalt"
    },
    {
      "x": -20,
      "y": -6,
      "z": 20,
      "name": "Rock_Basalt"
    },
    {
      "x": -20,
      "y": -5,
      "z": 20,
      "name": "Rock_Basalt_Brick"
    },
    {
      "x": -20,
      "y": -4,
      "z": 20,
      "name": "Rock_Basalt_Brick"
    },
    {
      "x": -20,
      "y": -3,
      "z": 20,
      "name": "Plant_Moss_Block_Green"
    },
    {
      "x": -20,
      "y": -14,
      "z": 21,
      "name": "Rock_Basalt"
    },
    {
      "x": -20,
      "y": -13,
      "z": 21,
      "name": "Rock_Basalt"
    },
    {
      "x": -20,
      "y": -12,
      "z": 21,
      "name": "Rock_Basalt"
    },
    {
      "x": -20,
      "y": -11,
      "z": 21,
      "name": "Rock_Basalt"
    },
    {
      "x": -20,
      "y": -10,
      "z": 21,
      "name": "Rock_Basalt"
    },
    {
      "x": -20,
      "y": -9,
      "z": 21,
      "name": "Rock_Basalt"
    },
    {
      "x": -20,
      "y": -8,
      "z": 21,
      "name": "Rock_Basalt"
    },
    {
      "x": -20,
      "y": -7,
      "z": 21,
      "name": "Rock_Basalt"
    },
    {
      "x": -20,
      "y": -6,
      "z": 21,
      "name": "Rock_Basalt"
    },
    {
      "x": -20,
      "y": -5,
      "z": 21,
      "name": "Rock_Basalt_Brick"
    },
    {
      "x": -20,
      "y": -4,
      "z": 21,
      "name": "Rock_Basalt_Brick"
    },
    {
      "x": -20,
      "y": -3,
      "z": 21,
      "name": "Plant_Moss_Block_Green"
    },
    {
      "x": -20,
      "y": -14,
      "z": 22,
      "name": "Rock_Basalt"
    },
    {
      "x": -20,
      "y": -13,
      "z": 22,
      "name": "Rock_Basalt"
    },
    {
      "x": -20,
      "y": -12,
      "z": 22,
      "name": "Rock_Basalt"
    },
    {
      "x": -20,
      "y": -11,
      "z": 22,
      "name": "Rock_Basalt"
    },
    {
      "x": -20,
      "y": -10,
      "z": 22,
      "name": "Rock_Basalt"
    },
    {
      "x": -20,
      "y": -9,
      "z": 22,
      "name": "Rock_Basalt"
    },
    {
      "x": -20,
      "y": -8,
      "z": 22,
      "name": "Rock_Basalt"
    },
    {
      "x": -20,
      "y": -7,
      "z": 22,
      "name": "Rock_Basalt"
    },
    {
      "x": -20,
      "y": -6,
      "z": 22,
      "name": "Rock_Basalt"
    },
    {
      "x": -20,
      "y": -5,
      "z": 22,
      "name": "Rock_Basalt_Brick"
    },
    {
      "x": -20,
      "y": -4,
      "z": 22,
      "name": "Rock_Basalt_Brick"
    },
    {
      "x": -20,
      "y": -3,
      "z": 22,
      "name": "Plant_Moss_Block_Green"
    },
    {
      "x": -20,
      "y": -14,
      "z": 23,
      "name": "Rock_Basalt"
    },
    {
      "x": -20,
      "y": -13,
      "z": 23,
      "name": "Rock_Basalt"
    },
    {
      "x": -20,
      "y": -12,
      "z": 23,
      "name": "Rock_Basalt"
    },
    {
      "x": -20,
      "y": -11,
      "z": 23,
      "name": "Rock_Basalt"
    },
    {
      "x": -20,
      "y": -10,
      "z": 23,
      "name": "Rock_Basalt"
    },
    {
      "x": -20,
      "y": -9,
      "z": 23,
      "name": "Rock_Basalt"
    },
    {
      "x": -20,
      "y": -8,
      "z": 23,
      "name": "Rock_Basalt"
    },
    {
      "x": -20,
      "y": -7,
      "z": 23,
      "name": "Rock_Basalt"
    },
    {
      "x": -20,
      "y": -6,
      "z": 23,
      "name": "Rock_Basalt"
    },
    {
      "x": -20,
      "y": -5,
      "z": 23,
      "name": "Rock_Basalt"
    },
    {
      "x": -20,
      "y": -4,
      "z": 23,
      "name": "Rock_Basalt"
    },
    {
      "x": -20,
      "y": -3,
      "z": 23,
      "name": "Plant_Moss_Block_Green"
    },
    {
      "x": -20,
      "y": -14,
      "z": 24,
      "name": "Rock_Basalt"
    },
    {
      "x": -20,
      "y": -13,
      "z": 24,
      "name": "Rock_Basalt"
    },
    {
      "x": -20,
      "y": -12,
      "z": 24,
      "name": "Rock_Basalt"
    },
    {
      "x": -20,
      "y": -11,
      "z": 24,
      "name": "Rock_Basalt"
    },
    {
      "x": -20,
      "y": -10,
      "z": 24,
      "name": "Rock_Basalt"
    },
    {
      "x": -20,
      "y": -9,
      "z": 24,
      "name": "Rock_Basalt"
    },
    {
      "x": -20,
      "y": -8,
      "z": 24,
      "name": "Rock_Basalt"
    },
    {
      "x": -20,
      "y": -7,
      "z": 24,
      "name": "Rock_Basalt"
    },
    {
      "x": -20,
      "y": -6,
      "z": 24,
      "name": "Rock_Basalt"
    },
    {
      "x": -20,
      "y": -5,
      "z": 24,
      "name": "Rock_Basalt"
    },
    {
      "x": -20,
      "y": -4,
      "z": 24,
      "name": "Rock_Basalt"
    },
    {
      "x": -20,
      "y": -3,
      "z": 24,
      "name": "Plant_Moss_Block_Green"
    },
    {
      "x": -20,
      "y": -14,
      "z": 25,
      "name": "Rock_Basalt"
    },
    {
      "x": -20,
      "y": -13,
      "z": 25,
      "name": "Rock_Basalt"
    },
    {
      "x": -20,
      "y": -12,
      "z": 25,
      "name": "Rock_Basalt"
    },
    {
      "x": -20,
      "y": -11,
      "z": 25,
      "name": "Rock_Basalt"
    },
    {
      "x": -20,
      "y": -10,
      "z": 25,
      "name": "Rock_Basalt"
    },
    {
      "x": -20,
      "y": -9,
      "z": 25,
      "name": "Rock_Basalt"
    },
    {
      "x": -20,
      "y": -14,
      "z": 26,
      "name": "Rock_Basalt"
    },
    {
      "x": -20,
      "y": -13,
      "z": 26,
      "name": "Rock_Basalt"
    },
    {
      "x": -20,
      "y": -12,
      "z": 26,
      "name": "Rock_Basalt"
    },
    {
      "x": -20,
      "y": -11,
      "z": 26,
      "name": "Rock_Basalt"
    },
    {
      "x": -20,
      "y": -14,
      "z": 27,
      "name": "Rock_Basalt"
    },
    {
      "x": -20,
      "y": -13,
      "z": 27,
      "name": "Rock_Basalt"
    },
    {
      "x": -20,
      "y": -12,
      "z": 27,
      "name": "Rock_Basalt"
    },
    {
      "x": -20,
      "y": -14,
      "z": 28,
      "name": "Rock_Basalt"
    },
    {
      "x": -20,
      "y": -13,
      "z": 28,
      "name": "Rock_Basalt"
    },
    {
      "x": -19,
      "y": -14,
      "z": -11,
      "name": "Rock_Basalt"
    },
    {
      "x": -19,
      "y": -14,
      "z": -10,
      "name": "Rock_Basalt"
    },
    {
      "x": -19,
      "y": -13,
      "z": -10,
      "name": "Rock_Basalt"
    },
    {
      "x": -19,
      "y": -12,
      "z": -10,
      "name": "Rock_Basalt"
    },
    {
      "x": -19,
      "y": -14,
      "z": -9,
      "name": "Rock_Basalt"
    },
    {
      "x": -19,
      "y": -13,
      "z": -9,
      "name": "Rock_Basalt"
    },
    {
      "x": -19,
      "y": -12,
      "z": -9,
      "name": "Rock_Basalt"
    },
    {
      "x": -19,
      "y": -11,
      "z": -9,
      "name": "Rock_Basalt"
    },
    {
      "x": -19,
      "y": -10,
      "z": -9,
      "name": "Rock_Basalt"
    },
    {
      "x": -19,
      "y": -9,
      "z": -9,
      "name": "Rock_Basalt"
    },
    {
      "x": -19,
      "y": -8,
      "z": -9,
      "name": "Rock_Basalt"
    },
    {
      "x": -19,
      "y": -7,
      "z": -9,
      "name": "Rock_Basalt"
    },
    {
      "x": -19,
      "y": -6,
      "z": -9,
      "name": "Rock_Basalt"
    },
    {
      "x": -19,
      "y": -14,
      "z": -8,
      "name": "Rock_Basalt"
    },
    {
      "x": -19,
      "y": -13,
      "z": -8,
      "name": "Rock_Basalt"
    },
    {
      "x": -19,
      "y": -12,
      "z": -8,
      "name": "Rock_Basalt"
    },
    {
      "x": -19,
      "y": -11,
      "z": -8,
      "name": "Rock_Basalt"
    },
    {
      "x": -19,
      "y": -10,
      "z": -8,
      "name": "Rock_Basalt"
    },
    {
      "x": -19,
      "y": -9,
      "z": -8,
      "name": "Rock_Basalt"
    },
    {
      "x": -19,
      "y": -8,
      "z": -8,
      "name": "Rock_Basalt"
    },
    {
      "x": -19,
      "y": -7,
      "z": -8,
      "name": "Rock_Basalt"
    },
    {
      "x": -19,
      "y": -6,
      "z": -8,
      "name": "Rock_Basalt"
    },
    {
      "x": -19,
      "y": -5,
      "z": -8,
      "name": "Rock_Basalt"
    },
    {
      "x": -19,
      "y": -14,
      "z": -7,
      "name": "Rock_Basalt"
    },
    {
      "x": -19,
      "y": -13,
      "z": -7,
      "name": "Rock_Basalt"
    },
    {
      "x": -19,
      "y": -12,
      "z": -7,
      "name": "Rock_Basalt"
    },
    {
      "x": -19,
      "y": -11,
      "z": -7,
      "name": "Rock_Basalt"
    },
    {
      "x": -19,
      "y": -10,
      "z": -7,
      "name": "Rock_Basalt"
    },
    {
      "x": -19,
      "y": -9,
      "z": -7,
      "name": "Rock_Basalt"
    },
    {
      "x": -19,
      "y": -8,
      "z": -7,
      "name": "Rock_Basalt"
    },
    {
      "x": -19,
      "y": -7,
      "z": -7,
      "name": "Rock_Basalt"
    },
    {
      "x": -19,
      "y": -6,
      "z": -7,
      "name": "Rock_Basalt"
    },
    {
      "x": -19,
      "y": -5,
      "z": -7,
      "name": "Rock_Basalt"
    },
    {
      "x": -19,
      "y": -4,
      "z": -7,
      "name": "Rock_Basalt"
    },
    {
      "x": -19,
      "y": -14,
      "z": -6,
      "name": "Rock_Basalt"
    },
    {
      "x": -19,
      "y": -13,
      "z": -6,
      "name": "Rock_Basalt"
    },
    {
      "x": -19,
      "y": -12,
      "z": -6,
      "name": "Rock_Basalt"
    },
    {
      "x": -19,
      "y": -11,
      "z": -6,
      "name": "Rock_Basalt"
    },
    {
      "x": -19,
      "y": -10,
      "z": -6,
      "name": "Rock_Basalt"
    },
    {
      "x": -19,
      "y": -9,
      "z": -6,
      "name": "Rock_Basalt"
    },
    {
      "x": -19,
      "y": -8,
      "z": -6,
      "name": "Rock_Basalt"
    },
    {
      "x": -19,
      "y": -7,
      "z": -6,
      "name": "Rock_Basalt"
    },
    {
      "x": -19,
      "y": -6,
      "z": -6,
      "name": "Rock_Basalt"
    },
    {
      "x": -19,
      "y": -5,
      "z": -6,
      "name": "Rock_Basalt"
    },
    {
      "x": -19,
      "y": -4,
      "z": -6,
      "name": "Rock_Basalt"
    },
    {
      "x": -19,
      "y": -3,
      "z": -6,
      "name": "Rock_Basalt"
    },
    {
      "x": -19,
      "y": -14,
      "z": -5,
      "name": "Rock_Basalt"
    },
    {
      "x": -19,
      "y": -13,
      "z": -5,
      "name": "Rock_Basalt"
    },
    {
      "x": -19,
      "y": -12,
      "z": -5,
      "name": "Rock_Basalt"
    },
    {
      "x": -19,
      "y": -11,
      "z": -5,
      "name": "Rock_Basalt"
    },
    {
      "x": -19,
      "y": -10,
      "z": -5,
      "name": "Rock_Basalt"
    },
    {
      "x": -19,
      "y": -9,
      "z": -5,
      "name": "Rock_Basalt"
    },
    {
      "x": -19,
      "y": -8,
      "z": -5,
      "name": "Rock_Basalt"
    },
    {
      "x": -19,
      "y": -7,
      "z": -5,
      "name": "Rock_Basalt"
    },
    {
      "x": -19,
      "y": -6,
      "z": -5,
      "name": "Rock_Basalt"
    },
    {
      "x": -19,
      "y": -5,
      "z": -5,
      "name": "Rock_Basalt"
    },
    {
      "x": -19,
      "y": -4,
      "z": -5,
      "name": "Rock_Basalt"
    },
    {
      "x": -19,
      "y": -3,
      "z": -5,
      "name": "Rock_Basalt"
    },
    {
      "x": -19,
      "y": -14,
      "z": -4,
      "name": "Rock_Basalt"
    },
    {
      "x": -19,
      "y": -13,
      "z": -4,
      "name": "Rock_Basalt"
    },
    {
      "x": -19,
      "y": -12,
      "z": -4,
      "name": "Rock_Basalt"
    },
    {
      "x": -19,
      "y": -11,
      "z": -4,
      "name": "Rock_Basalt"
    },
    {
      "x": -19,
      "y": -10,
      "z": -4,
      "name": "Rock_Basalt"
    },
    {
      "x": -19,
      "y": -9,
      "z": -4,
      "name": "Rock_Basalt"
    },
    {
      "x": -19,
      "y": -8,
      "z": -4,
      "name": "Rock_Basalt"
    },
    {
      "x": -19,
      "y": -7,
      "z": -4,
      "name": "Rock_Basalt"
    },
    {
      "x": -19,
      "y": -6,
      "z": -4,
      "name": "Rock_Basalt"
    },
    {
      "x": -19,
      "y": -5,
      "z": -4,
      "name": "Rock_Basalt"
    },
    {
      "x": -19,
      "y": -4,
      "z": -4,
      "name": "Rock_Basalt"
    },
    {
      "x": -19,
      "y": -3,
      "z": -4,
      "name": "Rock_Basalt"
    },
    {
      "x": -19,
      "y": -2,
      "z": -4,
      "name": "Rock_Basalt"
    },
    {
      "x": -19,
      "y": -14,
      "z": -3,
      "name": "Rock_Basalt"
    },
    {
      "x": -19,
      "y": -13,
      "z": -3,
      "name": "Rock_Basalt"
    },
    {
      "x": -19,
      "y": -12,
      "z": -3,
      "name": "Rock_Basalt"
    },
    {
      "x": -19,
      "y": -11,
      "z": -3,
      "name": "Rock_Basalt"
    },
    {
      "x": -19,
      "y": -10,
      "z": -3,
      "name": "Rock_Basalt"
    },
    {
      "x": -19,
      "y": -9,
      "z": -3,
      "name": "Rock_Basalt"
    },
    {
      "x": -19,
      "y": -8,
      "z": -3,
      "name": "Rock_Basalt"
    },
    {
      "x": -19,
      "y": -7,
      "z": -3,
      "name": "Rock_Basalt"
    },
    {
      "x": -19,
      "y": -6,
      "z": -3,
      "name": "Rock_Basalt"
    },
    {
      "x": -19,
      "y": -5,
      "z": -3,
      "name": "Rock_Basalt"
    },
    {
      "x": -19,
      "y": -4,
      "z": -3,
      "name": "Rock_Basalt"
    },
    {
      "x": -19,
      "y": -3,
      "z": -3,
      "name": "Rock_Basalt"
    },
    {
      "x": -19,
      "y": -14,
      "z": -2,
      "name": "Rock_Basalt"
    },
    {
      "x": -19,
      "y": -13,
      "z": -2,
      "name": "Rock_Basalt"
    },
    {
      "x": -19,
      "y": -12,
      "z": -2,
      "name": "Rock_Basalt"
    },
    {
      "x": -19,
      "y": -11,
      "z": -2,
      "name": "Rock_Basalt"
    },
    {
      "x": -19,
      "y": -10,
      "z": -2,
      "name": "Rock_Basalt"
    },
    {
      "x": -19,
      "y": -9,
      "z": -2,
      "name": "Rock_Basalt"
    },
    {
      "x": -19,
      "y": -8,
      "z": -2,
      "name": "Rock_Basalt"
    },
    {
      "x": -19,
      "y": -7,
      "z": -2,
      "name": "Rock_Basalt"
    },
    {
      "x": -19,
      "y": -6,
      "z": -2,
      "name": "Rock_Basalt"
    },
    {
      "x": -19,
      "y": -5,
      "z": -2,
      "name": "Rock_Basalt"
    },
    {
      "x": -19,
      "y": -4,
      "z": -2,
      "name": "Rock_Basalt"
    },
    {
      "x": -19,
      "y": -3,
      "z": -2,
      "name": "Rock_Basalt"
    },
    {
      "x": -19,
      "y": -14,
      "z": -1,
      "name": "Rock_Basalt"
    },
    {
      "x": -19,
      "y": -13,
      "z": -1,
      "name": "Rock_Basalt"
    },
    {
      "x": -19,
      "y": -12,
      "z": -1,
      "name": "Rock_Basalt"
    },
    {
      "x": -19,
      "y": -11,
      "z": -1,
      "name": "Rock_Basalt"
    },
    {
      "x": -19,
      "y": -10,
      "z": -1,
      "name": "Rock_Basalt"
    },
    {
      "x": -19,
      "y": -9,
      "z": -1,
      "name": "Rock_Basalt"
    },
    {
      "x": -19,
      "y": -8,
      "z": -1,
      "name": "Rock_Basalt"
    },
    {
      "x": -19,
      "y": -7,
      "z": -1,
      "name": "Rock_Basalt"
    },
    {
      "x": -19,
      "y": -6,
      "z": -1,
      "name": "Rock_Basalt"
    },
    {
      "x": -19,
      "y": -5,
      "z": -1,
      "name": "Rock_Basalt"
    },
    {
      "x": -19,
      "y": -4,
      "z": -1,
      "name": "Rock_Basalt"
    },
    {
      "x": -19,
      "y": -3,
      "z": -1,
      "name": "Plant_Moss_Block_Green"
    },
    {
      "x": -19,
      "y": -14,
      "z": 0,
      "name": "Rock_Basalt"
    },
    {
      "x": -19,
      "y": -13,
      "z": 0,
      "name": "Rock_Basalt"
    },
    {
      "x": -19,
      "y": -12,
      "z": 0,
      "name": "Rock_Basalt"
    },
    {
      "x": -19,
      "y": -11,
      "z": 0,
      "name": "Rock_Basalt"
    },
    {
      "x": -19,
      "y": -10,
      "z": 0,
      "name": "Rock_Basalt"
    },
    {
      "x": -19,
      "y": -9,
      "z": 0,
      "name": "Rock_Basalt"
    },
    {
      "x": -19,
      "y": -8,
      "z": 0,
      "name": "Rock_Basalt"
    },
    {
      "x": -19,
      "y": -7,
      "z": 0,
      "name": "Rock_Basalt"
    },
    {
      "x": -19,
      "y": -6,
      "z": 0,
      "name": "Rock_Basalt"
    },
    {
      "x": -19,
      "y": -5,
      "z": 0,
      "name": "Rock_Basalt_Brick"
    },
    {
      "x": -19,
      "y": -4,
      "z": 0,
      "name": "Rock_Basalt_Brick"
    },
    {
      "x": -19,
      "y": -3,
      "z": 0,
      "name": "Plant_Moss_Block_Green"
    },
    {
      "x": -19,
      "y": -14,
      "z": 1,
      "name": "Rock_Basalt"
    },
    {
      "x": -19,
      "y": -13,
      "z": 1,
      "name": "Rock_Basalt"
    },
    {
      "x": -19,
      "y": -12,
      "z": 1,
      "name": "Rock_Basalt"
    },
    {
      "x": -19,
      "y": -11,
      "z": 1,
      "name": "Rock_Basalt"
    },
    {
      "x": -19,
      "y": -10,
      "z": 1,
      "name": "Rock_Basalt"
    },
    {
      "x": -19,
      "y": -9,
      "z": 1,
      "name": "Rock_Basalt"
    },
    {
      "x": -19,
      "y": -8,
      "z": 1,
      "name": "Rock_Basalt"
    },
    {
      "x": -19,
      "y": -7,
      "z": 1,
      "name": "Rock_Basalt"
    },
    {
      "x": -19,
      "y": -6,
      "z": 1,
      "name": "Rock_Basalt"
    },
    {
      "x": -19,
      "y": -5,
      "z": 1,
      "name": "Rock_Basalt_Brick"
    },
    {
      "x": -19,
      "y": -4,
      "z": 1,
      "name": "Rock_Basalt_Brick"
    },
    {
      "x": -19,
      "y": -3,
      "z": 1,
      "name": "Plant_Moss_Block_Green"
    },
    {
      "x": -19,
      "y": -14,
      "z": 2,
      "name": "Rock_Basalt"
    },
    {
      "x": -19,
      "y": -13,
      "z": 2,
      "name": "Rock_Basalt"
    },
    {
      "x": -19,
      "y": -12,
      "z": 2,
      "name": "Rock_Basalt"
    },
    {
      "x": -19,
      "y": -11,
      "z": 2,
      "name": "Rock_Basalt"
    },
    {
      "x": -19,
      "y": -10,
      "z": 2,
      "name": "Rock_Basalt"
    },
    {
      "x": -19,
      "y": -9,
      "z": 2,
      "name": "Rock_Basalt"
    },
    {
      "x": -19,
      "y": -8,
      "z": 2,
      "name": "Rock_Basalt"
    },
    {
      "x": -19,
      "y": -7,
      "z": 2,
      "name": "Rock_Basalt"
    },
    {
      "x": -19,
      "y": -6,
      "z": 2,
      "name": "Rock_Sandstone_Red_Brick"
    },
    {
      "x": -19,
      "y": -5,
      "z": 2,
      "name": "Rock_Sandstone_Red_Brick"
    },
    {
      "x": -19,
      "y": -4,
      "z": 2,
      "name": "Rock_Basalt_Brick"
    },
    {
      "x": -19,
      "y": -3,
      "z": 2,
      "name": "Plant_Moss_Block_Green"
    },
    {
      "x": -19,
      "y": -14,
      "z": 3,
      "name": "Rock_Basalt"
    },
    {
      "x": -19,
      "y": -13,
      "z": 3,
      "name": "Rock_Basalt"
    },
    {
      "x": -19,
      "y": -12,
      "z": 3,
      "name": "Rock_Basalt"
    },
    {
      "x": -19,
      "y": -11,
      "z": 3,
      "name": "Rock_Basalt"
    },
    {
      "x": -19,
      "y": -10,
      "z": 3,
      "name": "Rock_Basalt"
    },
    {
      "x": -19,
      "y": -9,
      "z": 3,
      "name": "Rock_Basalt"
    },
    {
      "x": -19,
      "y": -8,
      "z": 3,
      "name": "Rock_Basalt"
    },
    {
      "x": -19,
      "y": -7,
      "z": 3,
      "name": "Rock_Basalt"
    },
    {
      "x": -19,
      "y": -6,
      "z": 3,
      "name": "Rock_Sandstone_Red_Brick"
    },
    {
      "x": -19,
      "y": -5,
      "z": 3,
      "name": "Rock_Sandstone_Red_Brick"
    },
    {
      "x": -19,
      "y": -4,
      "z": 3,
      "name": "Rock_Basalt_Brick"
    },
    {
      "x": -19,
      "y": -3,
      "z": 3,
      "name": "Plant_Moss_Block_Green"
    },
    {
      "x": -19,
      "y": -14,
      "z": 4,
      "name": "Rock_Basalt"
    },
    {
      "x": -19,
      "y": -13,
      "z": 4,
      "name": "Rock_Basalt"
    },
    {
      "x": -19,
      "y": -12,
      "z": 4,
      "name": "Rock_Basalt"
    },
    {
      "x": -19,
      "y": -11,
      "z": 4,
      "name": "Rock_Basalt"
    },
    {
      "x": -19,
      "y": -10,
      "z": 4,
      "name": "Rock_Basalt"
    },
    {
      "x": -19,
      "y": -9,
      "z": 4,
      "name": "Rock_Basalt"
    },
    {
      "x": -19,
      "y": -8,
      "z": 4,
      "name": "Rock_Basalt"
    },
    {
      "x": -19,
      "y": -7,
      "z": 4,
      "name": "Rock_Basalt"
    },
    {
      "x": -19,
      "y": -6,
      "z": 4,
      "name": "Rock_Basalt"
    },
    {
      "x": -19,
      "y": -5,
      "z": 4,
      "name": "Rock_Sandstone_Red_Brick"
    },
    {
      "x": -19,
      "y": -4,
      "z": 4,
      "name": "Rock_Basalt_Brick"
    },
    {
      "x": -19,
      "y": -3,
      "z": 4,
      "name": "Plant_Moss_Block_Green"
    },
    {
      "x": -19,
      "y": -14,
      "z": 5,
      "name": "Rock_Basalt"
    },
    {
      "x": -19,
      "y": -13,
      "z": 5,
      "name": "Rock_Basalt"
    },
    {
      "x": -19,
      "y": -12,
      "z": 5,
      "name": "Rock_Basalt"
    },
    {
      "x": -19,
      "y": -11,
      "z": 5,
      "name": "Rock_Basalt"
    },
    {
      "x": -19,
      "y": -10,
      "z": 5,
      "name": "Rock_Basalt"
    },
    {
      "x": -19,
      "y": -9,
      "z": 5,
      "name": "Rock_Basalt"
    },
    {
      "x": -19,
      "y": -8,
      "z": 5,
      "name": "Rock_Basalt"
    },
    {
      "x": -19,
      "y": -7,
      "z": 5,
      "name": "Rock_Basalt"
    },
    {
      "x": -19,
      "y": -6,
      "z": 5,
      "name": "Rock_Sandstone_Red_Brick"
    },
    {
      "x": -19,
      "y": -5,
      "z": 5,
      "name": "Rock_Sandstone_Red_Brick"
    },
    {
      "x": -19,
      "y": -4,
      "z": 5,
      "name": "Rock_Basalt_Brick"
    },
    {
      "x": -19,
      "y": -3,
      "z": 5,
      "name": "Plant_Moss_Block_Green"
    },
    {
      "x": -19,
      "y": -14,
      "z": 6,
      "name": "Rock_Basalt"
    },
    {
      "x": -19,
      "y": -13,
      "z": 6,
      "name": "Rock_Basalt"
    },
    {
      "x": -19,
      "y": -12,
      "z": 6,
      "name": "Rock_Basalt"
    },
    {
      "x": -19,
      "y": -11,
      "z": 6,
      "name": "Rock_Basalt"
    },
    {
      "x": -19,
      "y": -10,
      "z": 6,
      "name": "Rock_Basalt"
    },
    {
      "x": -19,
      "y": -9,
      "z": 6,
      "name": "Rock_Basalt"
    },
    {
      "x": -19,
      "y": -8,
      "z": 6,
      "name": "Rock_Basalt"
    },
    {
      "x": -19,
      "y": -7,
      "z": 6,
      "name": "Rock_Basalt"
    },
    {
      "x": -19,
      "y": -6,
      "z": 6,
      "name": "Rock_Basalt"
    },
    {
      "x": -19,
      "y": -5,
      "z": 6,
      "name": "Rock_Basalt"
    },
    {
      "x": -19,
      "y": -4,
      "z": 6,
      "name": "Rock_Basalt_Brick"
    },
    {
      "x": -19,
      "y": -3,
      "z": 6,
      "name": "Plant_Moss_Block_Green"
    },
    {
      "x": -19,
      "y": -14,
      "z": 7,
      "name": "Rock_Basalt"
    },
    {
      "x": -19,
      "y": -13,
      "z": 7,
      "name": "Rock_Basalt"
    },
    {
      "x": -19,
      "y": -12,
      "z": 7,
      "name": "Rock_Basalt"
    },
    {
      "x": -19,
      "y": -11,
      "z": 7,
      "name": "Rock_Basalt"
    },
    {
      "x": -19,
      "y": -10,
      "z": 7,
      "name": "Rock_Basalt"
    },
    {
      "x": -19,
      "y": -9,
      "z": 7,
      "name": "Rock_Basalt"
    },
    {
      "x": -19,
      "y": -8,
      "z": 7,
      "name": "Rock_Basalt"
    },
    {
      "x": -19,
      "y": -7,
      "z": 7,
      "name": "Rock_Basalt"
    },
    {
      "x": -19,
      "y": -6,
      "z": 7,
      "name": "Rock_Basalt"
    },
    {
      "x": -19,
      "y": -5,
      "z": 7,
      "name": "Rock_Basalt"
    },
    {
      "x": -19,
      "y": -4,
      "z": 7,
      "name": "Rock_Basalt"
    },
    {
      "x": -19,
      "y": -3,
      "z": 7,
      "name": "Plant_Moss_Block_Green"
    },
    {
      "x": -19,
      "y": -14,
      "z": 8,
      "name": "Rock_Basalt"
    },
    {
      "x": -19,
      "y": -13,
      "z": 8,
      "name": "Rock_Basalt"
    },
    {
      "x": -19,
      "y": -12,
      "z": 8,
      "name": "Rock_Basalt"
    },
    {
      "x": -19,
      "y": -11,
      "z": 8,
      "name": "Rock_Basalt"
    },
    {
      "x": -19,
      "y": -10,
      "z": 8,
      "name": "Rock_Basalt"
    },
    {
      "x": -19,
      "y": -9,
      "z": 8,
      "name": "Rock_Basalt"
    },
    {
      "x": -19,
      "y": -8,
      "z": 8,
      "name": "Rock_Basalt"
    },
    {
      "x": -19,
      "y": -7,
      "z": 8,
      "name": "Rock_Basalt"
    },
    {
      "x": -19,
      "y": -6,
      "z": 8,
      "name": "Rock_Basalt"
    },
    {
      "x": -19,
      "y": -5,
      "z": 8,
      "name": "Rock_Basalt"
    },
    {
      "x": -19,
      "y": -4,
      "z": 8,
      "name": "Rock_Basalt"
    },
    {
      "x": -19,
      "y": -3,
      "z": 8,
      "name": "Plant_Moss_Block_Green"
    },
    {
      "x": -19,
      "y": -14,
      "z": 9,
      "name": "Rock_Basalt"
    },
    {
      "x": -19,
      "y": -13,
      "z": 9,
      "name": "Rock_Basalt"
    },
    {
      "x": -19,
      "y": -12,
      "z": 9,
      "name": "Rock_Basalt"
    },
    {
      "x": -19,
      "y": -11,
      "z": 9,
      "name": "Rock_Crystal_Yellow_Block"
    },
    {
      "x": -19,
      "y": -10,
      "z": 9,
      "name": "Rock_Crystal_Yellow_Block",
      "rotation": 4
    },
    {
      "x": -19,
      "y": -9,
      "z": 9,
      "name": "Rock_Crystal_Yellow_Block"
    },
    {
      "x": -19,
      "y": -8,
      "z": 9,
      "name": "Rock_Crystal_Yellow_Block",
      "rotation": 5
    },
    {
      "x": -19,
      "y": -7,
      "z": 9,
      "name": "Rock_Basalt"
    },
    {
      "x": -19,
      "y": -6,
      "z": 9,
      "name": "Rock_Basalt"
    },
    {
      "x": -19,
      "y": -5,
      "z": 9,
      "name": "Rock_Basalt"
    },
    {
      "x": -19,
      "y": -4,
      "z": 9,
      "name": "Rock_Basalt"
    },
    {
      "x": -19,
      "y": -3,
      "z": 9,
      "name": "Plant_Moss_Block_Green"
    },
    {
      "x": -19,
      "y": -14,
      "z": 10,
      "name": "Rock_Basalt"
    },
    {
      "x": -19,
      "y": -13,
      "z": 10,
      "name": "Rock_Basalt"
    },
    {
      "x": -19,
      "y": -12,
      "z": 10,
      "name": "Rock_Basalt"
    },
    {
      "x": -19,
      "y": -11,
      "z": 10,
      "name": "Rock_Basalt"
    },
    {
      "x": -19,
      "y": -10,
      "z": 10,
      "name": "Rock_Crystal_Yellow_Block"
    },
    {
      "x": -19,
      "y": -9,
      "z": 10,
      "name": "Rock_Basalt"
    },
    {
      "x": -19,
      "y": -8,
      "z": 10,
      "name": "Rock_Basalt"
    },
    {
      "x": -19,
      "y": -7,
      "z": 10,
      "name": "Rock_Basalt"
    },
    {
      "x": -19,
      "y": -6,
      "z": 10,
      "name": "Rock_Basalt"
    },
    {
      "x": -19,
      "y": -5,
      "z": 10,
      "name": "Rock_Basalt"
    },
    {
      "x": -19,
      "y": -4,
      "z": 10,
      "name": "Rock_Basalt_Brick"
    },
    {
      "x": -19,
      "y": -3,
      "z": 10,
      "name": "Plant_Moss_Block_Green"
    },
    {
      "x": -19,
      "y": -14,
      "z": 11,
      "name": "Rock_Basalt"
    },
    {
      "x": -19,
      "y": -13,
      "z": 11,
      "name": "Rock_Basalt"
    },
    {
      "x": -19,
      "y": -12,
      "z": 11,
      "name": "Rock_Basalt"
    },
    {
      "x": -19,
      "y": -11,
      "z": 11,
      "name": "Rock_Basalt"
    },
    {
      "x": -19,
      "y": -10,
      "z": 11,
      "name": "Rock_Crystal_Yellow_Block",
      "rotation": 5
    },
    {
      "x": -19,
      "y": -9,
      "z": 11,
      "name": "Rock_Basalt"
    },
    {
      "x": -19,
      "y": -8,
      "z": 11,
      "name": "Rock_Basalt"
    },
    {
      "x": -19,
      "y": -7,
      "z": 11,
      "name": "Rock_Basalt"
    },
    {
      "x": -19,
      "y": -6,
      "z": 11,
      "name": "Rock_Basalt"
    },
    {
      "x": -19,
      "y": -5,
      "z": 11,
      "name": "Rock_Basalt"
    },
    {
      "x": -19,
      "y": -4,
      "z": 11,
      "name": "Rock_Basalt_Brick"
    },
    {
      "x": -19,
      "y": -3,
      "z": 11,
      "name": "Plant_Moss_Block_Green"
    },
    {
      "x": -19,
      "y": -14,
      "z": 12,
      "name": "Rock_Basalt"
    },
    {
      "x": -19,
      "y": -13,
      "z": 12,
      "name": "Rock_Basalt"
    },
    {
      "x": -19,
      "y": -12,
      "z": 12,
      "name": "Rock_Basalt"
    },
    {
      "x": -19,
      "y": -11,
      "z": 12,
      "name": "Rock_Basalt"
    },
    {
      "x": -19,
      "y": -10,
      "z": 12,
      "name": "Rock_Basalt"
    },
    {
      "x": -19,
      "y": -9,
      "z": 12,
      "name": "Rock_Basalt"
    },
    {
      "x": -19,
      "y": -8,
      "z": 12,
      "name": "Rock_Basalt"
    },
    {
      "x": -19,
      "y": -7,
      "z": 12,
      "name": "Rock_Basalt"
    },
    {
      "x": -19,
      "y": -6,
      "z": 12,
      "name": "Rock_Basalt"
    },
    {
      "x": -19,
      "y": -5,
      "z": 12,
      "name": "Rock_Basalt"
    },
    {
      "x": -19,
      "y": -4,
      "z": 12,
      "name": "Rock_Basalt_Brick"
    },
    {
      "x": -19,
      "y": -3,
      "z": 12,
      "name": "Plant_Moss_Block_Green"
    },
    {
      "x": -19,
      "y": -14,
      "z": 13,
      "name": "Rock_Basalt"
    },
    {
      "x": -19,
      "y": -13,
      "z": 13,
      "name": "Rock_Basalt"
    },
    {
      "x": -19,
      "y": -12,
      "z": 13,
      "name": "Rock_Basalt"
    },
    {
      "x": -19,
      "y": -11,
      "z": 13,
      "name": "Rock_Basalt"
    },
    {
      "x": -19,
      "y": -10,
      "z": 13,
      "name": "Rock_Basalt"
    },
    {
      "x": -19,
      "y": -9,
      "z": 13,
      "name": "Rock_Basalt"
    },
    {
      "x": -19,
      "y": -8,
      "z": 13,
      "name": "Rock_Basalt"
    },
    {
      "x": -19,
      "y": -7,
      "z": 13,
      "name": "Rock_Basalt"
    },
    {
      "x": -19,
      "y": -6,
      "z": 13,
      "name": "Rock_Basalt"
    },
    {
      "x": -19,
      "y": -5,
      "z": 13,
      "name": "Empty"
    },
    {
      "x": -19,
      "y": -4,
      "z": 13,
      "name": "Rock_Basalt_Brick"
    },
    {
      "x": -19,
      "y": -3,
      "z": 13,
      "name": "Plant_Moss_Block_Green"
    },
    {
      "x": -19,
      "y": -14,
      "z": 14,
      "name": "Rock_Basalt"
    },
    {
      "x": -19,
      "y": -13,
      "z": 14,
      "name": "Rock_Basalt"
    },
    {
      "x": -19,
      "y": -12,
      "z": 14,
      "name": "Rock_Basalt"
    },
    {
      "x": -19,
      "y": -11,
      "z": 14,
      "name": "Rock_Basalt"
    },
    {
      "x": -19,
      "y": -10,
      "z": 14,
      "name": "Rock_Basalt"
    },
    {
      "x": -19,
      "y": -9,
      "z": 14,
      "name": "Rock_Basalt"
    },
    {
      "x": -19,
      "y": -8,
      "z": 14,
      "name": "Rock_Basalt"
    },
    {
      "x": -19,
      "y": -7,
      "z": 14,
      "name": "Rock_Basalt"
    },
    {
      "x": -19,
      "y": -6,
      "z": 14,
      "name": "Empty"
    },
    {
      "x": -19,
      "y": -5,
      "z": 14,
      "name": "Empty"
    },
    {
      "x": -19,
      "y": -4,
      "z": 14,
      "name": "Rock_Basalt_Brick"
    },
    {
      "x": -19,
      "y": -3,
      "z": 14,
      "name": "Plant_Moss_Block_Green"
    },
    {
      "x": -19,
      "y": -14,
      "z": 15,
      "name": "Rock_Basalt"
    },
    {
      "x": -19,
      "y": -13,
      "z": 15,
      "name": "Rock_Basalt"
    },
    {
      "x": -19,
      "y": -12,
      "z": 15,
      "name": "Rock_Basalt"
    },
    {
      "x": -19,
      "y": -11,
      "z": 15,
      "name": "Rock_Basalt"
    },
    {
      "x": -19,
      "y": -10,
      "z": 15,
      "name": "Rock_Basalt"
    },
    {
      "x": -19,
      "y": -9,
      "z": 15,
      "name": "Rock_Basalt"
    },
    {
      "x": -19,
      "y": -8,
      "z": 15,
      "name": "Rock_Basalt"
    },
    {
      "x": -19,
      "y": -7,
      "z": 15,
      "name": "Rock_Basalt"
    },
    {
      "x": -19,
      "y": -6,
      "z": 15,
      "name": "Rock_Sandstone_Red_Brick"
    },
    {
      "x": -19,
      "y": -5,
      "z": 15,
      "name": "Rock_Sandstone_Red_Brick"
    },
    {
      "x": -19,
      "y": -4,
      "z": 15,
      "name": "Rock_Basalt_Brick"
    },
    {
      "x": -19,
      "y": -3,
      "z": 15,
      "name": "Plant_Moss_Block_Green"
    },
    {
      "x": -19,
      "y": -14,
      "z": 16,
      "name": "Rock_Basalt"
    },
    {
      "x": -19,
      "y": -13,
      "z": 16,
      "name": "Rock_Basalt"
    },
    {
      "x": -19,
      "y": -12,
      "z": 16,
      "name": "Rock_Basalt"
    },
    {
      "x": -19,
      "y": -11,
      "z": 16,
      "name": "Rock_Basalt"
    },
    {
      "x": -19,
      "y": -10,
      "z": 16,
      "name": "Rock_Basalt"
    },
    {
      "x": -19,
      "y": -9,
      "z": 16,
      "name": "Rock_Basalt"
    },
    {
      "x": -19,
      "y": -8,
      "z": 16,
      "name": "Rock_Basalt"
    },
    {
      "x": -19,
      "y": -7,
      "z": 16,
      "name": "Rock_Basalt"
    },
    {
      "x": -19,
      "y": -6,
      "z": 16,
      "name": "Rock_Sandstone_Red_Brick"
    },
    {
      "x": -19,
      "y": -5,
      "z": 16,
      "name": "Rock_Sandstone_Red_Brick"
    },
    {
      "x": -19,
      "y": -4,
      "z": 16,
      "name": "Rock_Basalt_Brick"
    },
    {
      "x": -19,
      "y": -3,
      "z": 16,
      "name": "Plant_Moss_Block_Green"
    },
    {
      "x": -19,
      "y": -14,
      "z": 17,
      "name": "Rock_Basalt"
    },
    {
      "x": -19,
      "y": -13,
      "z": 17,
      "name": "Rock_Basalt"
    },
    {
      "x": -19,
      "y": -12,
      "z": 17,
      "name": "Rock_Basalt"
    },
    {
      "x": -19,
      "y": -11,
      "z": 17,
      "name": "Rock_Basalt"
    },
    {
      "x": -19,
      "y": -10,
      "z": 17,
      "name": "Rock_Basalt"
    },
    {
      "x": -19,
      "y": -9,
      "z": 17,
      "name": "Rock_Basalt"
    },
    {
      "x": -19,
      "y": -8,
      "z": 17,
      "name": "Rock_Basalt"
    },
    {
      "x": -19,
      "y": -7,
      "z": 17,
      "name": "Rock_Basalt"
    },
    {
      "x": -19,
      "y": -6,
      "z": 17,
      "name": "Rock_Sandstone_Red_Brick"
    },
    {
      "x": -19,
      "y": -5,
      "z": 17,
      "name": "Rock_Sandstone_Red_Brick"
    },
    {
      "x": -19,
      "y": -4,
      "z": 17,
      "name": "Rock_Basalt_Brick"
    },
    {
      "x": -19,
      "y": -3,
      "z": 17,
      "name": "Plant_Moss_Block_Green"
    },
    {
      "x": -19,
      "y": -14,
      "z": 18,
      "name": "Rock_Basalt"
    },
    {
      "x": -19,
      "y": -13,
      "z": 18,
      "name": "Rock_Basalt"
    },
    {
      "x": -19,
      "y": -12,
      "z": 18,
      "name": "Rock_Basalt"
    },
    {
      "x": -19,
      "y": -11,
      "z": 18,
      "name": "Rock_Basalt"
    },
    {
      "x": -19,
      "y": -10,
      "z": 18,
      "name": "Rock_Basalt"
    },
    {
      "x": -19,
      "y": -9,
      "z": 18,
      "name": "Rock_Basalt"
    },
    {
      "x": -19,
      "y": -8,
      "z": 18,
      "name": "Rock_Basalt"
    },
    {
      "x": -19,
      "y": -7,
      "z": 18,
      "name": "Rock_Basalt"
    },
    {
      "x": -19,
      "y": -6,
      "z": 18,
      "name": "Rock_Sandstone_Red_Brick"
    },
    {
      "x": -19,
      "y": -5,
      "z": 18,
      "name": "Rock_Sandstone_Red_Brick"
    },
    {
      "x": -19,
      "y": -4,
      "z": 18,
      "name": "Rock_Basalt_Brick"
    },
    {
      "x": -19,
      "y": -3,
      "z": 18,
      "name": "Plant_Moss_Block_Green"
    },
    {
      "x": -19,
      "y": -14,
      "z": 19,
      "name": "Rock_Basalt"
    },
    {
      "x": -19,
      "y": -13,
      "z": 19,
      "name": "Rock_Basalt"
    },
    {
      "x": -19,
      "y": -12,
      "z": 19,
      "name": "Rock_Basalt"
    },
    {
      "x": -19,
      "y": -11,
      "z": 19,
      "name": "Rock_Basalt"
    },
    {
      "x": -19,
      "y": -10,
      "z": 19,
      "name": "Rock_Basalt"
    },
    {
      "x": -19,
      "y": -9,
      "z": 19,
      "name": "Rock_Basalt"
    },
    {
      "x": -19,
      "y": -8,
      "z": 19,
      "name": "Rock_Basalt"
    },
    {
      "x": -19,
      "y": -7,
      "z": 19,
      "name": "Rock_Basalt"
    },
    {
      "x": -19,
      "y": -6,
      "z": 19,
      "name": "Rock_Basalt_Brick"
    },
    {
      "x": -19,
      "y": -5,
      "z": 19,
      "name": "Rock_Basalt_Brick"
    },
    {
      "x": -19,
      "y": -4,
      "z": 19,
      "name": "Rock_Basalt_Brick"
    },
    {
      "x": -19,
      "y": -3,
      "z": 19,
      "name": "Plant_Moss_Block_Green"
    },
    {
      "x": -19,
      "y": -14,
      "z": 20,
      "name": "Rock_Basalt"
    },
    {
      "x": -19,
      "y": -13,
      "z": 20,
      "name": "Rock_Basalt"
    },
    {
      "x": -19,
      "y": -12,
      "z": 20,
      "name": "Rock_Basalt"
    },
    {
      "x": -19,
      "y": -11,
      "z": 20,
      "name": "Rock_Basalt"
    },
    {
      "x": -19,
      "y": -10,
      "z": 20,
      "name": "Rock_Basalt"
    },
    {
      "x": -19,
      "y": -9,
      "z": 20,
      "name": "Rock_Basalt"
    },
    {
      "x": -19,
      "y": -8,
      "z": 20,
      "name": "Rock_Basalt"
    },
    {
      "x": -19,
      "y": -7,
      "z": 20,
      "name": "Rock_Basalt"
    },
    {
      "x": -19,
      "y": -6,
      "z": 20,
      "name": "Rock_Basalt"
    },
    {
      "x": -19,
      "y": -5,
      "z": 20,
      "name": "Rock_Basalt_Brick"
    },
    {
      "x": -19,
      "y": -4,
      "z": 20,
      "name": "Rock_Basalt_Brick"
    },
    {
      "x": -19,
      "y": -3,
      "z": 20,
      "name": "Plant_Moss_Block_Green"
    },
    {
      "x": -19,
      "y": -14,
      "z": 21,
      "name": "Rock_Basalt"
    },
    {
      "x": -19,
      "y": -13,
      "z": 21,
      "name": "Rock_Basalt"
    },
    {
      "x": -19,
      "y": -12,
      "z": 21,
      "name": "Rock_Basalt"
    },
    {
      "x": -19,
      "y": -11,
      "z": 21,
      "name": "Rock_Basalt"
    },
    {
      "x": -19,
      "y": -10,
      "z": 21,
      "name": "Rock_Basalt"
    },
    {
      "x": -19,
      "y": -9,
      "z": 21,
      "name": "Rock_Basalt"
    },
    {
      "x": -19,
      "y": -8,
      "z": 21,
      "name": "Rock_Basalt"
    },
    {
      "x": -19,
      "y": -7,
      "z": 21,
      "name": "Rock_Basalt"
    },
    {
      "x": -19,
      "y": -6,
      "z": 21,
      "name": "Rock_Basalt_Brick"
    },
    {
      "x": -19,
      "y": -5,
      "z": 21,
      "name": "Rock_Basalt_Brick"
    },
    {
      "x": -19,
      "y": -4,
      "z": 21,
      "name": "Rock_Basalt_Brick"
    },
    {
      "x": -19,
      "y": -3,
      "z": 21,
      "name": "Plant_Moss_Block_Green"
    },
    {
      "x": -19,
      "y": -14,
      "z": 22,
      "name": "Rock_Basalt"
    },
    {
      "x": -19,
      "y": -13,
      "z": 22,
      "name": "Rock_Basalt"
    },
    {
      "x": -19,
      "y": -12,
      "z": 22,
      "name": "Rock_Basalt"
    },
    {
      "x": -19,
      "y": -11,
      "z": 22,
      "name": "Rock_Basalt"
    },
    {
      "x": -19,
      "y": -10,
      "z": 22,
      "name": "Rock_Basalt"
    },
    {
      "x": -19,
      "y": -9,
      "z": 22,
      "name": "Rock_Basalt"
    },
    {
      "x": -19,
      "y": -8,
      "z": 22,
      "name": "Rock_Basalt"
    },
    {
      "x": -19,
      "y": -7,
      "z": 22,
      "name": "Rock_Basalt"
    },
    {
      "x": -19,
      "y": -6,
      "z": 22,
      "name": "Rock_Basalt_Brick"
    },
    {
      "x": -19,
      "y": -5,
      "z": 22,
      "name": "Rock_Basalt_Brick"
    },
    {
      "x": -19,
      "y": -4,
      "z": 22,
      "name": "Rock_Basalt_Brick"
    },
    {
      "x": -19,
      "y": -3,
      "z": 22,
      "name": "Plant_Moss_Block_Green"
    },
    {
      "x": -19,
      "y": -14,
      "z": 23,
      "name": "Rock_Basalt"
    },
    {
      "x": -19,
      "y": -13,
      "z": 23,
      "name": "Rock_Basalt"
    },
    {
      "x": -19,
      "y": -12,
      "z": 23,
      "name": "Rock_Basalt"
    },
    {
      "x": -19,
      "y": -11,
      "z": 23,
      "name": "Rock_Basalt"
    },
    {
      "x": -19,
      "y": -10,
      "z": 23,
      "name": "Rock_Basalt"
    },
    {
      "x": -19,
      "y": -9,
      "z": 23,
      "name": "Rock_Basalt"
    },
    {
      "x": -19,
      "y": -8,
      "z": 23,
      "name": "Rock_Basalt"
    },
    {
      "x": -19,
      "y": -7,
      "z": 23,
      "name": "Rock_Basalt"
    },
    {
      "x": -19,
      "y": -6,
      "z": 23,
      "name": "Rock_Basalt_Brick"
    },
    {
      "x": -19,
      "y": -5,
      "z": 23,
      "name": "Rock_Basalt_Brick"
    },
    {
      "x": -19,
      "y": -4,
      "z": 23,
      "name": "Rock_Basalt_Brick"
    },
    {
      "x": -19,
      "y": -3,
      "z": 23,
      "name": "Plant_Moss_Block_Green"
    },
    {
      "x": -19,
      "y": -14,
      "z": 24,
      "name": "Rock_Basalt"
    },
    {
      "x": -19,
      "y": -13,
      "z": 24,
      "name": "Rock_Basalt"
    },
    {
      "x": -19,
      "y": -12,
      "z": 24,
      "name": "Rock_Basalt"
    },
    {
      "x": -19,
      "y": -11,
      "z": 24,
      "name": "Rock_Basalt"
    },
    {
      "x": -19,
      "y": -10,
      "z": 24,
      "name": "Rock_Basalt"
    },
    {
      "x": -19,
      "y": -9,
      "z": 24,
      "name": "Rock_Basalt"
    },
    {
      "x": -19,
      "y": -8,
      "z": 24,
      "name": "Rock_Basalt"
    },
    {
      "x": -19,
      "y": -7,
      "z": 24,
      "name": "Rock_Basalt_Brick"
    },
    {
      "x": -19,
      "y": -6,
      "z": 24,
      "name": "Rock_Basalt_Brick"
    },
    {
      "x": -19,
      "y": -5,
      "z": 24,
      "name": "Rock_Basalt_Brick"
    },
    {
      "x": -19,
      "y": -4,
      "z": 24,
      "name": "Rock_Basalt"
    },
    {
      "x": -19,
      "y": -3,
      "z": 24,
      "name": "Plant_Moss_Block_Green"
    },
    {
      "x": -19,
      "y": -14,
      "z": 25,
      "name": "Rock_Basalt"
    },
    {
      "x": -19,
      "y": -13,
      "z": 25,
      "name": "Rock_Basalt"
    },
    {
      "x": -19,
      "y": -12,
      "z": 25,
      "name": "Rock_Basalt"
    },
    {
      "x": -19,
      "y": -11,
      "z": 25,
      "name": "Rock_Basalt"
    },
    {
      "x": -19,
      "y": -10,
      "z": 25,
      "name": "Rock_Basalt"
    },
    {
      "x": -19,
      "y": -9,
      "z": 25,
      "name": "Rock_Basalt"
    },
    {
      "x": -19,
      "y": -8,
      "z": 25,
      "name": "Rock_Basalt"
    },
    {
      "x": -19,
      "y": -7,
      "z": 25,
      "name": "Rock_Basalt"
    },
    {
      "x": -19,
      "y": -14,
      "z": 26,
      "name": "Rock_Basalt"
    },
    {
      "x": -19,
      "y": -13,
      "z": 26,
      "name": "Rock_Basalt"
    },
    {
      "x": -19,
      "y": -12,
      "z": 26,
      "name": "Rock_Basalt"
    },
    {
      "x": -19,
      "y": -11,
      "z": 26,
      "name": "Rock_Basalt"
    },
    {
      "x": -19,
      "y": -10,
      "z": 26,
      "name": "Rock_Basalt"
    },
    {
      "x": -19,
      "y": -9,
      "z": 26,
      "name": "Rock_Basalt"
    },
    {
      "x": -19,
      "y": -14,
      "z": 27,
      "name": "Rock_Basalt"
    },
    {
      "x": -19,
      "y": -13,
      "z": 27,
      "name": "Rock_Basalt"
    },
    {
      "x": -19,
      "y": -12,
      "z": 27,
      "name": "Rock_Basalt"
    },
    {
      "x": -19,
      "y": -11,
      "z": 27,
      "name": "Rock_Basalt"
    },
    {
      "x": -19,
      "y": -10,
      "z": 27,
      "name": "Rock_Basalt"
    },
    {
      "x": -19,
      "y": -14,
      "z": 28,
      "name": "Rock_Basalt"
    },
    {
      "x": -19,
      "y": -13,
      "z": 28,
      "name": "Rock_Basalt"
    },
    {
      "x": -19,
      "y": -12,
      "z": 28,
      "name": "Rock_Basalt"
    },
    {
      "x": -19,
      "y": -11,
      "z": 28,
      "name": "Rock_Basalt"
    },
    {
      "x": -18,
      "y": -14,
      "z": -11,
      "name": "Rock_Basalt"
    },
    {
      "x": -18,
      "y": -13,
      "z": -11,
      "name": "Rock_Basalt"
    },
    {
      "x": -18,
      "y": -14,
      "z": -10,
      "name": "Rock_Basalt"
    },
    {
      "x": -18,
      "y": -13,
      "z": -10,
      "name": "Rock_Basalt"
    },
    {
      "x": -18,
      "y": -12,
      "z": -10,
      "name": "Rock_Basalt"
    },
    {
      "x": -18,
      "y": -11,
      "z": -10,
      "name": "Rock_Basalt"
    },
    {
      "x": -18,
      "y": -10,
      "z": -10,
      "name": "Rock_Basalt"
    },
    {
      "x": -18,
      "y": -9,
      "z": -10,
      "name": "Rock_Basalt"
    },
    {
      "x": -18,
      "y": -14,
      "z": -9,
      "name": "Rock_Basalt"
    },
    {
      "x": -18,
      "y": -13,
      "z": -9,
      "name": "Rock_Basalt"
    },
    {
      "x": -18,
      "y": -12,
      "z": -9,
      "name": "Rock_Basalt"
    },
    {
      "x": -18,
      "y": -11,
      "z": -9,
      "name": "Rock_Basalt"
    },
    {
      "x": -18,
      "y": -10,
      "z": -9,
      "name": "Rock_Basalt"
    },
    {
      "x": -18,
      "y": -9,
      "z": -9,
      "name": "Rock_Basalt"
    },
    {
      "x": -18,
      "y": -8,
      "z": -9,
      "name": "Rock_Basalt"
    },
    {
      "x": -18,
      "y": -7,
      "z": -9,
      "name": "Rock_Basalt"
    },
    {
      "x": -18,
      "y": -6,
      "z": -9,
      "name": "Rock_Basalt"
    },
    {
      "x": -18,
      "y": -14,
      "z": -8,
      "name": "Rock_Basalt"
    },
    {
      "x": -18,
      "y": -13,
      "z": -8,
      "name": "Rock_Basalt"
    },
    {
      "x": -18,
      "y": -12,
      "z": -8,
      "name": "Rock_Basalt"
    },
    {
      "x": -18,
      "y": -11,
      "z": -8,
      "name": "Rock_Basalt"
    },
    {
      "x": -18,
      "y": -10,
      "z": -8,
      "name": "Rock_Basalt"
    },
    {
      "x": -18,
      "y": -9,
      "z": -8,
      "name": "Rock_Basalt"
    },
    {
      "x": -18,
      "y": -8,
      "z": -8,
      "name": "Rock_Basalt"
    },
    {
      "x": -18,
      "y": -7,
      "z": -8,
      "name": "Rock_Basalt"
    },
    {
      "x": -18,
      "y": -6,
      "z": -8,
      "name": "Rock_Basalt"
    },
    {
      "x": -18,
      "y": -5,
      "z": -8,
      "name": "Rock_Basalt"
    },
    {
      "x": -18,
      "y": -14,
      "z": -7,
      "name": "Rock_Basalt"
    },
    {
      "x": -18,
      "y": -13,
      "z": -7,
      "name": "Rock_Basalt"
    },
    {
      "x": -18,
      "y": -12,
      "z": -7,
      "name": "Rock_Basalt"
    },
    {
      "x": -18,
      "y": -11,
      "z": -7,
      "name": "Rock_Basalt"
    },
    {
      "x": -18,
      "y": -10,
      "z": -7,
      "name": "Rock_Basalt"
    },
    {
      "x": -18,
      "y": -9,
      "z": -7,
      "name": "Rock_Basalt"
    },
    {
      "x": -18,
      "y": -8,
      "z": -7,
      "name": "Rock_Basalt"
    },
    {
      "x": -18,
      "y": -7,
      "z": -7,
      "name": "Rock_Basalt"
    },
    {
      "x": -18,
      "y": -6,
      "z": -7,
      "name": "Rock_Basalt"
    },
    {
      "x": -18,
      "y": -5,
      "z": -7,
      "name": "Rock_Basalt"
    },
    {
      "x": -18,
      "y": -4,
      "z": -7,
      "name": "Rock_Basalt"
    },
    {
      "x": -18,
      "y": -14,
      "z": -6,
      "name": "Rock_Basalt"
    },
    {
      "x": -18,
      "y": -13,
      "z": -6,
      "name": "Rock_Basalt"
    },
    {
      "x": -18,
      "y": -12,
      "z": -6,
      "name": "Rock_Basalt"
    },
    {
      "x": -18,
      "y": -11,
      "z": -6,
      "name": "Rock_Basalt"
    },
    {
      "x": -18,
      "y": -10,
      "z": -6,
      "name": "Rock_Basalt"
    },
    {
      "x": -18,
      "y": -9,
      "z": -6,
      "name": "Rock_Basalt"
    },
    {
      "x": -18,
      "y": -8,
      "z": -6,
      "name": "Rock_Basalt"
    },
    {
      "x": -18,
      "y": -7,
      "z": -6,
      "name": "Rock_Basalt"
    },
    {
      "x": -18,
      "y": -6,
      "z": -6,
      "name": "Rock_Basalt"
    },
    {
      "x": -18,
      "y": -5,
      "z": -6,
      "name": "Rock_Basalt"
    },
    {
      "x": -18,
      "y": -4,
      "z": -6,
      "name": "Rock_Basalt"
    },
    {
      "x": -18,
      "y": -3,
      "z": -6,
      "name": "Rock_Basalt"
    },
    {
      "x": -18,
      "y": -14,
      "z": -5,
      "name": "Rock_Basalt"
    },
    {
      "x": -18,
      "y": -13,
      "z": -5,
      "name": "Rock_Basalt"
    },
    {
      "x": -18,
      "y": -12,
      "z": -5,
      "name": "Rock_Basalt"
    },
    {
      "x": -18,
      "y": -11,
      "z": -5,
      "name": "Rock_Basalt"
    },
    {
      "x": -18,
      "y": -10,
      "z": -5,
      "name": "Rock_Basalt"
    },
    {
      "x": -18,
      "y": -9,
      "z": -5,
      "name": "Rock_Basalt"
    },
    {
      "x": -18,
      "y": -8,
      "z": -5,
      "name": "Rock_Basalt"
    },
    {
      "x": -18,
      "y": -7,
      "z": -5,
      "name": "Rock_Basalt"
    },
    {
      "x": -18,
      "y": -6,
      "z": -5,
      "name": "Rock_Basalt"
    },
    {
      "x": -18,
      "y": -5,
      "z": -5,
      "name": "Rock_Basalt"
    },
    {
      "x": -18,
      "y": -4,
      "z": -5,
      "name": "Rock_Basalt"
    },
    {
      "x": -18,
      "y": -3,
      "z": -5,
      "name": "Rock_Basalt"
    },
    {
      "x": -18,
      "y": -14,
      "z": -4,
      "name": "Rock_Basalt"
    },
    {
      "x": -18,
      "y": -13,
      "z": -4,
      "name": "Rock_Basalt"
    },
    {
      "x": -18,
      "y": -12,
      "z": -4,
      "name": "Rock_Basalt"
    },
    {
      "x": -18,
      "y": -11,
      "z": -4,
      "name": "Rock_Basalt"
    },
    {
      "x": -18,
      "y": -10,
      "z": -4,
      "name": "Rock_Basalt"
    },
    {
      "x": -18,
      "y": -9,
      "z": -4,
      "name": "Rock_Basalt"
    },
    {
      "x": -18,
      "y": -8,
      "z": -4,
      "name": "Rock_Basalt"
    },
    {
      "x": -18,
      "y": -7,
      "z": -4,
      "name": "Rock_Basalt"
    },
    {
      "x": -18,
      "y": -6,
      "z": -4,
      "name": "Rock_Basalt"
    },
    {
      "x": -18,
      "y": -5,
      "z": -4,
      "name": "Rock_Basalt"
    },
    {
      "x": -18,
      "y": -4,
      "z": -4,
      "name": "Rock_Basalt"
    },
    {
      "x": -18,
      "y": -3,
      "z": -4,
      "name": "Rock_Basalt"
    },
    {
      "x": -18,
      "y": -2,
      "z": -4,
      "name": "Rock_Basalt"
    },
    {
      "x": -18,
      "y": -14,
      "z": -3,
      "name": "Rock_Basalt"
    },
    {
      "x": -18,
      "y": -13,
      "z": -3,
      "name": "Rock_Basalt"
    },
    {
      "x": -18,
      "y": -12,
      "z": -3,
      "name": "Rock_Basalt"
    },
    {
      "x": -18,
      "y": -11,
      "z": -3,
      "name": "Rock_Basalt"
    },
    {
      "x": -18,
      "y": -10,
      "z": -3,
      "name": "Rock_Basalt"
    },
    {
      "x": -18,
      "y": -9,
      "z": -3,
      "name": "Rock_Basalt"
    },
    {
      "x": -18,
      "y": -8,
      "z": -3,
      "name": "Rock_Basalt"
    },
    {
      "x": -18,
      "y": -7,
      "z": -3,
      "name": "Rock_Basalt"
    },
    {
      "x": -18,
      "y": -6,
      "z": -3,
      "name": "Rock_Basalt"
    },
    {
      "x": -18,
      "y": -5,
      "z": -3,
      "name": "Rock_Basalt"
    },
    {
      "x": -18,
      "y": -4,
      "z": -3,
      "name": "Rock_Basalt"
    },
    {
      "x": -18,
      "y": -3,
      "z": -3,
      "name": "Rock_Basalt"
    },
    {
      "x": -18,
      "y": -2,
      "z": -3,
      "name": "Rock_Basalt"
    },
    {
      "x": -18,
      "y": -14,
      "z": -2,
      "name": "Rock_Basalt"
    },
    {
      "x": -18,
      "y": -13,
      "z": -2,
      "name": "Rock_Basalt"
    },
    {
      "x": -18,
      "y": -12,
      "z": -2,
      "name": "Rock_Basalt"
    },
    {
      "x": -18,
      "y": -11,
      "z": -2,
      "name": "Rock_Basalt"
    },
    {
      "x": -18,
      "y": -10,
      "z": -2,
      "name": "Rock_Basalt"
    },
    {
      "x": -18,
      "y": -9,
      "z": -2,
      "name": "Rock_Basalt"
    },
    {
      "x": -18,
      "y": -8,
      "z": -2,
      "name": "Rock_Basalt"
    },
    {
      "x": -18,
      "y": -7,
      "z": -2,
      "name": "Rock_Basalt"
    },
    {
      "x": -18,
      "y": -6,
      "z": -2,
      "name": "Rock_Basalt"
    },
    {
      "x": -18,
      "y": -5,
      "z": -2,
      "name": "Rock_Basalt"
    },
    {
      "x": -18,
      "y": -4,
      "z": -2,
      "name": "Rock_Basalt"
    },
    {
      "x": -18,
      "y": -3,
      "z": -2,
      "name": "Rock_Basalt"
    },
    {
      "x": -18,
      "y": -14,
      "z": -1,
      "name": "Rock_Basalt"
    },
    {
      "x": -18,
      "y": -13,
      "z": -1,
      "name": "Rock_Basalt"
    },
    {
      "x": -18,
      "y": -12,
      "z": -1,
      "name": "Rock_Basalt"
    },
    {
      "x": -18,
      "y": -11,
      "z": -1,
      "name": "Rock_Basalt"
    },
    {
      "x": -18,
      "y": -10,
      "z": -1,
      "name": "Rock_Basalt"
    },
    {
      "x": -18,
      "y": -9,
      "z": -1,
      "name": "Rock_Basalt"
    },
    {
      "x": -18,
      "y": -8,
      "z": -1,
      "name": "Rock_Basalt"
    },
    {
      "x": -18,
      "y": -7,
      "z": -1,
      "name": "Rock_Basalt"
    },
    {
      "x": -18,
      "y": -6,
      "z": -1,
      "name": "Rock_Basalt"
    },
    {
      "x": -18,
      "y": -5,
      "z": -1,
      "name": "Rock_Basalt"
    },
    {
      "x": -18,
      "y": -4,
      "z": -1,
      "name": "Rock_Basalt"
    },
    {
      "x": -18,
      "y": -3,
      "z": -1,
      "name": "Plant_Moss_Block_Green"
    },
    {
      "x": -18,
      "y": -14,
      "z": 0,
      "name": "Rock_Basalt"
    },
    {
      "x": -18,
      "y": -13,
      "z": 0,
      "name": "Rock_Basalt"
    },
    {
      "x": -18,
      "y": -12,
      "z": 0,
      "name": "Rock_Basalt"
    },
    {
      "x": -18,
      "y": -11,
      "z": 0,
      "name": "Rock_Basalt"
    },
    {
      "x": -18,
      "y": -10,
      "z": 0,
      "name": "Rock_Basalt"
    },
    {
      "x": -18,
      "y": -9,
      "z": 0,
      "name": "Rock_Basalt"
    },
    {
      "x": -18,
      "y": -8,
      "z": 0,
      "name": "Rock_Basalt"
    },
    {
      "x": -18,
      "y": -7,
      "z": 0,
      "name": "Rock_Basalt"
    },
    {
      "x": -18,
      "y": -6,
      "z": 0,
      "name": "Rock_Basalt"
    },
    {
      "x": -18,
      "y": -5,
      "z": 0,
      "name": "Rock_Basalt_Brick"
    },
    {
      "x": -18,
      "y": -4,
      "z": 0,
      "name": "Rock_Basalt_Brick"
    },
    {
      "x": -18,
      "y": -3,
      "z": 0,
      "name": "Plant_Moss_Block_Green"
    },
    {
      "x": -18,
      "y": -14,
      "z": 1,
      "name": "Rock_Basalt"
    },
    {
      "x": -18,
      "y": -13,
      "z": 1,
      "name": "Rock_Basalt"
    },
    {
      "x": -18,
      "y": -12,
      "z": 1,
      "name": "Rock_Basalt"
    },
    {
      "x": -18,
      "y": -11,
      "z": 1,
      "name": "Rock_Basalt"
    },
    {
      "x": -18,
      "y": -10,
      "z": 1,
      "name": "Rock_Basalt"
    },
    {
      "x": -18,
      "y": -9,
      "z": 1,
      "name": "Rock_Basalt"
    },
    {
      "x": -18,
      "y": -8,
      "z": 1,
      "name": "Rock_Basalt"
    },
    {
      "x": -18,
      "y": -7,
      "z": 1,
      "name": "Rock_Basalt"
    },
    {
      "x": -18,
      "y": -6,
      "z": 1,
      "name": "Rock_Basalt"
    },
    {
      "x": -18,
      "y": -5,
      "z": 1,
      "name": "Empty"
    },
    {
      "x": -18,
      "y": -4,
      "z": 1,
      "name": "Rock_Basalt_Brick"
    },
    {
      "x": -18,
      "y": -3,
      "z": 1,
      "name": "Plant_Moss_Block_Green"
    },
    {
      "x": -18,
      "y": -14,
      "z": 2,
      "name": "Rock_Basalt"
    },
    {
      "x": -18,
      "y": -13,
      "z": 2,
      "name": "Rock_Basalt"
    },
    {
      "x": -18,
      "y": -12,
      "z": 2,
      "name": "Rock_Basalt"
    },
    {
      "x": -18,
      "y": -11,
      "z": 2,
      "name": "Rock_Basalt"
    },
    {
      "x": -18,
      "y": -10,
      "z": 2,
      "name": "Rock_Basalt"
    },
    {
      "x": -18,
      "y": -9,
      "z": 2,
      "name": "Rock_Basalt"
    },
    {
      "x": -18,
      "y": -8,
      "z": 2,
      "name": "Rock_Basalt"
    },
    {
      "x": -18,
      "y": -7,
      "z": 2,
      "name": "Rock_Basalt"
    },
    {
      "x": -18,
      "y": -6,
      "z": 2,
      "name": "Rock_Basalt"
    },
    {
      "x": -18,
      "y": -5,
      "z": 2,
      "name": "Empty"
    },
    {
      "x": -18,
      "y": -4,
      "z": 2,
      "name": "Rock_Basalt_Brick"
    },
    {
      "x": -18,
      "y": -3,
      "z": 2,
      "name": "Plant_Moss_Block_Green"
    },
    {
      "x": -18,
      "y": -14,
      "z": 3,
      "name": "Rock_Basalt"
    },
    {
      "x": -18,
      "y": -13,
      "z": 3,
      "name": "Rock_Basalt"
    },
    {
      "x": -18,
      "y": -12,
      "z": 3,
      "name": "Rock_Basalt"
    },
    {
      "x": -18,
      "y": -11,
      "z": 3,
      "name": "Rock_Basalt"
    },
    {
      "x": -18,
      "y": -10,
      "z": 3,
      "name": "Rock_Basalt"
    },
    {
      "x": -18,
      "y": -9,
      "z": 3,
      "name": "Rock_Basalt"
    },
    {
      "x": -18,
      "y": -8,
      "z": 3,
      "name": "Rock_Basalt"
    },
    {
      "x": -18,
      "y": -7,
      "z": 3,
      "name": "Rock_Basalt"
    },
    {
      "x": -18,
      "y": -6,
      "z": 3,
      "name": "Rock_Sandstone_Red_Brick"
    },
    {
      "x": -18,
      "y": -5,
      "z": 3,
      "name": "Rock_Sandstone_Red_Brick"
    },
    {
      "x": -18,
      "y": -4,
      "z": 3,
      "name": "Rock_Basalt_Brick"
    },
    {
      "x": -18,
      "y": -3,
      "z": 3,
      "name": "Plant_Moss_Block_Green"
    },
    {
      "x": -18,
      "y": -14,
      "z": 4,
      "name": "Rock_Basalt"
    },
    {
      "x": -18,
      "y": -13,
      "z": 4,
      "name": "Rock_Basalt"
    },
    {
      "x": -18,
      "y": -12,
      "z": 4,
      "name": "Rock_Basalt"
    },
    {
      "x": -18,
      "y": -11,
      "z": 4,
      "name": "Rock_Basalt"
    },
    {
      "x": -18,
      "y": -10,
      "z": 4,
      "name": "Rock_Basalt"
    },
    {
      "x": -18,
      "y": -9,
      "z": 4,
      "name": "Rock_Basalt"
    },
    {
      "x": -18,
      "y": -8,
      "z": 4,
      "name": "Rock_Basalt",
      "support": 15
    },
    {
      "x": -18,
      "y": -7,
      "z": 4,
      "name": "Rock_Basalt"
    },
    {
      "x": -18,
      "y": -6,
      "z": 4,
      "name": "Rock_Sandstone_Red_Brick"
    },
    {
      "x": -18,
      "y": -5,
      "z": 4,
      "name": "Rock_Sandstone_Red_Brick"
    },
    {
      "x": -18,
      "y": -4,
      "z": 4,
      "name": "Rock_Basalt_Brick"
    },
    {
      "x": -18,
      "y": -3,
      "z": 4,
      "name": "Plant_Moss_Block_Green"
    },
    {
      "x": -18,
      "y": -14,
      "z": 5,
      "name": "Rock_Basalt"
    },
    {
      "x": -18,
      "y": -13,
      "z": 5,
      "name": "Rock_Basalt"
    },
    {
      "x": -18,
      "y": -12,
      "z": 5,
      "name": "Rock_Basalt"
    },
    {
      "x": -18,
      "y": -11,
      "z": 5,
      "name": "Rock_Basalt"
    },
    {
      "x": -18,
      "y": -10,
      "z": 5,
      "name": "Rock_Basalt"
    },
    {
      "x": -18,
      "y": -9,
      "z": 5,
      "name": "Rock_Basalt"
    },
    {
      "x": -18,
      "y": -8,
      "z": 5,
      "name": "Rock_Basalt"
    },
    {
      "x": -18,
      "y": -7,
      "z": 5,
      "name": "Rock_Basalt"
    },
    {
      "x": -18,
      "y": -6,
      "z": 5,
      "name": "Rock_Sandstone_Red_Brick"
    },
    {
      "x": -18,
      "y": -5,
      "z": 5,
      "name": "Rock_Sandstone_Red_Brick"
    },
    {
      "x": -18,
      "y": -4,
      "z": 5,
      "name": "Rock_Basalt_Brick"
    },
    {
      "x": -18,
      "y": -3,
      "z": 5,
      "name": "Plant_Moss_Block_Green"
    },
    {
      "x": -18,
      "y": -14,
      "z": 6,
      "name": "Rock_Basalt"
    },
    {
      "x": -18,
      "y": -13,
      "z": 6,
      "name": "Rock_Basalt"
    },
    {
      "x": -18,
      "y": -12,
      "z": 6,
      "name": "Rock_Basalt"
    },
    {
      "x": -18,
      "y": -11,
      "z": 6,
      "name": "Rock_Basalt"
    },
    {
      "x": -18,
      "y": -10,
      "z": 6,
      "name": "Rock_Basalt"
    },
    {
      "x": -18,
      "y": -9,
      "z": 6,
      "name": "Rock_Basalt"
    },
    {
      "x": -18,
      "y": -8,
      "z": 6,
      "name": "Rock_Basalt"
    },
    {
      "x": -18,
      "y": -7,
      "z": 6,
      "name": "Rock_Basalt_Brick"
    },
    {
      "x": -18,
      "y": -6,
      "z": 6,
      "name": "Empty"
    },
    {
      "x": -18,
      "y": -5,
      "z": 6,
      "name": "Empty"
    },
    {
      "x": -18,
      "y": -4,
      "z": 6,
      "name": "Rock_Basalt_Brick"
    },
    {
      "x": -18,
      "y": -3,
      "z": 6,
      "name": "Plant_Moss_Block_Green"
    },
    {
      "x": -18,
      "y": -14,
      "z": 7,
      "name": "Rock_Basalt"
    },
    {
      "x": -18,
      "y": -13,
      "z": 7,
      "name": "Rock_Basalt"
    },
    {
      "x": -18,
      "y": -12,
      "z": 7,
      "name": "Rock_Basalt"
    },
    {
      "x": -18,
      "y": -11,
      "z": 7,
      "name": "Rock_Basalt"
    },
    {
      "x": -18,
      "y": -10,
      "z": 7,
      "name": "Rock_Basalt"
    },
    {
      "x": -18,
      "y": -9,
      "z": 7,
      "name": "Rock_Basalt"
    },
    {
      "x": -18,
      "y": -8,
      "z": 7,
      "name": "Rock_Basalt"
    },
    {
      "x": -18,
      "y": -7,
      "z": 7,
      "name": "Rock_Basalt"
    },
    {
      "x": -18,
      "y": -6,
      "z": 7,
      "name": "Empty"
    },
    {
      "x": -18,
      "y": -5,
      "z": 7,
      "name": "Empty"
    },
    {
      "x": -18,
      "y": -4,
      "z": 7,
      "name": "Rock_Basalt_Brick"
    },
    {
      "x": -18,
      "y": -3,
      "z": 7,
      "name": "Plant_Moss_Block_Green"
    },
    {
      "x": -18,
      "y": -14,
      "z": 8,
      "name": "Rock_Basalt"
    },
    {
      "x": -18,
      "y": -13,
      "z": 8,
      "name": "Rock_Basalt"
    },
    {
      "x": -18,
      "y": -12,
      "z": 8,
      "name": "Rock_Basalt"
    },
    {
      "x": -18,
      "y": -11,
      "z": 8,
      "name": "Empty"
    },
    {
      "x": -18,
      "y": -10,
      "z": 8,
      "name": "Rock_Basalt"
    },
    {
      "x": -18,
      "y": -9,
      "z": 8,
      "name": "Rock_Basalt"
    },
    {
      "x": -18,
      "y": -8,
      "z": 8,
      "name": "Rock_Basalt"
    },
    {
      "x": -18,
      "y": -7,
      "z": 8,
      "name": "Rock_Basalt"
    },
    {
      "x": -18,
      "y": -6,
      "z": 8,
      "name": "Rock_Basalt"
    },
    {
      "x": -18,
      "y": -5,
      "z": 8,
      "name": "Rock_Basalt"
    },
    {
      "x": -18,
      "y": -4,
      "z": 8,
      "name": "Rock_Basalt_Brick"
    },
    {
      "x": -18,
      "y": -3,
      "z": 8,
      "name": "Plant_Moss_Block_Green"
    },
    {
      "x": -18,
      "y": -14,
      "z": 9,
      "name": "Rock_Basalt"
    },
    {
      "x": -18,
      "y": -13,
      "z": 9,
      "name": "Rock_Basalt"
    },
    {
      "x": -18,
      "y": -12,
      "z": 9,
      "name": "Rock_Basalt"
    },
    {
      "x": -18,
      "y": -11,
      "z": 9,
      "name": "Empty"
    },
    {
      "x": -18,
      "y": -10,
      "z": 9,
      "name": "Empty"
    },
    {
      "x": -18,
      "y": -9,
      "z": 9,
      "name": "Empty"
    },
    {
      "x": -18,
      "y": -8,
      "z": 9,
      "name": "Rock_Basalt"
    },
    {
      "x": -18,
      "y": -7,
      "z": 9,
      "name": "Rock_Basalt"
    },
    {
      "x": -18,
      "y": -6,
      "z": 9,
      "name": "Rock_Basalt"
    },
    {
      "x": -18,
      "y": -5,
      "z": 9,
      "name": "Rock_Basalt"
    },
    {
      "x": -18,
      "y": -4,
      "z": 9,
      "name": "Rock_Basalt_Brick"
    },
    {
      "x": -18,
      "y": -3,
      "z": 9,
      "name": "Plant_Moss_Block_Green"
    },
    {
      "x": -18,
      "y": -14,
      "z": 10,
      "name": "Rock_Basalt"
    },
    {
      "x": -18,
      "y": -13,
      "z": 10,
      "name": "Rock_Basalt"
    },
    {
      "x": -18,
      "y": -12,
      "z": 10,
      "name": "Rock_Basalt"
    },
    {
      "x": -18,
      "y": -11,
      "z": 10,
      "name": "Rock_Basalt"
    },
    {
      "x": -18,
      "y": -10,
      "z": 10,
      "name": "Empty"
    },
    {
      "x": -18,
      "y": -9,
      "z": 10,
      "name": "Plant_Crop_Mushroom_Shelve_Yellow"
    },
    {
      "x": -18,
      "y": -8,
      "z": 10,
      "name": "Empty"
    },
    {
      "x": -18,
      "y": -7,
      "z": 10,
      "name": "Empty"
    },
    {
      "x": -18,
      "y": -6,
      "z": 10,
      "name": "Rock_Basalt"
    },
    {
      "x": -18,
      "y": -5,
      "z": 10,
      "name": "Rock_Basalt"
    },
    {
      "x": -18,
      "y": -4,
      "z": 10,
      "name": "Rock_Basalt_Brick"
    },
    {
      "x": -18,
      "y": -3,
      "z": 10,
      "name": "Plant_Moss_Block_Green"
    },
    {
      "x": -18,
      "y": -14,
      "z": 11,
      "name": "Rock_Basalt"
    },
    {
      "x": -18,
      "y": -13,
      "z": 11,
      "name": "Rock_Basalt"
    },
    {
      "x": -18,
      "y": -12,
      "z": 11,
      "name": "Rock_Basalt"
    },
    {
      "x": -18,
      "y": -11,
      "z": 11,
      "name": "Rock_Basalt"
    },
    {
      "x": -18,
      "y": -10,
      "z": 11,
      "name": "Empty"
    },
    {
      "x": -18,
      "y": -9,
      "z": 11,
      "name": "Empty"
    },
    {
      "x": -18,
      "y": -8,
      "z": 11,
      "name": "Rock_Basalt"
    },
    {
      "x": -18,
      "y": -7,
      "z": 11,
      "name": "Empty"
    },
    {
      "x": -18,
      "y": -6,
      "z": 11,
      "name": "Rock_Basalt"
    },
    {
      "x": -18,
      "y": -5,
      "z": 11,
      "name": "Rock_Basalt"
    },
    {
      "x": -18,
      "y": -4,
      "z": 11,
      "name": "Rock_Basalt_Brick"
    },
    {
      "x": -18,
      "y": -3,
      "z": 11,
      "name": "Plant_Moss_Block_Green"
    },
    {
      "x": -18,
      "y": -14,
      "z": 12,
      "name": "Rock_Basalt"
    },
    {
      "x": -18,
      "y": -13,
      "z": 12,
      "name": "Rock_Basalt"
    },
    {
      "x": -18,
      "y": -12,
      "z": 12,
      "name": "Rock_Basalt"
    },
    {
      "x": -18,
      "y": -11,
      "z": 12,
      "name": "Rock_Basalt"
    },
    {
      "x": -18,
      "y": -10,
      "z": 12,
      "name": "Rock_Basalt"
    },
    {
      "x": -18,
      "y": -9,
      "z": 12,
      "name": "Rock_Basalt"
    },
    {
      "x": -18,
      "y": -8,
      "z": 12,
      "name": "Rock_Basalt"
    },
    {
      "x": -18,
      "y": -7,
      "z": 12,
      "name": "Rock_Basalt"
    },
    {
      "x": -18,
      "y": -6,
      "z": 12,
      "name": "Rock_Basalt"
    },
    {
      "x": -18,
      "y": -5,
      "z": 12,
      "name": "Rock_Basalt"
    },
    {
      "x": -18,
      "y": -4,
      "z": 12,
      "name": "Rock_Basalt_Brick"
    },
    {
      "x": -18,
      "y": -3,
      "z": 12,
      "name": "Plant_Moss_Block_Green"
    },
    {
      "x": -18,
      "y": -14,
      "z": 13,
      "name": "Rock_Basalt"
    },
    {
      "x": -18,
      "y": -13,
      "z": 13,
      "name": "Rock_Basalt"
    },
    {
      "x": -18,
      "y": -12,
      "z": 13,
      "name": "Rock_Basalt"
    },
    {
      "x": -18,
      "y": -11,
      "z": 13,
      "name": "Rock_Basalt"
    },
    {
      "x": -18,
      "y": -10,
      "z": 13,
      "name": "Rock_Basalt"
    },
    {
      "x": -18,
      "y": -9,
      "z": 13,
      "name": "Rock_Basalt"
    },
    {
      "x": -18,
      "y": -8,
      "z": 13,
      "name": "Rock_Basalt"
    },
    {
      "x": -18,
      "y": -7,
      "z": 13,
      "name": "Rock_Basalt"
    },
    {
      "x": -18,
      "y": -6,
      "z": 13,
      "name": "Empty"
    },
    {
      "x": -18,
      "y": -5,
      "z": 13,
      "name": "Empty"
    },
    {
      "x": -18,
      "y": -4,
      "z": 13,
      "name": "Rock_Basalt_Brick"
    },
    {
      "x": -18,
      "y": -3,
      "z": 13,
      "name": "Plant_Moss_Block_Green"
    },
    {
      "x": -18,
      "y": -14,
      "z": 14,
      "name": "Rock_Basalt"
    },
    {
      "x": -18,
      "y": -13,
      "z": 14,
      "name": "Rock_Basalt"
    },
    {
      "x": -18,
      "y": -12,
      "z": 14,
      "name": "Rock_Basalt"
    },
    {
