{
  "version": 8,
  "blockIdVersion": 11,
  "anchorX": -1,
  "anchorY": -1,
  "anchorZ": 0,
  "blocks": [
    {
      "x": -7,
      "y": -2,
      "z": -2,
      "name": "Rock_Basalt"
    },
    {
      "x": -7,
      "y": -1,
      "z": -2,
      "name": "Rock_Basalt"
    },
    {
      "x": -7,
      "y": -2,
      "z": -1,
      "name": "Rock_Basalt"
    },
    {
      "x": -7,
      "y": -1,
      "z": -1,
      "name": "Rock_Basalt"
    },
    {
      "x": -7,
      "y": -2,
      "z": 0,
      "name": "Rock_Basalt"
    },
    {
      "x": -7,
      "y": -1,
      "z": 0,
      "name": "Rock_Basalt"
    },
    {
      "x": -7,
      "y": -2,
      "z": 1,
      "name": "Rock_Basalt"
    },
    {
      "x": -7,
      "y": -1,
      "z": 1,
      "name": "Rock_Basalt"
    },
    {
      "x": -7,
      "y": -1,
      "z": 2,
      "name": "Rock_Basalt"
    },
    {
      "x": -6,
      "y": -1,
      "z": -3,
      "name": "Rock_Basalt"
    },
    {
      "x": -6,
      "y": -3,
      "z": -2,
      "name": "Rock_Basalt"
    },
    {
      "x": -6,
      "y": -2,
      "z": -2,
      "name": "Rock_Basalt"
    },
    {
      "x": -6,
      "y": -1,
      "z": -2,
      "name": "Soil_Grass"
    },
    {
      "x": -6,
      "y": -3,
      "z": -1,
      "name": "Rock_Basalt"
    },
    {
      "x": -6,
      "y": -2,
      "z": -1,
      "name": "Rock_Basalt"
    },
    {
      "x": -6,
      "y": -1,
      "z": -1,
      "name": "Soil_Grass"
    },
    {
      "x": -6,
      "y": 0,
      "z": -1,
      "name": "Cloth_Roof_Hide",
      "rotation": 2
    },
    {
      "x": -6,
      "y": -4,
      "z": 0,
      "name": "Rock_Basalt"
    },
    {
      "x": -6,
      "y": -3,
      "z": 0,
      "name": "Rock_Basalt"
    },
    {
      "x": -6,
      "y": -2,
      "z": 0,
      "name": "Rock_Basalt"
    },
    {
      "x": -6,
      "y": -1,
      "z": 0,
      "name": "Soil_Grass"
    },
    {
      "x": -6,
      "y": 0,
      "z": 0,
      "name": "Plant_Grass_Sharp_Short"
    },
    {
      "x": -6,
      "y": 1,
      "z": 0,
      "name": "Cloth_Roof_Hide",
      "rotation": 2
    },
    {
      "x": -6,
      "y": -4,
      "z": 1,
      "name": "Rock_Basalt"
    },
    {
      "x": -6,
      "y": -3,
      "z": 1,
      "name": "Rock_Basalt"
    },
    {
      "x": -6,
      "y": -2,
      "z": 1,
      "name": "Rock_Basalt"
    },
    {
      "x": -6,
      "y": -1,
      "z": 1,
      "name": "Soil_Grass"
    },
    {
      "x": -6,
      "y": 1,
      "z": 1,
      "name": "Cloth_Roof_Hide"
    },
    {
      "x": -6,
      "y": -3,
      "z": 2,
      "name": "Rock_Basalt"
    },
    {
      "x": -6,
      "y": -2,
      "z": 2,
      "name": "Rock_Basalt"
    },
    {
      "x": -6,
      "y": -1,
      "z": 2,
      "name": "Soil_Grass"
    },
    {
      "x": -6,
      "y": 0,
      "z": 2,
      "name": "Cloth_Roof_Hide"
    },
    {
      "x": -5,
      "y": -2,
      "z": -3,
      "name": "Rock_Basalt"
    },
    {
      "x": -5,
      "y": -1,
      "z": -3,
      "name": "Soil_Dirt"
    },
    {
      "x": -5,
      "y": 0,
      "z": -3,
      "name": "Furniture_Village_Crate"
    },
    {
      "x": -5,
      "y": 1,
      "z": -3,
      "name": "Plant_Moss_Rug_Green"
    },
    {
      "x": -5,
      "y": -3,
      "z": -2,
      "name": "Rock_Basalt"
    },
    {
      "x": -5,
      "y": -2,
      "z": -2,
      "name": "Rock_Basalt"
    },
    {
      "x": -5,
      "y": -1,
      "z": -2,
      "name": "Soil_Dirt"
    },
    {
      "x": -5,
      "y": 0,
      "z": -2,
      "name": "Furniture_Village_Crate"
    },
    {
      "x": -5,
      "y": 1,
      "z": -2,
      "name": "Plant_Moss_Rug_Green"
    },
    {
      "x": -5,
      "y": -4,
      "z": -1,
      "name": "Rock_Basalt"
    },
    {
      "x": -5,
      "y": -3,
      "z": -1,
      "name": "Rock_Basalt"
    },
    {
      "x": -5,
      "y": -2,
      "z": -1,
      "name": "Rock_Basalt"
    },
    {
      "x": -5,
      "y": -1,
      "z": -1,
      "name": "Soil_Grass"
    },
    {
      "x": -5,
      "y": 0,
      "z": -1,
      "name": "Cloth_Roof_Hide",
      "rotation": 2
    },
    {
      "x": -5,
      "y": -5,
      "z": 0,
      "name": "Rock_Basalt"
    },
    {
      "x": -5,
      "y": -4,
      "z": 0,
      "name": "Rock_Basalt"
    },
    {
      "x": -5,
      "y": -3,
      "z": 0,
      "name": "Rock_Basalt"
    },
    {
      "x": -5,
      "y": -2,
      "z": 0,
      "name": "Rock_Basalt"
    },
    {
      "x": -5,
      "y": -1,
      "z": 0,
      "name": "Soil_Grass"
    },
    {
      "x": -5,
      "y": 0,
      "z": 0,
      "name": "Plant_Moss_Rug_Green"
    },
    {
      "x": -5,
      "y": 1,
      "z": 0,
      "name": "Cloth_Roof_Hide",
      "rotation": 2
    },
    {
      "x": -5,
      "y": -5,
      "z": 1,
      "name": "Rock_Basalt"
    },
    {
      "x": -5,
      "y": -4,
      "z": 1,
      "name": "Rock_Basalt"
    },
    {
      "x": -5,
      "y": -3,
      "z": 1,
      "name": "Rock_Basalt"
    },
    {
      "x": -5,
      "y": -2,
      "z": 1,
      "name": "Rock_Basalt"
    },
    {
      "x": -5,
      "y": -1,
      "z": 1,
      "name": "Soil_Dirt"
    },
    {
      "x": -5,
      "y": 0,
      "z": 1,
      "name": "Deco_Bone_Skulls"
    },
    {
      "x": -5,
      "y": 1,
      "z": 1,
      "name": "Cloth_Roof_Hide"
    },
    {
      "x": -5,
      "y": -4,
      "z": 2,
      "name": "Rock_Basalt"
    },
    {
      "x": -5,
      "y": -3,
      "z": 2,
      "name": "Rock_Basalt"
    },
    {
      "x": -5,
      "y": -2,
      "z": 2,
      "name": "Rock_Basalt"
    },
    {
      "x": -5,
      "y": -1,
      "z": 2,
      "name": "Soil_Grass"
    },
    {
      "x": -5,
      "y": 0,
      "z": 2,
      "name": "Cloth_Roof_Hide"
    },
    {
      "x": -5,
      "y": -3,
      "z": 3,
      "name": "Rock_Basalt"
    },
    {
      "x": -5,
      "y": -2,
      "z": 3,
      "name": "Rock_Basalt"
    },
    {
      "x": -4,
      "y": 0,
      "z": -3,
      "name": "Plant_Moss_Wall_Green",
      "rotation": 1
    },
    {
      "x": -4,
      "y": -3,
      "z": -2,
      "name": "Rock_Basalt"
    },
    {
      "x": -4,
      "y": -2,
      "z": -2,
      "name": "Rock_Basalt"
    },
    {
      "x": -4,
      "y": -1,
      "z": -2,
      "name": "Soil_Grass"
    },
    {
      "x": -4,
      "y": 0,
      "z": -2,
      "name": "Furniture_Tavern_Barrel"
    },
    {
      "x": -4,
      "y": -5,
      "z": -1,
      "name": "Rock_Basalt"
    },
    {
      "x": -4,
      "y": -4,
      "z": -1,
      "name": "Rock_Basalt"
    },
    {
      "x": -4,
      "y": -3,
      "z": -1,
      "name": "Rock_Basalt"
    },
    {
      "x": -4,
      "y": -2,
      "z": -1,
      "name": "Rock_Basalt"
    },
    {
      "x": -4,
      "y": -1,
      "z": -1,
      "name": "Soil_Grass"
    },
    {
      "x": -4,
      "y": 0,
      "z": -1,
      "name": "Cloth_Roof_Hide",
      "rotation": 2
    },
    {
      "x": -4,
      "y": -7,
      "z": 0,
      "name": "Rock_Basalt"
    },
    {
      "x": -4,
      "y": -5,
      "z": 0,
      "name": "Rock_Basalt"
    },
    {
      "x": -4,
      "y": -4,
      "z": 0,
      "name": "Rock_Basalt"
    },
    {
      "x": -4,
      "y": -3,
      "z": 0,
      "name": "Rock_Basalt"
    },
    {
      "x": -4,
      "y": -2,
      "z": 0,
      "name": "Rock_Basalt"
    },
    {
      "x": -4,
      "y": -1,
      "z": 0,
      "name": "Soil_Grass"
    },
    {
      "x": -4,
      "y": 0,
      "z": 0,
      "name": "Furniture_Crude_Bed",
      "components": {
        "Components": {
          "PlacedByInteraction": {
            "WhoPlacedUuid": {
              "$binary": "5RPZJ2uQSJ2g+KZxfjqR+g==",
              "$type": "04"
            }
          },
          "RespawnBlock": {}
        }
      },
      "rotation": 1
    },
    {
      "x": -4,
      "y": 1,
      "z": 0,
      "name": "Cloth_Roof_Hide",
      "rotation": 2
    },
    {
      "x": -4,
      "y": -7,
      "z": 1,
      "name": "Rock_Basalt"
    },
    {
      "x": -4,
      "y": -5,
      "z": 1,
      "name": "Rock_Basalt"
    },
    {
      "x": -4,
      "y": -4,
      "z": 1,
      "name": "Rock_Basalt"
    },
    {
      "x": -4,
      "y": -3,
      "z": 1,
      "name": "Rock_Basalt"
    },
    {
      "x": -4,
      "y": -2,
      "z": 1,
      "name": "Rock_Basalt"
    },
    {
      "x": -4,
      "y": -1,
      "z": 1,
      "name": "Soil_Dirt"
    },
    {
      "x": -4,
      "y": 0,
      "z": 1,
      "name": "Deco_Bone_Pile"
    },
    {
      "x": -4,
      "y": 1,
      "z": 1,
      "name": "Cloth_Roof_Hide"
    },
    {
      "x": -4,
      "y": -7,
      "z": 2,
      "name": "Rock_Basalt"
    },
    {
      "x": -4,
      "y": -4,
      "z": 2,
      "name": "Rock_Basalt"
    },
    {
      "x": -4,
      "y": -3,
      "z": 2,
      "name": "Rock_Basalt"
    },
    {
      "x": -4,
      "y": -2,
      "z": 2,
      "name": "Rock_Basalt"
    },
    {
      "x": -4,
      "y": -1,
      "z": 2,
      "name": "Soil_Grass"
    },
    {
      "x": -4,
      "y": 0,
      "z": 2,
      "name": "Cloth_Roof_Hide"
    },
    {
      "x": -4,
      "y": -2,
      "z": 3,
      "name": "Rock_Basalt"
    },
    {
      "x": -4,
      "y": -1,
      "z": 3,
      "name": "Soil_Grass"
    },
    {
      "x": -4,
      "y": 0,
      "z": 3,
      "name": "Plant_Grass_Lush_Tall"
    },
    {
      "x": -3,
      "y": -3,
      "z": -2,
      "name": "Rock_Basalt"
    },
    {
      "x": -3,
      "y": -2,
      "z": -2,
      "name": "Rock_Basalt"
    },
    {
      "x": -3,
      "y": -1,
      "z": -2,
      "name": "Rock_Basalt"
    },
    {
      "x": -3,
      "y": -6,
      "z": -1,
      "name": "Rock_Basalt"
    },
    {
      "x": -3,
      "y": -5,
      "z": -1,
      "name": "Rock_Basalt"
    },
    {
      "x": -3,
      "y": -4,
      "z": -1,
      "name": "Rock_Basalt"
    },
    {
      "x": -3,
      "y": -3,
      "z": -1,
      "name": "Rock_Basalt"
    },
    {
      "x": -3,
      "y": -2,
      "z": -1,
      "name": "Rock_Basalt"
    },
    {
      "x": -3,
      "y": -1,
      "z": -1,
      "name": "Soil_Grass"
    },
    {
      "x": -3,
      "y": 0,
      "z": -1,
      "name": "Cloth_Roof_Hide",
      "rotation": 2
    },
    {
      "x": -3,
      "y": -7,
      "z": 0,
      "name": "Rock_Basalt"
    },
    {
      "x": -3,
      "y": -6,
      "z": 0,
      "name": "Rock_Basalt"
    },
    {
      "x": -3,
      "y": -5,
      "z": 0,
      "name": "Rock_Basalt"
    },
    {
      "x": -3,
      "y": -4,
      "z": 0,
      "name": "Rock_Basalt"
    },
    {
      "x": -3,
      "y": -3,
      "z": 0,
      "name": "Rock_Basalt"
    },
    {
      "x": -3,
      "y": -2,
      "z": 0,
      "name": "Rock_Basalt"
    },
    {
      "x": -3,
      "y": -1,
      "z": 0,
      "name": "Soil_Grass"
    },
    {
      "x": -3,
      "y": 0,
      "z": 0,
      "name": "Furniture_Crude_Bed",
      "filler": 1,
      "rotation": 1
    },
    {
      "x": -3,
      "y": 1,
      "z": 0,
      "name": "Cloth_Roof_Hide",
      "rotation": 2
    },
    {
      "x": -3,
      "y": -7,
      "z": 1,
      "name": "Rock_Basalt"
    },
    {
      "x": -3,
      "y": -6,
      "z": 1,
      "name": "Rock_Basalt"
    },
    {
      "x": -3,
      "y": -5,
      "z": 1,
      "name": "Rock_Basalt"
    },
    {
      "x": -3,
      "y": -4,
      "z": 1,
      "name": "Rock_Basalt"
    },
    {
      "x": -3,
      "y": -3,
      "z": 1,
      "name": "Rock_Basalt"
    },
    {
      "x": -3,
      "y": -2,
      "z": 1,
      "name": "Rock_Basalt"
    },
    {
      "x": -3,
      "y": -1,
      "z": 1,
      "name": "Soil_Grass"
    },
    {
      "x": -3,
      "y": 1,
      "z": 1,
      "name": "Cloth_Roof_Hide"
    },
    {
      "x": -3,
      "y": -7,
      "z": 2,
      "name": "Rock_Basalt"
    },
    {
      "x": -3,
      "y": -5,
      "z": 2,
      "name": "Rock_Basalt"
    },
    {
      "x": -3,
      "y": -4,
      "z": 2,
      "name": "Rock_Basalt"
    },
    {
      "x": -3,
      "y": -3,
      "z": 2,
      "name": "Rock_Basalt"
    },
    {
      "x": -3,
      "y": -2,
      "z": 2,
      "name": "Rock_Basalt"
    },
    {
      "x": -3,
      "y": -1,
      "z": 2,
      "name": "Soil_Grass"
    },
    {
      "x": -3,
      "y": 0,
      "z": 2,
      "name": "Cloth_Roof_Hide"
    },
    {
      "x": -3,
      "y": -3,
      "z": 3,
      "name": "Rock_Basalt"
    },
    {
      "x": -3,
      "y": -2,
      "z": 3,
      "name": "Rock_Basalt"
    },
    {
      "x": -3,
      "y": -1,
      "z": 3,
      "name": "Soil_Dirt"
    },
    {
      "x": -3,
      "y": 0,
      "z": 3,
      "name": "Furniture_Village_Crate"
    },
    {
      "x": -3,
      "y": 1,
      "z": 3,
      "name": "Plant_Moss_Rug_Green"
    },
    {
      "x": -2,
      "y": -1,
      "z": -7,
      "name": "Soil_Grass"
    },
    {
      "x": -2,
      "y": 0,
      "z": -7,
      "name": "Cloth_Roof_Hide",
      "rotation": 3
    },
    {
      "x": -2,
      "y": -1,
      "z": -6,
      "name": "Soil_Grass"
    },
    {
      "x": -2,
      "y": 0,
      "z": -6,
      "name": "Cloth_Roof_Hide",
      "rotation": 3
    },
    {
      "x": -2,
      "y": -1,
      "z": -5,
      "name": "Soil_Grass"
    },
    {
      "x": -2,
      "y": 0,
      "z": -5,
      "name": "Cloth_Roof_Hide",
      "rotation": 3
    },
    {
      "x": -2,
      "y": -1,
      "z": -4,
      "name": "Soil_Grass"
    },
    {
      "x": -2,
      "y": 0,
      "z": -4,
      "name": "Cloth_Roof_Hide",
      "rotation": 3
    },
    {
      "x": -2,
      "y": -2,
      "z": -3,
      "name": "Rock_Basalt"
    },
    {
      "x": -2,
      "y": -4,
      "z": -2,
      "name": "Rock_Basalt"
    },
    {
      "x": -2,
      "y": -3,
      "z": -2,
      "name": "Rock_Basalt"
    },
    {
      "x": -2,
      "y": -2,
      "z": -2,
      "name": "Rock_Basalt"
    },
    {
      "x": -2,
      "y": -5,
      "z": -1,
      "name": "Rock_Basalt"
    },
    {
      "x": -2,
      "y": -4,
      "z": -1,
      "name": "Rock_Basalt"
    },
    {
      "x": -2,
      "y": -3,
      "z": -1,
      "name": "Rock_Basalt"
    },
    {
      "x": -2,
      "y": -2,
      "z": -1,
      "name": "Rock_Basalt"
    },
    {
      "x": -2,
      "y": -1,
      "z": -1,
      "name": "Soil_Grass"
    },
    {
      "x": -2,
      "y": -7,
      "z": 0,
      "name": "Rock_Basalt"
    },
    {
      "x": -2,
      "y": -6,
      "z": 0,
      "name": "Rock_Basalt"
    },
    {
      "x": -2,
      "y": -5,
      "z": 0,
      "name": "Rock_Basalt"
    },
    {
      "x": -2,
      "y": -4,
      "z": 0,
      "name": "Rock_Basalt"
    },
    {
      "x": -2,
      "y": -3,
      "z": 0,
      "name": "Rock_Basalt"
    },
    {
      "x": -2,
      "y": -2,
      "z": 0,
      "name": "Rock_Basalt"
    },
    {
      "x": -2,
      "y": -1,
      "z": 0,
      "name": "Soil_Pathway"
    },
    {
      "x": -2,
      "y": -7,
      "z": 1,
      "name": "Rock_Basalt"
    },
    {
      "x": -2,
      "y": -6,
      "z": 1,
      "name": "Rock_Basalt"
    },
    {
      "x": -2,
      "y": -5,
      "z": 1,
      "name": "Rock_Basalt"
    },
    {
      "x": -2,
      "y": -4,
      "z": 1,
      "name": "Rock_Basalt"
    },
    {
      "x": -2,
      "y": -3,
      "z": 1,
      "name": "Rock_Basalt"
    },
    {
      "x": -2,
      "y": -2,
      "z": 1,
      "name": "Rock_Basalt"
    },
    {
      "x": -2,
      "y": -1,
      "z": 1,
      "name": "Soil_Pathway"
    },
    {
      "x": -2,
      "y": -7,
      "z": 2,
      "name": "Rock_Basalt"
    },
    {
      "x": -2,
      "y": -6,
      "z": 2,
      "name": "Rock_Basalt"
    },
    {
      "x": -2,
      "y": -5,
      "z": 2,
      "name": "Rock_Basalt"
    },
    {
      "x": -2,
      "y": -4,
      "z": 2,
      "name": "Rock_Basalt"
    },
    {
      "x": -2,
      "y": -3,
      "z": 2,
      "name": "Rock_Basalt"
    },
    {
      "x": -2,
      "y": -2,
      "z": 2,
      "name": "Rock_Basalt"
    },
    {
      "x": -2,
      "y": -1,
      "z": 2,
      "name": "Soil_Grass"
    },
    {
      "x": -2,
      "y": -7,
      "z": 3,
      "name": "Rock_Basalt"
    },
    {
      "x": -2,
      "y": -5,
      "z": 3,
      "name": "Rock_Basalt"
    },
    {
      "x": -2,
      "y": -4,
      "z": 3,
      "name": "Rock_Basalt"
    },
    {
      "x": -2,
      "y": -3,
      "z": 3,
      "name": "Rock_Basalt"
    },
    {
      "x": -2,
      "y": -1,
      "z": 3,
      "name": "Soil_Pathway"
    },
    {
      "x": -2,
      "y": -1,
      "z": 4,
      "name": "Soil_Pathway"
    },
    {
      "x": -1,
      "y": -1,
      "z": -7,
      "name": "Soil_Grass"
    },
    {
      "x": -1,
      "y": 0,
      "z": -7,
      "name": "Plant_Grass_Lush_Short"
    },
    {
      "x": -1,
      "y": 1,
      "z": -7,
      "name": "Cloth_Roof_Hide",
      "rotation": 3
    },
    {
      "x": -1,
      "y": -1,
      "z": -6,
      "name": "Soil_Grass"
    },
    {
      "x": -1,
      "y": 0,
      "z": -6,
      "name": "Plant_Moss_Rug_Green"
    },
    {
      "x": -1,
      "y": 1,
      "z": -6,
      "name": "Cloth_Roof_Hide",
      "rotation": 3
    },
    {
      "x": -1,
      "y": -1,
      "z": -5,
      "name": "Soil_Grass"
    },
    {
      "x": -1,
      "y": 0,
      "z": -5,
      "name": "Furniture_Crude_Bed",
      "components": {
        "Components": {
          "PlacedByInteraction": {
            "WhoPlacedUuid": {
              "$binary": "5RPZJ2uQSJ2g+KZxfjqR+g==",
              "$type": "04"
            }
          },
          "RespawnBlock": {}
        }
      }
    },
    {
      "x": -1,
      "y": 1,
      "z": -5,
      "name": "Cloth_Roof_Hide",
      "rotation": 3
    },
    {
      "x": -1,
      "y": -1,
      "z": -4,
      "name": "Soil_Grass"
    },
    {
      "x": -1,
      "y": 0,
      "z": -4,
      "name": "Furniture_Crude_Bed",
      "filler": 32
    },
    {
      "x": -1,
      "y": 1,
      "z": -4,
      "name": "Cloth_Roof_Hide",
      "rotation": 3
    },
    {
      "x": -1,
      "y": -5,
      "z": -3,
      "name": "Rock_Basalt"
    },
    {
      "x": -1,
      "y": -4,
      "z": -3,
      "name": "Rock_Basalt"
    },
    {
      "x": -1,
      "y": -3,
      "z": -3,
      "name": "Rock_Basalt"
    },
    {
      "x": -1,
      "y": -2,
      "z": -3,
      "name": "Rock_Basalt"
    },
    {
      "x": -1,
      "y": -1,
      "z": -3,
      "name": "Soil_Pathway"
    },
    {
      "x": -1,
      "y": -6,
      "z": -2,
      "name": "Rock_Basalt"
    },
    {
      "x": -1,
      "y": -5,
      "z": -2,
      "name": "Rock_Basalt"
    },
    {
      "x": -1,
      "y": -4,
      "z": -2,
      "name": "Rock_Basalt"
    },
    {
      "x": -1,
      "y": -3,
      "z": -2,
      "name": "Rock_Basalt"
    },
    {
      "x": -1,
      "y": -2,
      "z": -2,
      "name": "Rock_Basalt"
    },
    {
      "x": -1,
      "y": -1,
      "z": -2,
      "name": "Soil_Grass"
    },
    {
      "x": -1,
      "y": -6,
      "z": -1,
      "name": "Rock_Basalt"
    },
    {
      "x": -1,
      "y": -5,
      "z": -1,
      "name": "Rock_Basalt"
    },
    {
      "x": -1,
      "y": -4,
      "z": -1,
      "name": "Rock_Basalt"
    },
    {
      "x": -1,
      "y": -3,
      "z": -1,
      "name": "Rock_Basalt"
    },
    {
      "x": -1,
      "y": -2,
      "z": -1,
      "name": "Rock_Basalt"
    },
    {
      "x": -1,
      "y": -1,
      "z": -1,
      "name": "Soil_Grass"
    },
    {
      "x": -1,
      "y": -7,
      "z": 0,
      "name": "Rock_Basalt"
    },
    {
      "x": -1,
      "y": -6,
      "z": 0,
      "name": "Rock_Basalt"
    },
    {
      "x": -1,
      "y": -5,
      "z": 0,
      "name": "Rock_Basalt"
    },
    {
      "x": -1,
      "y": -4,
      "z": 0,
      "name": "Rock_Basalt"
    },
    {
      "x": -1,
      "y": -3,
      "z": 0,
      "name": "Rock_Basalt"
    },
    {
      "x": -1,
      "y": -2,
      "z": 0,
      "name": "Rock_Basalt"
    },
    {
      "x": -1,
      "y": -1,
      "z": 0,
      "name": "Soil_Grass"
    },
    {
      "x": -1,
      "y": -7,
      "z": 1,
      "name": "Rock_Basalt"
    },
    {
      "x": -1,
      "y": -6,
      "z": 1,
      "name": "Rock_Basalt"
    },
    {
      "x": -1,
      "y": -5,
      "z": 1,
      "name": "Rock_Basalt"
    },
    {
      "x": -1,
      "y": -4,
      "z": 1,
      "name": "Rock_Basalt"
    },
    {
      "x": -1,
      "y": -3,
      "z": 1,
      "name": "Rock_Basalt"
    },
    {
      "x": -1,
      "y": -2,
      "z": 1,
      "name": "Rock_Basalt"
    },
    {
      "x": -1,
      "y": -1,
      "z": 1,
      "name": "Soil_Pathway"
    },
    {
      "x": -1,
      "y": -7,
      "z": 2,
      "name": "Rock_Basalt"
    },
    {
      "x": -1,
      "y": -6,
      "z": 2,
      "name": "Rock_Basalt"
    },
    {
      "x": -1,
      "y": -5,
      "z": 2,
      "name": "Rock_Basalt"
    },
    {
      "x": -1,
      "y": -4,
      "z": 2,
      "name": "Rock_Basalt"
    },
    {
      "x": -1,
      "y": -3,
      "z": 2,
      "name": "Rock_Basalt"
    },
    {
      "x": -1,
      "y": -2,
      "z": 2,
      "name": "Rock_Basalt"
    },
    {
      "x": -1,
      "y": -1,
      "z": 2,
      "name": "Soil_Pathway"
    },
    {
      "x": -1,
      "y": -7,
      "z": 3,
      "name": "Rock_Basalt"
    },
    {
      "x": -1,
      "y": -6,
      "z": 3,
      "name": "Rock_Basalt"
    },
    {
      "x": -1,
      "y": -5,
      "z": 3,
      "name": "Rock_Basalt"
    },
    {
      "x": -1,
      "y": -4,
      "z": 3,
      "name": "Rock_Basalt"
    },
    {
      "x": -1,
      "y": -3,
      "z": 3,
      "name": "Rock_Basalt"
    },
    {
      "x": -1,
      "y": -1,
      "z": 3,
      "name": "Soil_Grass"
    },
    {
      "x": -1,
      "y": -7,
      "z": 4,
      "name": "Rock_Basalt"
    },
    {
      "x": -1,
      "y": -1,
      "z": 4,
      "name": "Soil_Pathway"
    },
    {
      "x": 0,
      "y": -1,
      "z": -7,
      "name": "Soil_Grass"
    },
    {
      "x": 0,
      "y": 0,
      "z": -7,
      "name": "Wood_Softwood_Beam"
    },
    {
      "x": 0,
      "y": 1,
      "z": -7,
      "name": "Wood_Softwood_Beam"
    },
    {
      "x": 0,
      "y": 2,
      "z": -7,
      "name": "Cloth_Roof_Hide_Flat"
    },
    {
      "x": 0,
      "y": -1,
      "z": -6,
      "name": "Soil_Grass"
    },
    {
      "x": 0,
      "y": 0,
      "z": -6,
      "name": "Plant_Moss_Rug_Green"
    },
    {
      "x": 0,
      "y": 1,
      "z": -6,
      "name": "Plant_Moss_Cave_Green",
      "rotation": 8
    },
    {
      "x": 0,
      "y": 2,
      "z": -6,
      "name": "Cloth_Roof_Hide_Flat"
    },
    {
      "x": 0,
      "y": -4,
      "z": -5,
      "name": "Rock_Basalt"
    },
    {
      "x": 0,
      "y": -3,
      "z": -5,
      "name": "Rock_Basalt"
    },
    {
      "x": 0,
      "y": -2,
      "z": -5,
      "name": "Rock_Basalt"
    },
    {
      "x": 0,
      "y": -1,
      "z": -5,
      "name": "Soil_Grass"
    },
    {
      "x": 0,
      "y": 0,
      "z": -5,
      "name": "Plant_Moss_Rug_Green"
    },
    {
      "x": 0,
      "y": 2,
      "z": -5,
      "name": "Cloth_Roof_Hide_Flat"
    },
    {
      "x": 0,
      "y": -5,
      "z": -4,
      "name": "Rock_Basalt"
    },
    {
      "x": 0,
      "y": -4,
      "z": -4,
      "name": "Rock_Basalt"
    },
    {
      "x": 0,
      "y": -3,
      "z": -4,
      "name": "Rock_Basalt"
    },
    {
      "x": 0,
      "y": -2,
      "z": -4,
      "name": "Rock_Basalt"
    },
    {
      "x": 0,
      "y": -1,
      "z": -4,
      "name": "Soil_Grass"
    },
    {
      "x": 0,
      "y": 2,
      "z": -4,
      "name": "Cloth_Roof_Hide_Flat"
    },
    {
      "x": 0,
      "y": -7,
      "z": -3,
      "name": "Rock_Basalt"
    },
    {
      "x": 0,
      "y": -6,
      "z": -3,
      "name": "Rock_Basalt"
    },
    {
      "x": 0,
      "y": -5,
      "z": -3,
      "name": "Rock_Basalt"
    },
    {
      "x": 0,
      "y": -4,
      "z": -3,
      "name": "Rock_Basalt"
    },
    {
      "x": 0,
      "y": -3,
      "z": -3,
      "name": "Rock_Basalt"
    },
    {
      "x": 0,
      "y": -2,
      "z": -3,
      "name": "Rock_Basalt"
    },
    {
      "x": 0,
      "y": -1,
      "z": -3,
      "name": "Soil_Pathway"
    },
    {
      "x": 0,
      "y": -7,
      "z": -2,
      "name": "Rock_Basalt"
    },
    {
      "x": 0,
      "y": -6,
      "z": -2,
      "name": "Rock_Basalt"
    },
    {
      "x": 0,
      "y": -5,
      "z": -2,
      "name": "Rock_Basalt"
    },
    {
      "x": 0,
      "y": -4,
      "z": -2,
      "name": "Rock_Basalt"
    },
    {
      "x": 0,
      "y": -3,
      "z": -2,
      "name": "Rock_Basalt"
    },
    {
      "x": 0,
      "y": -2,
      "z": -2,
      "name": "Rock_Basalt"
    },
    {
      "x": 0,
      "y": -1,
      "z": -2,
      "name": "Soil_Pathway"
    },
    {
      "x": 0,
      "y": -7,
      "z": -1,
      "name": "Rock_Basalt"
    },
    {
      "x": 0,
      "y": -6,
      "z": -1,
      "name": "Rock_Basalt"
    },
    {
      "x": 0,
      "y": -5,
      "z": -1,
      "name": "Rock_Basalt"
    },
    {
      "x": 0,
      "y": -4,
      "z": -1,
      "name": "Rock_Basalt"
    },
    {
      "x": 0,
      "y": -3,
      "z": -1,
      "name": "Rock_Basalt"
    },
    {
      "x": 0,
      "y": -2,
      "z": -1,
      "name": "Rock_Basalt"
    },
    {
      "x": 0,
      "y": -1,
      "z": -1,
      "name": "Soil_Grass"
    },
    {
      "x": 0,
      "y": -7,
      "z": 0,
      "name": "Rock_Basalt"
    },
    {
      "x": 0,
      "y": -6,
      "z": 0,
      "name": "Rock_Basalt"
    },
    {
      "x": 0,
      "y": -5,
      "z": 0,
      "name": "Rock_Basalt"
    },
    {
      "x": 0,
      "y": -4,
      "z": 0,
      "name": "Rock_Basalt"
    },
    {
      "x": 0,
      "y": -3,
      "z": 0,
      "name": "Rock_Basalt"
    },
    {
      "x": 0,
      "y": -2,
      "z": 0,
      "name": "Rock_Basalt"
    },
    {
      "x": 0,
      "y": -1,
      "z": 0,
      "name": "Soil_Grass"
    },
    {
      "x": 0,
      "y": -7,
      "z": 1,
      "name": "Rock_Basalt"
    },
    {
      "x": 0,
      "y": -6,
      "z": 1,
      "name": "Rock_Basalt"
    },
    {
      "x": 0,
      "y": -5,
      "z": 1,
      "name": "Rock_Basalt"
    },
    {
      "x": 0,
      "y": -4,
      "z": 1,
      "name": "Rock_Basalt"
    },
    {
      "x": 0,
      "y": -3,
      "z": 1,
      "name": "Rock_Basalt"
    },
    {
      "x": 0,
      "y": -2,
      "z": 1,
      "name": "Rock_Basalt"
    },
    {
      "x": 0,
      "y": -1,
      "z": 1,
      "name": "Soil_Dirt"
    },
    {
      "x": 0,
      "y": 0,
      "z": 1,
      "name": "Bench_Campfire",
      "components": {
        "Components": {
          "BenchBlock": {
            "TierLevel": 1,
            "UpgradeItems": []
          },
          "ProcessingBenchBlock": {
            "InputContainer": {
              "Id": "Simple",
              "Capacity": 2,
              "Items": {}
            },
            "FuelContainer": {
              "Id": "Simple",
              "Capacity": 1,
              "Items": {}
            },
            "OutputContainer": {
              "Id": "Simple",
              "Capacity": 4,
              "Items": {}
            },
            "Progress": 0.0,
            "FuelTime": 0.0,
            "Active": false,
            "NextExtra": 4,
            "LastTickGameTime": "0001-01-01T12:00:00Z"
          }
        }
      }
    },
    {
      "x": 0,
      "y": -7,
      "z": 2,
      "name": "Rock_Basalt"
    },
    {
      "x": 0,
      "y": -6,
      "z": 2,
      "name": "Rock_Basalt"
    },
    {
      "x": 0,
      "y": -5,
      "z": 2,
      "name": "Rock_Basalt"
    },
    {
      "x": 0,
      "y": -4,
      "z": 2,
      "name": "Rock_Basalt"
    },
    {
      "x": 0,
      "y": -3,
      "z": 2,
      "name": "Rock_Basalt"
    },
    {
      "x": 0,
      "y": -2,
      "z": 2,
      "name": "Rock_Basalt"
    },
    {
      "x": 0,
      "y": -1,
      "z": 2,
      "name": "Soil_Grass"
    },
    {
      "x": 0,
      "y": -7,
      "z": 3,
      "name": "Rock_Basalt"
    },
    {
      "x": 0,
      "y": -6,
      "z": 3,
      "name": "Rock_Basalt"
    },
    {
      "x": 0,
      "y": -5,
      "z": 3,
      "name": "Rock_Basalt"
    },
    {
      "x": 0,
      "y": -4,
      "z": 3,
      "name": "Rock_Basalt"
    },
    {
      "x": 0,
      "y": -1,
      "z": 3,
      "name": "Soil_Grass"
    },
    {
      "x": 0,
      "y": 0,
      "z": 3,
      "name": "Plant_Grass_Sharp_Short"
    },
    {
      "x": 0,
      "y": -1,
      "z": 4,
      "name": "Soil_Grass"
    },
    {
      "x": 1,
      "y": -1,
      "z": -7,
      "name": "Soil_Grass"
    },
    {
      "x": 1,
      "y": 1,
      "z": -7,
      "name": "Cloth_Roof_Hide",
      "rotation": 1
    },
    {
      "x": 1,
      "y": -4,
      "z": -6,
      "name": "Rock_Basalt"
    },
    {
      "x": 1,
      "y": -3,
      "z": -6,
      "name": "Rock_Basalt"
    },
    {
      "x": 1,
      "y": -2,
      "z": -6,
      "name": "Rock_Basalt"
    },
    {
      "x": 1,
      "y": -1,
      "z": -6,
      "name": "Soil_Grass"
    },
    {
      "x": 1,
      "y": 0,
      "z": -6,
      "name": "Furniture_Tavern_Barrel"
    },
    {
      "x": 1,
      "y": 1,
      "z": -6,
      "name": "Cloth_Roof_Hide",
      "rotation": 1
    },
    {
      "x": 1,
      "y": -6,
      "z": -5,
      "name": "Rock_Basalt"
    },
    {
      "x": 1,
      "y": -5,
      "z": -5,
      "name": "Rock_Basalt"
    },
    {
      "x": 1,
      "y": -4,
      "z": -5,
      "name": "Rock_Basalt"
    },
    {
      "x": 1,
      "y": -3,
      "z": -5,
      "name": "Rock_Basalt"
    },
    {
      "x": 1,
      "y": -2,
      "z": -5,
      "name": "Rock_Basalt"
    },
    {
      "x": 1,
      "y": -1,
      "z": -5,
      "name": "Soil_Grass"
    },
    {
      "x": 1,
      "y": 0,
      "z": -5,
      "name": "Furniture_Crude_Bed",
      "components": {
        "Components": {
          "PlacedByInteraction": {
            "WhoPlacedUuid": {
              "$binary": "5RPZJ2uQSJ2g+KZxfjqR+g==",
              "$type": "04"
            }
          },
          "RespawnBlock": {}
        }
      }
    },
    {
      "x": 1,
      "y": 1,
      "z": -5,
      "name": "Cloth_Roof_Hide",
      "rotation": 1
    },
    {
      "x": 1,
      "y": -7,
      "z": -4,
      "name": "Rock_Basalt"
    },
    {
      "x": 1,
      "y": -6,
      "z": -4,
      "name": "Rock_Basalt"
    },
    {
      "x": 1,
      "y": -5,
      "z": -4,
      "name": "Rock_Basalt"
    },
    {
      "x": 1,
      "y": -4,
      "z": -4,
      "name": "Rock_Basalt"
    },
    {
      "x": 1,
      "y": -3,
      "z": -4,
      "name": "Rock_Basalt"
    },
    {
      "x": 1,
      "y": -2,
      "z": -4,
      "name": "Rock_Basalt"
    },
    {
      "x": 1,
      "y": -1,
      "z": -4,
      "name": "Soil_Grass"
    },
    {
      "x": 1,
      "y": 0,
      "z": -4,
      "name": "Furniture_Crude_Bed",
      "filler": 32
    },
    {
      "x": 1,
      "y": 1,
      "z": -4,
      "name": "Cloth_Roof_Hide",
      "rotation": 1
    },
    {
      "x": 1,
      "y": -7,
      "z": -3,
      "name": "Rock_Basalt"
    },
    {
      "x": 1,
      "y": -6,
      "z": -3,
      "name": "Rock_Basalt"
    },
    {
      "x": 1,
      "y": -5,
      "z": -3,
      "name": "Rock_Basalt"
    },
    {
      "x": 1,
      "y": -4,
      "z": -3,
      "name": "Rock_Basalt"
    },
    {
      "x": 1,
      "y": -3,
      "z": -3,
      "name": "Rock_Basalt"
    },
    {
      "x": 1,
      "y": -2,
      "z": -3,
      "name": "Rock_Basalt"
    },
    {
      "x": 1,
      "y": -1,
      "z": -3,
      "name": "Soil_Pathway"
    },
    {
      "x": 1,
      "y": -7,
      "z": -2,
      "name": "Rock_Basalt"
    },
    {
      "x": 1,
      "y": -6,
      "z": -2,
      "name": "Rock_Basalt"
    },
    {
      "x": 1,
      "y": -5,
      "z": -2,
      "name": "Rock_Basalt"
    },
    {
      "x": 1,
      "y": -4,
      "z": -2,
      "name": "Rock_Basalt"
    },
    {
      "x": 1,
      "y": -3,
      "z": -2,
      "name": "Rock_Basalt"
    },
    {
      "x": 1,
      "y": -2,
      "z": -2,
      "name": "Rock_Basalt"
    },
    {
      "x": 1,
      "y": -1,
      "z": -2,
      "name": "Soil_Pathway"
    },
    {
      "x": 1,
      "y": -7,
      "z": -1,
      "name": "Rock_Basalt"
    },
    {
      "x": 1,
      "y": -6,
      "z": -1,
      "name": "Rock_Basalt"
    },
    {
      "x": 1,
      "y": -5,
      "z": -1,
      "name": "Rock_Basalt"
    },
    {
      "x": 1,
      "y": -4,
      "z": -1,
      "name": "Rock_Basalt"
    },
    {
      "x": 1,
      "y": -3,
      "z": -1,
      "name": "Rock_Basalt"
    },
    {
      "x": 1,
      "y": -2,
      "z": -1,
      "name": "Block_Spawner_Block",
      "components": {
        "Components": {
          "PlacedByInteraction": {
            "WhoPlacedUuid": {
              "$binary": "5RPZJ2uQSJ2g+KZxfjqR+g==",
              "$type": "04"
            }
          },
          "BlockSpawner": {
            "BlockSpawnerId": "Thunderstorm_Tier1"
          }
        }
      },
      "rotation": 3
    },
    {
      "x": 1,
      "y": -1,
      "z": -1,
      "name": "Soil_Dirt_Dry"
    },
    {
      "x": 1,
      "y": -7,
      "z": 0,
      "name": "Rock_Basalt"
    },
    {
      "x": 1,
      "y": -6,
      "z": 0,
      "name": "Rock_Basalt"
    },
    {
      "x": 1,
      "y": -5,
      "z": 0,
      "name": "Rock_Basalt"
    },
    {
      "x": 1,
      "y": -4,
      "z": 0,
      "name": "Rock_Basalt"
    },
    {
      "x": 1,
      "y": -3,
      "z": 0,
      "name": "Rock_Basalt"
    },
    {
      "x": 1,
      "y": -2,
      "z": 0,
      "name": "Rock_Basalt"
    },
    {
      "x": 1,
      "y": -1,
      "z": 0,
      "name": "Soil_Grass"
    },
    {
      "x": 1,
      "y": -7,
      "z": 1,
      "name": "Rock_Basalt"
    },
    {
      "x": 1,
      "y": -6,
      "z": 1,
      "name": "Rock_Basalt"
    },
    {
      "x": 1,
      "y": -5,
      "z": 1,
      "name": "Rock_Basalt"
    },
    {
      "x": 1,
      "y": -4,
      "z": 1,
      "name": "Rock_Basalt"
    },
    {
      "x": 1,
      "y": -3,
      "z": 1,
      "name": "Rock_Basalt"
    },
    {
      "x": 1,
      "y": -2,
      "z": 1,
      "name": "Rock_Basalt"
    },
    {
      "x": 1,
      "y": -1,
      "z": 1,
      "name": "Soil_Grass"
    },
    {
      "x": 1,
      "y": -7,
      "z": 2,
      "name": "Rock_Basalt"
    },
    {
      "x": 1,
      "y": -6,
      "z": 2,
      "name": "Rock_Basalt"
    },
    {
      "x": 1,
      "y": -5,
      "z": 2,
      "name": "Rock_Basalt"
    },
    {
      "x": 1,
      "y": -4,
      "z": 2,
      "name": "Rock_Basalt"
    },
    {
      "x": 1,
      "y": -3,
      "z": 2,
      "name": "Rock_Basalt"
    },
    {
      "x": 1,
      "y": -2,
      "z": 2,
      "name": "Rock_Basalt"
    },
    {
      "x": 1,
      "y": -1,
      "z": 2,
      "name": "Soil_Grass"
    },
    {
      "x": 1,
      "y": -6,
      "z": 3,
      "name": "Rock_Basalt"
    },
    {
      "x": 1,
      "y": -5,
      "z": 3,
      "name": "Rock_Basalt"
    },
    {
      "x": 1,
      "y": -4,
      "z": 3,
      "name": "Rock_Basalt"
    },
    {
      "x": 1,
      "y": -1,
      "z": 3,
      "name": "Soil_Pathway"
    },
    {
      "x": 1,
      "y": -1,
      "z": 4,
      "name": "Soil_Grass"
    },
    {
      "x": 2,
      "y": -1,
      "z": -7,
      "name": "Soil_Grass"
    },
    {
      "x": 2,
      "y": 0,
      "z": -7,
      "name": "Cloth_Roof_Hide",
      "rotation": 1
    },
    {
      "x": 2,
      "y": -5,
      "z": -6,
      "name": "Rock_Basalt"
    },
    {
      "x": 2,
      "y": -4,
      "z": -6,
      "name": "Rock_Basalt"
    },
    {
      "x": 2,
      "y": -3,
      "z": -6,
      "name": "Rock_Basalt"
    },
    {
      "x": 2,
      "y": -2,
      "z": -6,
      "name": "Rock_Basalt"
    },
    {
      "x": 2,
      "y": -1,
      "z": -6,
      "name": "Soil_Grass"
    },
    {
      "x": 2,
      "y": 0,
      "z": -6,
      "name": "Cloth_Roof_Hide",
      "rotation": 1
    },
    {
      "x": 2,
      "y": -6,
      "z": -5,
      "name": "Rock_Basalt"
    },
    {
      "x": 2,
      "y": -5,
      "z": -5,
      "name": "Rock_Basalt"
    },
    {
      "x": 2,
      "y": -4,
      "z": -5,
      "name": "Rock_Basalt"
    },
    {
      "x": 2,
      "y": -3,
      "z": -5,
      "name": "Rock_Basalt"
    },
    {
      "x": 2,
      "y": -2,
      "z": -5,
      "name": "Rock_Basalt"
    },
    {
      "x": 2,
      "y": -1,
      "z": -5,
      "name": "Soil_Grass"
    },
    {
      "x": 2,
      "y": 0,
      "z": -5,
      "name": "Cloth_Roof_Hide",
      "rotation": 1
    },
    {
      "x": 2,
      "y": -7,
      "z": -4,
      "name": "Rock_Basalt"
    },
    {
      "x": 2,
      "y": -6,
      "z": -4,
      "name": "Rock_Basalt"
    },
    {
      "x": 2,
      "y": -5,
      "z": -4,
      "name": "Rock_Basalt"
    },
    {
      "x": 2,
      "y": -4,
      "z": -4,
      "name": "Rock_Basalt"
    },
    {
      "x": 2,
      "y": -3,
      "z": -4,
      "name": "Rock_Basalt"
    },
    {
      "x": 2,
      "y": -2,
      "z": -4,
      "name": "Rock_Basalt"
    },
    {
      "x": 2,
      "y": -1,
      "z": -4,
      "name": "Soil_Grass"
    },
    {
      "x": 2,
      "y": 0,
      "z": -4,
      "name": "Cloth_Roof_Hide",
      "rotation": 1
    },
    {
      "x": 2,
      "y": -7,
      "z": -3,
      "name": "Rock_Basalt"
    },
    {
      "x": 2,
      "y": -6,
      "z": -3,
      "name": "Rock_Basalt"
    },
    {
      "x": 2,
      "y": -5,
      "z": -3,
      "name": "Rock_Basalt"
    },
    {
      "x": 2,
      "y": -4,
      "z": -3,
      "name": "Rock_Basalt"
    },
    {
      "x": 2,
      "y": -3,
      "z": -3,
      "name": "Rock_Basalt"
    },
    {
      "x": 2,
      "y": -2,
      "z": -3,
      "name": "Rock_Basalt"
    },
    {
      "x": 2,
      "y": -1,
      "z": -3,
      "name": "Soil_Grass"
    },
    {
      "x": 2,
      "y": -7,
      "z": -2,
      "name": "Rock_Basalt"
    },
    {
      "x": 2,
      "y": -6,
      "z": -2,
      "name": "Rock_Basalt"
    },
    {
      "x": 2,
      "y": -5,
      "z": -2,
      "name": "Rock_Basalt"
    },
    {
      "x": 2,
      "y": -4,
      "z": -2,
      "name": "Rock_Basalt"
    },
    {
      "x": 2,
      "y": -3,
      "z": -2,
      "name": "Rock_Basalt"
    },
    {
      "x": 2,
      "y": -2,
      "z": -2,
      "name": "Rock_Basalt"
    },
    {
      "x": 2,
      "y": -1,
      "z": -2,
      "name": "Soil_Grass"
    },
    {
      "x": 2,
      "y": -7,
      "z": -1,
      "name": "Rock_Basalt"
    },
    {
      "x": 2,
      "y": -6,
      "z": -1,
      "name": "Rock_Basalt"
    },
    {
      "x": 2,
      "y": -5,
      "z": -1,
      "name": "Rock_Basalt"
    },
    {
      "x": 2,
      "y": -4,
      "z": -1,
      "name": "Rock_Basalt"
    },
    {
      "x": 2,
      "y": -3,
      "z": -1,
      "name": "Rock_Basalt"
    },
    {
      "x": 2,
      "y": -2,
      "z": -1,
      "name": "Rock_Basalt"
    },
    {
      "x": 2,
      "y": -1,
      "z": -1,
      "name": "Soil_Grass"
    },
    {
      "x": 2,
      "y": 0,
      "z": -1,
      "name": "Cloth_Roof_Hide",
      "rotation": 2
    },
    {
      "x": 2,
      "y": -6,
      "z": 0,
      "name": "Rock_Basalt"
    },
    {
      "x": 2,
      "y": -5,
      "z": 0,
      "name": "Rock_Basalt"
    },
    {
      "x": 2,
      "y": -4,
      "z": 0,
      "name": "Rock_Basalt"
    },
    {
      "x": 2,
      "y": -3,
      "z": 0,
      "name": "Rock_Basalt"
    },
    {
      "x": 2,
      "y": -2,
      "z": 0,
      "name": "Rock_Basalt"
    },
    {
      "x": 2,
      "y": -1,
      "z": 0,
      "name": "Soil_Grass"
    },
    {
      "x": 2,
      "y": 0,
      "z": 0,
      "name": "Furniture_Crude_Bed",
      "filler": 31,
      "rotation": 3
    },
    {
      "x": 2,
      "y": 1,
      "z": 0,
      "name": "Cloth_Roof_Hide",
      "rotation": 2
    },
    {
      "x": 2,
      "y": -7,
      "z": 1,
      "name": "Rock_Basalt"
    },
    {
      "x": 2,
      "y": -6,
      "z": 1,
      "name": "Rock_Basalt"
    },
    {
      "x": 2,
      "y": -5,
      "z": 1,
      "name": "Rock_Basalt"
    },
    {
      "x": 2,
      "y": -4,
      "z": 1,
      "name": "Rock_Basalt"
    },
    {
      "x": 2,
      "y": -3,
      "z": 1,
      "name": "Rock_Basalt"
    },
    {
      "x": 2,
      "y": -2,
      "z": 1,
      "name": "Rock_Basalt"
    },
    {
      "x": 2,
      "y": -1,
      "z": 1,
      "name": "Soil_Grass"
    },
    {
      "x": 2,
      "y": 2,
      "z": 1,
      "name": "Cloth_Roof_Hide_Flat"
    },
    {
      "x": 2,
      "y": -6,
      "z": 2,
      "name": "Rock_Basalt"
    },
    {
      "x": 2,
      "y": -5,
      "z": 2,
      "name": "Rock_Basalt"
    },
    {
      "x": 2,
      "y": -4,
      "z": 2,
      "name": "Rock_Basalt"
    },
    {
      "x": 2,
      "y": -1,
      "z": 2,
      "name": "Soil_Pathway"
    },
    {
      "x": 2,
      "y": 0,
      "z": 2,
      "name": "Furniture_Crude_Bed",
      "filler": 31,
      "rotation": 3
    },
    {
      "x": 2,
      "y": 1,
      "z": 2,
      "name": "Cloth_Roof_Hide"
    },
    {
      "x": 2,
      "y": -1,
      "z": 3,
      "name": "Soil_Pathway"
    },
    {
      "x": 2,
      "y": 0,
      "z": 3,
      "name": "Cloth_Roof_Hide"
    },
    {
      "x": 3,
      "y": -4,
      "z": -6,
      "name": "Rock_Basalt"
    },
    {
      "x": 3,
      "y": -3,
      "z": -6,
      "name": "Rock_Basalt"
    },
    {
      "x": 3,
      "y": -2,
      "z": -6,
      "name": "Rock_Basalt"
    },
    {
      "x": 3,
      "y": -6,
      "z": -5,
      "name": "Rock_Basalt"
    },
    {
      "x": 3,
      "y": -5,
      "z": -5,
      "name": "Rock_Basalt"
    },
    {
      "x": 3,
      "y": -4,
      "z": -5,
      "name": "Rock_Basalt"
    },
    {
      "x": 3,
      "y": -3,
      "z": -5,
      "name": "Rock_Basalt"
    },
    {
      "x": 3,
      "y": -2,
      "z": -5,
      "name": "Rock_Basalt"
    },
    {
      "x": 3,
      "y": -1,
      "z": -5,
      "name": "Soil_Grass"
    },
    {
      "x": 3,
      "y": 0,
      "z": -5,
      "name": "Plant_Grass_Lush_Tall"
    },
    {
      "x": 3,
      "y": -7,
      "z": -4,
      "name": "Rock_Basalt"
    },
    {
      "x": 3,
      "y": -6,
      "z": -4,
      "name": "Rock_Basalt"
    },
    {
      "x": 3,
      "y": -5,
      "z": -4,
      "name": "Rock_Basalt"
    },
    {
      "x": 3,
      "y": -4,
      "z": -4,
      "name": "Rock_Basalt"
    },
    {
      "x": 3,
      "y": -3,
      "z": -4,
      "name": "Rock_Basalt"
    },
    {
      "x": 3,
      "y": -2,
      "z": -4,
      "name": "Rock_Basalt"
    },
    {
      "x": 3,
      "y": -1,
      "z": -4,
      "name": "Soil_Grass"
    },
    {
      "x": 3,
      "y": 0,
      "z": -4,
      "name": "Plant_Grass_Lush_Tall"
    },
    {
      "x": 3,
      "y": -7,
      "z": -3,
      "name": "Rock_Basalt"
    },
    {
      "x": 3,
      "y": -6,
      "z": -3,
      "name": "Rock_Basalt"
    },
    {
      "x": 3,
      "y": -5,
      "z": -3,
      "name": "Rock_Basalt"
    },
    {
      "x": 3,
      "y": -4,
      "z": -3,
      "name": "Rock_Basalt"
    },
    {
      "x": 3,
      "y": -3,
      "z": -3,
      "name": "Rock_Basalt"
    },
    {
      "x": 3,
      "y": -2,
      "z": -3,
      "name": "Rock_Basalt"
    },
    {
      "x": 3,
      "y": -1,
      "z": -3,
      "name": "Soil_Grass"
    },
    {
      "x": 3,
      "y": -7,
      "z": -2,
      "name": "Rock_Basalt"
    },
    {
      "x": 3,
      "y": -6,
      "z": -2,
      "name": "Rock_Basalt"
    },
    {
      "x": 3,
      "y": -5,
      "z": -2,
      "name": "Rock_Basalt"
    },
    {
      "x": 3,
      "y": -4,
      "z": -2,
      "name": "Rock_Basalt"
    },
    {
      "x": 3,
      "y": -3,
      "z": -2,
      "name": "Rock_Basalt"
    },
    {
      "x": 3,
      "y": -2,
      "z": -2,
      "name": "Rock_Basalt"
    },
    {
      "x": 3,
      "y": -1,
      "z": -2,
      "name": "Soil_Grass"
    },
    {
      "x": 3,
      "y": 0,
      "z": -2,
      "name": "Deco_Bone_Skulls"
    },
    {
      "x": 3,
      "y": -6,
      "z": -1,
      "name": "Rock_Basalt"
    },
    {
      "x": 3,
      "y": -5,
      "z": -1,
      "name": "Rock_Basalt"
    },
    {
      "x": 3,
      "y": -4,
      "z": -1,
      "name": "Rock_Basalt"
    },
    {
      "x": 3,
      "y": -3,
      "z": -1,
      "name": "Rock_Basalt"
    },
    {
      "x": 3,
      "y": -2,
      "z": -1,
      "name": "Rock_Basalt"
    },
    {
      "x": 3,
      "y": -1,
      "z": -1,
      "name": "Soil_Grass"
    },
    {
      "x": 3,
      "y": 0,
      "z": -1,
      "name": "Cloth_Roof_Hide",
      "rotation": 2
    },
    {
      "x": 3,
      "y": -6,
      "z": 0,
      "name": "Rock_Basalt"
    },
    {
      "x": 3,
      "y": -5,
      "z": 0,
      "name": "Rock_Basalt"
    },
    {
      "x": 3,
      "y": -4,
      "z": 0,
      "name": "Rock_Basalt"
    },
    {
      "x": 3,
      "y": -3,
      "z": 0,
      "name": "Rock_Basalt"
    },
    {
      "x": 3,
      "y": -2,
      "z": 0,
      "name": "Rock_Basalt"
    },
    {
      "x": 3,
      "y": -1,
      "z": 0,
      "name": "Soil_Grass"
    },
    {
      "x": 3,
      "y": 0,
      "z": 0,
      "name": "Furniture_Crude_Bed",
      "components": {
        "Components": {
          "PlacedByInteraction": {
            "WhoPlacedUuid": {
              "$binary": "5RPZJ2uQSJ2g+KZxfjqR+g==",
              "$type": "04"
            }
          },
          "RespawnBlock": {}
        }
      },
      "rotation": 3
    },
    {
      "x": 3,
      "y": 1,
      "z": 0,
      "name": "Cloth_Roof_Hide",
      "rotation": 2
    },
    {
      "x": 3,
      "y": -5,
      "z": 1,
      "name": "Rock_Basalt"
    },
    {
      "x": 3,
      "y": -4,
      "z": 1,
      "name": "Rock_Basalt"
    },
    {
      "x": 3,
      "y": -2,
      "z": 1,
      "name": "Rock_Basalt"
    },
    {
      "x": 3,
      "y": -1,
      "z": 1,
      "name": "Soil_Pathway"
    },
    {
      "x": 3,
      "y": 2,
      "z": 1,
      "name": "Cloth_Roof_Hide_Flat"
    },
    {
      "x": 3,
      "y": -1,
      "z": 2,
      "name": "Soil_Grass"
    },
    {
      "x": 3,
      "y": 0,
      "z": 2,
      "name": "Furniture_Crude_Bed",
      "components": {
        "Components": {
          "PlacedByInteraction": {
            "WhoPlacedUuid": {
              "$binary": "5RPZJ2uQSJ2g+KZxfjqR+g==",
              "$type": "04"
            }
          },
          "RespawnBlock": {}
        }
      },
      "rotation": 3
    },
    {
      "x": 3,
      "y": 1,
      "z": 2,
      "name": "Cloth_Roof_Hide"
    },
    {
      "x": 3,
      "y": -1,
      "z": 3,
      "name": "Soil_Pathway"
    },
    {
      "x": 3,
      "y": 0,
      "z": 3,
      "name": "Cloth_Roof_Hide"
    },
    {
      "x": 4,
      "y": -5,
      "z": -5,
      "name": "Rock_Basalt"
    },
    {
      "x": 4,
      "y": -4,
      "z": -5,
      "name": "Rock_Basalt"
    },
    {
      "x": 4,
      "y": -3,
      "z": -5,
      "name": "Rock_Basalt"
    },
    {
      "x": 4,
      "y": -2,
      "z": -5,
      "name": "Rock_Basalt"
    },
    {
      "x": 4,
      "y": -7,
      "z": -4,
      "name": "Rock_Basalt"
    },
    {
      "x": 4,
      "y": -6,
      "z": -4,
      "name": "Rock_Basalt"
    },
    {
      "x": 4,
      "y": -5,
      "z": -4,
      "name": "Rock_Basalt"
    },
    {
      "x": 4,
      "y": -4,
      "z": -4,
      "name": "Rock_Basalt"
    },
    {
      "x": 4,
      "y": -3,
      "z": -4,
      "name": "Rock_Basalt"
    },
    {
      "x": 4,
      "y": -2,
      "z": -4,
      "name": "Rock_Basalt"
    },
    {
      "x": 4,
      "y": -1,
      "z": -4,
      "name": "Soil_Grass"
    },
    {
      "x": 4,
      "y": -7,
      "z": -3,
      "name": "Rock_Basalt"
    },
    {
      "x": 4,
      "y": -6,
      "z": -3,
      "name": "Rock_Basalt"
    },
    {
      "x": 4,
      "y": -5,
      "z": -3,
      "name": "Rock_Basalt"
    },
    {
      "x": 4,
      "y": -4,
      "z": -3,
      "name": "Rock_Basalt"
    },
    {
      "x": 4,
      "y": -3,
      "z": -3,
      "name": "Rock_Basalt"
    },
    {
      "x": 4,
      "y": -2,
      "z": -3,
      "name": "Rock_Basalt"
    },
    {
      "x": 4,
      "y": -1,
      "z": -3,
      "name": "Soil_Grass"
    },
    {
      "x": 4,
      "y": 0,
      "z": -3,
      "name": "Deco_Bone_Pile"
    },
    {
      "x": 4,
      "y": -7,
      "z": -2,
      "name": "Rock_Basalt"
    },
    {
      "x": 4,
      "y": -6,
      "z": -2,
      "name": "Rock_Basalt"
    },
    {
      "x": 4,
      "y": -5,
      "z": -2,
      "name": "Rock_Basalt"
    },
    {
      "x": 4,
      "y": -4,
      "z": -2,
      "name": "Rock_Basalt"
    },
    {
      "x": 4,
      "y": -3,
      "z": -2,
      "name": "Rock_Basalt"
    },
    {
      "x": 4,
      "y": -2,
      "z": -2,
      "name": "Rock_Basalt"
    },
    {
      "x": 4,
      "y": -1,
      "z": -2,
      "name": "Soil_Grass"
    },
    {
      "x": 4,
      "y": -6,
      "z": -1,
      "name": "Rock_Basalt"
    },
    {
      "x": 4,
      "y": -5,
      "z": -1,
      "name": "Rock_Basalt"
    },
    {
      "x": 4,
      "y": -4,
      "z": -1,
      "name": "Rock_Basalt"
    },
    {
      "x": 4,
      "y": -3,
      "z": -1,
      "name": "Rock_Basalt"
    },
    {
      "x": 4,
      "y": -2,
      "z": -1,
      "name": "Rock_Basalt"
    },
    {
      "x": 4,
      "y": -1,
      "z": -1,
      "name": "Soil_Grass"
    },
    {
      "x": 4,
      "y": 0,
      "z": -1,
      "name": "Cloth_Roof_Hide",
      "rotation": 2
    },
    {
      "x": 4,
      "y": -5,
      "z": 0,
      "name": "Rock_Basalt"
    },
    {
      "x": 4,
      "y": -4,
      "z": 0,
      "name": "Rock_Basalt"
    },
    {
      "x": 4,
      "y": -3,
      "z": 0,
      "name": "Rock_Basalt"
    },
    {
      "x": 4,
      "y": -2,
      "z": 0,
      "name": "Rock_Basalt"
    },
    {
      "x": 4,
      "y": -1,
      "z": 0,
      "name": "Soil_Grass"
    },
    {
      "x": 4,
      "y": -2,
      "z": 1,
      "name": "Rock_Basalt"
    },
    {
      "x": 4,
      "y": -1,
      "z": 1,
      "name": "Soil_Grass"
    },
    {
      "x": 4,
      "y": -1,
      "z": 2,
      "name": "Soil_Grass"
    },
    {
      "x": 4,
      "y": -1,
      "z": 3,
      "name": "Soil_Grass"
    },
    {
      "x": 5,
      "y": -5,
      "z": -4,
      "name": "Rock_Basalt"
    },
    {
      "x": 5,
      "y": -4,
      "z": -4,
      "name": "Rock_Basalt"
    },
    {
      "x": 5,
      "y": -3,
      "z": -4,
      "name": "Rock_Basalt"
    },
    {
      "x": 5,
      "y": -6,
      "z": -3,
      "name": "Rock_Basalt"
    },
    {
      "x": 5,
      "y": -5,
      "z": -3,
      "name": "Rock_Basalt"
    },
    {
      "x": 5,
      "y": -4,
      "z": -3,
      "name": "Rock_Basalt"
    },
    {
      "x": 5,
      "y": -3,
      "z": -3,
      "name": "Rock_Basalt"
    },
    {
      "x": 5,
      "y": -1,
      "z": -3,
      "name": "Soil_Grass"
    },
    {
      "x": 5,
      "y": -5,
      "z": -2,
      "name": "Rock_Basalt"
    },
    {
      "x": 5,
      "y": -4,
      "z": -2,
      "name": "Rock_Basalt"
    },
    {
      "x": 5,
      "y": -3,
      "z": -2,
      "name": "Rock_Basalt"
    },
    {
      "x": 5,
      "y": -2,
      "z": -2,
      "name": "Rock_Basalt"
    },
    {
      "x": 5,
      "y": -1,
      "z": -2,
      "name": "Soil_Grass"
    },
    {
      "x": 5,
      "y": -5,
      "z": -1,
      "name": "Rock_Basalt"
    },
    {
      "x": 5,
      "y": -4,
      "z": -1,
      "name": "Rock_Basalt"
    },
    {
      "x": 5,
      "y": -3,
      "z": -1,
      "name": "Rock_Basalt"
    },
    {
      "x": 5,
      "y": -2,
      "z": -1,
      "name": "Rock_Basalt"
    },
    {
      "x": 5,
      "y": -1,
      "z": -1,
      "name": "Soil_Grass"
    },
    {
      "x": 5,
      "y": -2,
      "z": 0,
      "name": "Rock_Basalt"
    },
    {
      "x": 5,
      "y": -1,
      "z": 0,
      "name": "Soil_Grass"
    },
    {
      "x": 5,
      "y": -1,
      "z": 1,
      "name": "Soil_Grass"
    },
    {
      "x": 5,
      "y": -1,
      "z": 2,
      "name": "Soil_Grass"
    },
    {
      "x": 6,
      "y": -1,
      "z": -1,
      "name": "Soil_Grass"
    },
    {
      "x": 6,
      "y": -1,
      "z": 0,
      "name": "Soil_Grass"
    },
    {
      "x": 6,
      "y": -1,
      "z": 1,
      "name": "Soil_Grass"
    }
  ],
  "entities": [
    {
      "Components": {
        "UtilityInventory": {
          "Inventory": {
            "Id": "Simple",
            "Capacity": 2,
            "Items": {
              "0": {
                "Id": "Furniture_Crude_Torch",
                "Quantity": 1,
                "Durability": 0.0,
                "MaxDurability": 0.0,
                "OverrideDroppedItemAnimation": false
              }
            }
          },
          "ActiveSlot": 0
        },
        "EffectController": {},
        "UIComponentList": {},
        "HotbarInventory": {
          "Inventory": {
            "Id": "Simple",
            "Capacity": 3,
            "Items": {
              "0": {
                "Id": "Weapon_Gun_Blunderbuss_Rusty",
                "Quantity": 1,
                "Durability": 0.0,
                "MaxDurability": 0.0,
                "OverrideDroppedItemAnimation": false
              }
            }
          },
          "ActiveSlot": 0
        },
        "Transform": {
          "Position": {
            "X": -1.5566449165344238,
            "Y": -0.13366317749023438,
            "Z": 0.6330881118774414
          },
          "Rotation": {
            "Pitch": 0.0,
            "Yaw": 2.0915780067443848,
            "Roll": 0.0
          }
        },
        "EntityScale": {
          "Scale": 1.0
        },
        "StorageInventory": {
          "Inventory": {
            "Id": "Empty"
          }
        },
        "Velocity": {
          "Velocity": {
            "X": 0.0,
            "Y": 0.0,
            "Z": 0.0
          }
        },
        "PrefabCopyable": {},
        "Interactions": {
          "Interactions": {
            "Use": "*UseNPC"
          }
        },
        "Model": {
          "Model": {
            "Id": "Skeleton_Burnt_Gunner",
            "Scale": 1.0,
            "Static": false
          }
        },
        "UUID": {
          "UUID": {
            "$binary": "359dsqZ1P5W0zEbekLOt4A==",
            "$type": "04"
          }
        },
        "EntityStats": {
          "Version": 5,
          "Stats": {
            "Oxygen": {
              "Id": "Oxygen",
              "Value": 100.0
            },
            "Mana": {
              "Id": "Mana",
              "Value": 0.0
            },
            "Health": {
              "Id": "Health",
              "Value": 81.0,
              "Modifiers": {
                "NPC_Max": {
                  "Id": "Static",
                  "CalculationType": "Additive",
                  "Amount": -19.0
                }
              }
            },
            "GlidingActive": {
              "Id": "GlidingActive",
              "Value": 0.0
            },
            "Immunity": {
              "Id": "Immunity",
              "Value": 0.0
            },
            "SignatureCharges": {
              "Id": "SignatureCharges",
              "Value": 0.0
            },
            "Stamina": {
              "Id": "Stamina",
              "Value": 10.0
            },
            "Ammo": {
              "Id": "Ammo",
              "Value": 0.0
            },
            "Unknown": {
              "Id": "Unknown",
              "Value": 0.0
            },
            "SignatureEnergy": {
              "Id": "SignatureEnergy",
              "Value": 0.0
            },
            "DeployablePreview": {
              "Id": "DeployablePreview",
              "Value": 0.0
            },
            "StaminaRegenDelay": {
              "Id": "StaminaRegenDelay",
              "Value": 0.0
            },
            "MagicCharges": {
              "Id": "MagicCharges",
              "Value": 0.0
            }
          }
        },
        "NPC": {
          "Version": 5,
          "UUID": {
            "$binary": "359dsqZ1P5W0zEbekLOt4A==",
            "$type": "04"
          },
          "Inventory": {
            "Version": 4,
            "ActiveHotbarSlot": 0,
            "ActiveToolsSlot": -1,
            "ActiveUtilitySlot": -1
          },
          "HvrPhs": 0.0,
          "HvrHght": 0.0,
          "MdlScl": 1.0,
          "SpawnInstant": "0001-01-01T12:00:00Z",
          "WorldgenId": 0,
          "PathManager": {},
          "LeashPos": {
            "X": 7.045734665973651,
            "Y": 56.0,
            "Z": 9.337365353206948
          },
          "LeashHdg": 2.0915780067443848,
          "LeashPtch": 0.0,
          "RoleName": "Skeleton_Burnt_Gunner",
          "ActiveMC": "Walk"
        },
        "ArmorInventory": {
          "Inventory": {
            "Id": "Simple",
            "Capacity": 4,
            "Items": {}
          }
        },
        "HeadRotation": {
          "Rotation": {
            "Pitch": 0.0,
            "Yaw": 2.0915780067443848,
            "Roll": 0.0
          }
        }
      }
    },
    {
      "Components": {
        "UtilityInventory": {
          "Inventory": {
            "Id": "Simple",
            "Capacity": 2,
            "Items": {
              "0": {
                "Id": "Weapon_Shield_Rusty",
                "Quantity": 1,
                "Durability": 0.0,
                "MaxDurability": 0.0,
                "OverrideDroppedItemAnimation": false
              }
            }
          },
          "ActiveSlot": 0
        },
        "EffectController": {},
        "UIComponentList": {},
        "HotbarInventory": {
          "Inventory": {
            "Id": "Simple",
            "Capacity": 3,
            "Items": {
              "0": {
                "Id": "Weapon_Sword_Steel_Rusty",
                "Quantity": 1,
                "Durability": 80.0,
                "MaxDurability": 80.0,
                "OverrideDroppedItemAnimation": false
              }
            }
          },
          "ActiveSlot": 0
        },
        "Transform": {
          "Position": {
            "X": 0.22527647018432617,
            "Y": -0.11925888061523438,
            "Z": 0.7129974365234375
          },
          "Rotation": {
            "Pitch": 0.0,
            "Yaw": 3.096343755722046,
            "Roll": 0.0
          }
        },
        "EntityScale": {
          "Scale": 1.0
        },
        "StorageInventory": {
          "Inventory": {
            "Id": "Empty"
          }
        },
        "Velocity": {
          "Velocity": {
            "X": 0.0,
            "Y": 0.0,
            "Z": 0.0
          }
        },
        "PrefabCopyable": {},
        "Interactions": {
          "Interactions": {
            "Use": "*UseNPC"
          }
        },
        "Model": {
          "Model": {
            "Id": "Skeleton_Burnt_Soldier",
            "Scale": 1.0,
            "Static": false
          }
        },
        "UUID": {
          "UUID": {
            "$binary": "neqzzI9JPpiLVBvPrawnxA==",
            "$type": "04"
          }
        },
        "EntityStats": {
          "Version": 5,
          "Stats": {
            "Oxygen": {
              "Id": "Oxygen",
              "Value": 100.0
            },
            "Mana": {
              "Id": "Mana",
              "Value": 0.0
            },
            "Health": {
              "Id": "Health",
              "Value": 100.0,
              "Modifiers": {
                "NPC_Max": {
                  "Id": "Static",
                  "CalculationType": "Additive",
                  "Amount": 24.0
                }
              }
            },
            "GlidingActive": {
              "Id": "GlidingActive",
              "Value": 0.0
            },
            "Immunity": {
              "Id": "Immunity",
              "Value": 0.0
            },
            "SignatureCharges": {
              "Id": "SignatureCharges",
              "Value": 0.0
            },
            "Stamina": {
              "Id": "Stamina",
              "Value": 10.0
            },
            "Ammo": {
              "Id": "Ammo",
              "Value": 0.0
            },
            "Unknown": {
              "Id": "Unknown",
              "Value": 0.0
            },
            "SignatureEnergy": {
              "Id": "SignatureEnergy",
              "Value": 0.0,
              "Modifiers": {
                "*Weapon_0": {
                  "Id": "Static",
                  "CalculationType": "Additive",
                  "Amount": 20.0
                }
              }
            },
            "DeployablePreview": {
              "Id": "DeployablePreview",
              "Value": 0.0
            },
            "StaminaRegenDelay": {
              "Id": "StaminaRegenDelay",
              "Value": 0.0
            },
            "MagicCharges": {
              "Id": "MagicCharges",
              "Value": 0.0
            }
          }
        },
        "NPC": {
          "Version": 5,
          "UUID": {
            "$binary": "neqzzI9JPpiLVBvPrawnxA==",
            "$type": "04"
          },
          "Inventory": {
            "Version": 4,
            "ActiveHotbarSlot": 0,
            "ActiveToolsSlot": -1,
            "ActiveUtilitySlot": -1
          },
          "HvrPhs": 0.0,
          "HvrHght": 0.0,
          "MdlScl": 1.0,
          "SpawnInstant": "0001-01-01T12:00:00Z",
          "WorldgenId": 0,
          "PathManager": {},
          "LeashPos": {
            "X": 5.347629248976998,
            "Y": 56.0,
            "Z": 8.885068892303863
          },
          "LeashHdg": 3.096343755722046,
          "LeashPtch": 0.0,
          "RoleName": "Skeleton_Burnt_Soldier",
          "ActiveMC": "Walk"
        },
        "ArmorInventory": {
          "Inventory": {
            "Id": "Simple",
            "Capacity": 4,
            "Items": {}
          }
        },
        "HeadRotation": {
          "Rotation": {
            "Pitch": 0.0,
            "Yaw": 3.096343755722046,
            "Roll": 0.0
          }
        }
      }
    },
    {
      "Components": {
        "UtilityInventory": {
          "Inventory": {
            "Id": "Simple",
            "Capacity": 2,
            "Items": {
              "0": {
                "Id": "Weapon_Shield_Rusty",
                "Quantity": 1,
                "Durability": 0.0,
                "MaxDurability": 0.0,
                "OverrideDroppedItemAnimation": false
              }
            }
          },
          "ActiveSlot": 0
        },
        "EffectController": {},
        "UIComponentList": {},
        "HotbarInventory": {
          "Inventory": {
            "Id": "Simple",
            "Capacity": 3,
            "Items": {
              "0": {
                "Id": "Weapon_Sword_Steel_Rusty",
                "Quantity": 1,
                "Durability": 80.0,
                "MaxDurability": 80.0,
                "OverrideDroppedItemAnimation": false
              }
            }
          },
          "ActiveSlot": 0
        },
        "Transform": {
          "Position": {
            "X": 0.8613901138305664,
            "Y": -0.24212265014648438,
            "Z": -2.743764877319336
          },
          "Rotation": {
            "Pitch": 0.0,
            "Yaw": 3.096343755722046,
            "Roll": 0.0
          }
        },
        "EntityScale": {
          "Scale": 1.0
        },
        "StorageInventory": {
          "Inventory": {
            "Id": "Empty"
          }
        },
        "Velocity": {
          "Velocity": {
            "X": 0.0,
            "Y": 0.0,
            "Z": 0.0
          }
        },
        "PrefabCopyable": {},
        "Interactions": {
          "Interactions": {
            "Use": "*UseNPC"
          }
        },
        "Model": {
          "Model": {
            "Id": "Skeleton_Burnt_Soldier",
            "Scale": 1.0,
            "Static": false
          }
        },
        "UUID": {
          "UUID": {
            "$binary": "WkjUDYd3Mtmp8JMq6vfgFw==",
            "$type": "04"
          }
        },
        "EntityStats": {
          "Version": 5,
          "Stats": {
            "Oxygen": {
              "Id": "Oxygen",
              "Value": 100.0
            },
            "Mana": {
              "Id": "Mana",
              "Value": 0.0
            },
            "Health": {
              "Id": "Health",
              "Value": 100.0,
              "Modifiers": {
                "NPC_Max": {
                  "Id": "Static",
                  "CalculationType": "Additive",
                  "Amount": 24.0
                }
              }
            },
            "GlidingActive": {
              "Id": "GlidingActive",
              "Value": 0.0
            },
            "Immunity": {
              "Id": "Immunity",
              "Value": 0.0
            },
            "SignatureCharges": {
              "Id": "SignatureCharges",
              "Value": 0.0
            },
            "Stamina": {
              "Id": "Stamina",
              "Value": 10.0
            },
            "Ammo": {
              "Id": "Ammo",
              "Value": 0.0
            },
            "Unknown": {
              "Id": "Unknown",
              "Value": 0.0
            },
            "SignatureEnergy": {
              "Id": "SignatureEnergy",
              "Value": 0.0,
              "Modifiers": {
                "*Weapon_0": {
                  "Id": "Static",
                  "CalculationType": "Additive",
                  "Amount": 20.0
                }
              }
            },
            "DeployablePreview": {
              "Id": "DeployablePreview",
              "Value": 0.0
            },
            "StaminaRegenDelay": {
              "Id": "StaminaRegenDelay",
              "Value": 0.0
            },
            "MagicCharges": {
              "Id": "MagicCharges",
              "Value": 0.0
            }
          }
        },
        "NPC": {
          "Version": 5,
          "UUID": {
            "$binary": "WkjUDYd3Mtmp8JMq6vfgFw==",
            "$type": "04"
          },
          "Inventory": {
            "Version": 4,
            "ActiveHotbarSlot": 0,
            "ActiveToolsSlot": -1,
            "ActiveUtilitySlot": -1
          },
          "HvrPhs": 0.0,
          "HvrHght": 0.0,
          "MdlScl": 1.0,
          "SpawnInstant": "0001-01-01T12:00:00Z",
          "WorldgenId": 0,
          "PathManager": {},
          "LeashPos": {
            "X": 5.347629248976998,
            "Y": 56.0,
            "Z": 8.885068892303863
          },
          "LeashHdg": 3.096343755722046,
          "LeashPtch": 0.0,
          "RoleName": "Skeleton_Burnt_Soldier",
          "ActiveMC": "Walk"
        },
        "ArmorInventory": {
          "Inventory": {
            "Id": "Simple",
            "Capacity": 4,
            "Items": {}
          }
        },
        "HeadRotation": {
          "Rotation": {
            "Pitch": 0.0,
            "Yaw": 3.096343755722046,
            "Roll": 0.0
          }
        }
      }
    },
    {
      "Components": {
        "UtilityInventory": {
          "Inventory": {
            "Id": "Simple",
            "Capacity": 2,
            "Items": {
              "0": {
                "Id": "Weapon_Shield_Rusty",
                "Quantity": 1,
                "Durability": 0.0,
                "MaxDurability": 0.0,
                "OverrideDroppedItemAnimation": false
              }
            }
          },
          "ActiveSlot": 0
        },
        "EffectController": {},
        "UIComponentList": {},
        "HotbarInventory": {
          "Inventory": {
            "Id": "Simple",
            "Capacity": 3,
            "Items": {
              "0": {
                "Id": "Weapon_Sword_Steel_Rusty",
                "Quantity": 1,
                "Durability": 80.0,
                "MaxDurability": 80.0,
                "OverrideDroppedItemAnimation": false
              }
            }
          },
          "ActiveSlot": 0
        },
        "Transform": {
          "Position": {
            "X": 2.3905467987060547,
            "Y": -0.18460845947265625,
            "Z": 1.1463203430175781
          },
          "Rotation": {
            "Pitch": 0.0,
            "Yaw": 3.096343755722046,
            "Roll": 0.0
          }
        },
        "EntityScale": {
          "Scale": 1.0
        },
        "StorageInventory": {
          "Inventory": {
            "Id": "Empty"
          }
        },
        "Velocity": {
          "Velocity": {
            "X": 0.0,
            "Y": 0.0,
            "Z": 0.0
          }
        },
        "PrefabCopyable": {},
        "Interactions": {
          "Interactions": {
            "Use": "*UseNPC"
          }
        },
        "Model": {
          "Model": {
            "Id": "Skeleton_Burnt_Soldier",
            "Scale": 1.0,
            "Static": false
          }
        },
        "UUID": {
          "UUID": {
            "$binary": "yIztlfZcPumHGJSNk3k/0A==",
            "$type": "04"
          }
        },
        "EntityStats": {
          "Version": 5,
          "Stats": {
            "Oxygen": {
              "Id": "Oxygen",
              "Value": 100.0
            },
            "Mana": {
              "Id": "Mana",
              "Value": 0.0
            },
            "Health": {
              "Id": "Health",
              "Value": 100.0,
              "Modifiers": {
                "NPC_Max": {
                  "Id": "Static",
                  "CalculationType": "Additive",
                  "Amount": 24.0
                }
              }
            },
            "GlidingActive": {
              "Id": "GlidingActive",
              "Value": 0.0
            },
            "Immunity": {
              "Id": "Immunity",
              "Value": 0.0
            },
            "SignatureCharges": {
              "Id": "SignatureCharges",
              "Value": 0.0
            },
            "Stamina": {
              "Id": "Stamina",
              "Value": 10.0
            },
            "Ammo": {
              "Id": "Ammo",
              "Value": 0.0
            },
            "Unknown": {
              "Id": "Unknown",
              "Value": 0.0
            },
            "SignatureEnergy": {
              "Id": "SignatureEnergy",
              "Value": 0.0,
              "Modifiers": {
                "*Weapon_0": {
                  "Id": "Static",
                  "CalculationType": "Additive",
                  "Amount": 20.0
                }
              }
            },
            "DeployablePreview": {
              "Id": "DeployablePreview",
              "Value": 0.0
            },
            "StaminaRegenDelay": {
              "Id": "StaminaRegenDelay",
              "Value": 0.0
            },
            "MagicCharges": {
              "Id": "MagicCharges",
              "Value": 0.0
            }
          }
        },
        "NPC": {
          "Version": 5,
          "UUID": {
            "$binary": "yIztlfZcPumHGJSNk3k/0A==",
            "$type": "04"
          },
          "Inventory": {
            "Version": 4,
            "ActiveHotbarSlot": 0,
            "ActiveToolsSlot": -1,
            "ActiveUtilitySlot": -1
          },
          "HvrPhs": 0.0,
          "HvrHght": 0.0,
          "MdlScl": 1.0,
          "SpawnInstant": "0001-01-01T12:00:00Z",
          "WorldgenId": 0,
          "PathManager": {},
          "LeashPos": {
            "X": 5.347629248976998,
            "Y": 56.0,
            "Z": 8.885068892303863
          },
          "LeashHdg": 3.096343755722046,
          "LeashPtch": 0.0,
          "RoleName": "Skeleton_Burnt_Soldier",
          "ActiveMC": "Walk"
        },
        "ArmorInventory": {
          "Inventory": {
            "Id": "Simple",
            "Capacity": 4,
            "Items": {}
          }
        },
        "HeadRotation": {
          "Rotation": {
            "Pitch": 0.0,
            "Yaw": 3.096343755722046,
            "Roll": 0.0
          }
        }
      }
    }
  ]
}